ERROR 2023-10-05 15:35:17,316 views An error occurred: [Errno 11001] getaddrinfo failed
Traceback (most recent call last):
  File "C:\Users\Lenovo\Downloads\Appstack\Appstack\freelance_project\customer_engine\views.py", line 338, in post
    send_mail(
  File "C:\Users\Lenovo\Downloads\Appstack\Appstack\env\Lib\site-packages\django\core\mail\__init__.py", line 87, in send_mail
    return mail.send()
           ^^^^^^^^^^^
  File "C:\Users\Lenovo\Downloads\Appstack\Appstack\env\Lib\site-packages\django\core\mail\message.py", line 298, in send
    return self.get_connection(fail_silently).send_messages([self])
           ^^^^^^^^^^^^^^^^^^^^^^^^^^^^^^^^^^^^^^^^^^^^^^^^^^^^^^^^
  File "C:\Users\Lenovo\Downloads\Appstack\Appstack\env\Lib\site-packages\django\core\mail\backends\smtp.py", line 127, in send_messages
    new_conn_created = self.open()
                       ^^^^^^^^^^^
  File "C:\Users\Lenovo\Downloads\Appstack\Appstack\env\Lib\site-packages\django\core\mail\backends\smtp.py", line 85, in open
    self.connection = self.connection_class(
                      ^^^^^^^^^^^^^^^^^^^^^^
  File "C:\Users\Lenovo\AppData\Local\Programs\Python\Python311\Lib\smtplib.py", line 255, in __init__
    (code, msg) = self.connect(host, port)
                  ^^^^^^^^^^^^^^^^^^^^^^^^
  File "C:\Users\Lenovo\AppData\Local\Programs\Python\Python311\Lib\smtplib.py", line 341, in connect
    self.sock = self._get_socket(host, port, self.timeout)
                ^^^^^^^^^^^^^^^^^^^^^^^^^^^^^^^^^^^^^^^^^^
  File "C:\Users\Lenovo\AppData\Local\Programs\Python\Python311\Lib\smtplib.py", line 312, in _get_socket
    return socket.create_connection((host, port), timeout,
           ^^^^^^^^^^^^^^^^^^^^^^^^^^^^^^^^^^^^^^^^^^^^^^^
  File "C:\Users\Lenovo\AppData\Local\Programs\Python\Python311\Lib\socket.py", line 827, in create_connection
    for res in getaddrinfo(host, port, 0, SOCK_STREAM):
               ^^^^^^^^^^^^^^^^^^^^^^^^^^^^^^^^^^^^^^^
  File "C:\Users\Lenovo\AppData\Local\Programs\Python\Python311\Lib\socket.py", line 962, in getaddrinfo
    for res in _socket.getaddrinfo(host, port, family, type, proto, flags):
               ^^^^^^^^^^^^^^^^^^^^^^^^^^^^^^^^^^^^^^^^^^^^^^^^^^^^^^^^^^^
socket.gaierror: [Errno 11001] getaddrinfo failed
ERROR 2023-10-05 15:35:17,782 log Internal Server Error: /api/login/
ERROR 2023-10-05 16:18:25,056 views Daily snacks with ID 15 not found
ERROR 2023-10-05 16:18:35,320 views Daily snacks with ID 1 not found
ERROR 2023-10-05 16:20:38,261 views Daily snacks with ID 11 not found
ERROR 2023-10-05 16:20:41,221 views Daily snacks with ID 11 not found
ERROR 2023-10-05 17:01:04,218 views An error occurred: [Errno 11001] getaddrinfo failed
Traceback (most recent call last):
  File "C:\Users\Lenovo\Downloads\Appstack\Appstack\freelance_project\customer_engine\views.py", line 338, in post
    send_mail(
  File "C:\Users\Lenovo\Downloads\Appstack\Appstack\env\Lib\site-packages\django\core\mail\__init__.py", line 87, in send_mail
    return mail.send()
           ^^^^^^^^^^^
  File "C:\Users\Lenovo\Downloads\Appstack\Appstack\env\Lib\site-packages\django\core\mail\message.py", line 298, in send
    return self.get_connection(fail_silently).send_messages([self])
           ^^^^^^^^^^^^^^^^^^^^^^^^^^^^^^^^^^^^^^^^^^^^^^^^^^^^^^^^
  File "C:\Users\Lenovo\Downloads\Appstack\Appstack\env\Lib\site-packages\django\core\mail\backends\smtp.py", line 127, in send_messages
    new_conn_created = self.open()
                       ^^^^^^^^^^^
  File "C:\Users\Lenovo\Downloads\Appstack\Appstack\env\Lib\site-packages\django\core\mail\backends\smtp.py", line 85, in open
    self.connection = self.connection_class(
                      ^^^^^^^^^^^^^^^^^^^^^^
  File "C:\Users\Lenovo\AppData\Local\Programs\Python\Python311\Lib\smtplib.py", line 255, in __init__
    (code, msg) = self.connect(host, port)
                  ^^^^^^^^^^^^^^^^^^^^^^^^
  File "C:\Users\Lenovo\AppData\Local\Programs\Python\Python311\Lib\smtplib.py", line 341, in connect
    self.sock = self._get_socket(host, port, self.timeout)
                ^^^^^^^^^^^^^^^^^^^^^^^^^^^^^^^^^^^^^^^^^^
  File "C:\Users\Lenovo\AppData\Local\Programs\Python\Python311\Lib\smtplib.py", line 312, in _get_socket
    return socket.create_connection((host, port), timeout,
           ^^^^^^^^^^^^^^^^^^^^^^^^^^^^^^^^^^^^^^^^^^^^^^^
  File "C:\Users\Lenovo\AppData\Local\Programs\Python\Python311\Lib\socket.py", line 827, in create_connection
    for res in getaddrinfo(host, port, 0, SOCK_STREAM):
               ^^^^^^^^^^^^^^^^^^^^^^^^^^^^^^^^^^^^^^^
  File "C:\Users\Lenovo\AppData\Local\Programs\Python\Python311\Lib\socket.py", line 962, in getaddrinfo
    for res in _socket.getaddrinfo(host, port, family, type, proto, flags):
               ^^^^^^^^^^^^^^^^^^^^^^^^^^^^^^^^^^^^^^^^^^^^^^^^^^^^^^^^^^^
socket.gaierror: [Errno 11001] getaddrinfo failed
ERROR 2023-10-05 17:01:04,338 log Internal Server Error: /api/login/
ERROR 2023-10-05 17:13:23,865 views An error occurred: [Errno 11001] getaddrinfo failed
Traceback (most recent call last):
  File "C:\Users\Lenovo\Downloads\Appstack\Appstack\freelance_project\customer_engine\views.py", line 338, in post
    send_mail(
  File "C:\Users\Lenovo\Downloads\Appstack\Appstack\env\Lib\site-packages\django\core\mail\__init__.py", line 87, in send_mail
    return mail.send()
           ^^^^^^^^^^^
  File "C:\Users\Lenovo\Downloads\Appstack\Appstack\env\Lib\site-packages\django\core\mail\message.py", line 298, in send
    return self.get_connection(fail_silently).send_messages([self])
           ^^^^^^^^^^^^^^^^^^^^^^^^^^^^^^^^^^^^^^^^^^^^^^^^^^^^^^^^
  File "C:\Users\Lenovo\Downloads\Appstack\Appstack\env\Lib\site-packages\django\core\mail\backends\smtp.py", line 127, in send_messages
    new_conn_created = self.open()
                       ^^^^^^^^^^^
  File "C:\Users\Lenovo\Downloads\Appstack\Appstack\env\Lib\site-packages\django\core\mail\backends\smtp.py", line 85, in open
    self.connection = self.connection_class(
                      ^^^^^^^^^^^^^^^^^^^^^^
  File "C:\Users\Lenovo\AppData\Local\Programs\Python\Python311\Lib\smtplib.py", line 255, in __init__
    (code, msg) = self.connect(host, port)
                  ^^^^^^^^^^^^^^^^^^^^^^^^
  File "C:\Users\Lenovo\AppData\Local\Programs\Python\Python311\Lib\smtplib.py", line 341, in connect
    self.sock = self._get_socket(host, port, self.timeout)
                ^^^^^^^^^^^^^^^^^^^^^^^^^^^^^^^^^^^^^^^^^^
  File "C:\Users\Lenovo\AppData\Local\Programs\Python\Python311\Lib\smtplib.py", line 312, in _get_socket
    return socket.create_connection((host, port), timeout,
           ^^^^^^^^^^^^^^^^^^^^^^^^^^^^^^^^^^^^^^^^^^^^^^^
  File "C:\Users\Lenovo\AppData\Local\Programs\Python\Python311\Lib\socket.py", line 827, in create_connection
    for res in getaddrinfo(host, port, 0, SOCK_STREAM):
               ^^^^^^^^^^^^^^^^^^^^^^^^^^^^^^^^^^^^^^^
  File "C:\Users\Lenovo\AppData\Local\Programs\Python\Python311\Lib\socket.py", line 962, in getaddrinfo
    for res in _socket.getaddrinfo(host, port, family, type, proto, flags):
               ^^^^^^^^^^^^^^^^^^^^^^^^^^^^^^^^^^^^^^^^^^^^^^^^^^^^^^^^^^^
socket.gaierror: [Errno 11001] getaddrinfo failed
ERROR 2023-10-05 17:13:23,876 log Internal Server Error: /api/login/
ERROR 2023-10-05 17:13:33,240 views An error occurred: [Errno 11001] getaddrinfo failed
Traceback (most recent call last):
  File "C:\Users\Lenovo\Downloads\Appstack\Appstack\freelance_project\customer_engine\views.py", line 338, in post
    send_mail(
  File "C:\Users\Lenovo\Downloads\Appstack\Appstack\env\Lib\site-packages\django\core\mail\__init__.py", line 87, in send_mail
    return mail.send()
           ^^^^^^^^^^^
  File "C:\Users\Lenovo\Downloads\Appstack\Appstack\env\Lib\site-packages\django\core\mail\message.py", line 298, in send
    return self.get_connection(fail_silently).send_messages([self])
           ^^^^^^^^^^^^^^^^^^^^^^^^^^^^^^^^^^^^^^^^^^^^^^^^^^^^^^^^
  File "C:\Users\Lenovo\Downloads\Appstack\Appstack\env\Lib\site-packages\django\core\mail\backends\smtp.py", line 127, in send_messages
    new_conn_created = self.open()
                       ^^^^^^^^^^^
  File "C:\Users\Lenovo\Downloads\Appstack\Appstack\env\Lib\site-packages\django\core\mail\backends\smtp.py", line 85, in open
    self.connection = self.connection_class(
                      ^^^^^^^^^^^^^^^^^^^^^^
  File "C:\Users\Lenovo\AppData\Local\Programs\Python\Python311\Lib\smtplib.py", line 255, in __init__
    (code, msg) = self.connect(host, port)
                  ^^^^^^^^^^^^^^^^^^^^^^^^
  File "C:\Users\Lenovo\AppData\Local\Programs\Python\Python311\Lib\smtplib.py", line 341, in connect
    self.sock = self._get_socket(host, port, self.timeout)
                ^^^^^^^^^^^^^^^^^^^^^^^^^^^^^^^^^^^^^^^^^^
  File "C:\Users\Lenovo\AppData\Local\Programs\Python\Python311\Lib\smtplib.py", line 312, in _get_socket
    return socket.create_connection((host, port), timeout,
           ^^^^^^^^^^^^^^^^^^^^^^^^^^^^^^^^^^^^^^^^^^^^^^^
  File "C:\Users\Lenovo\AppData\Local\Programs\Python\Python311\Lib\socket.py", line 827, in create_connection
    for res in getaddrinfo(host, port, 0, SOCK_STREAM):
               ^^^^^^^^^^^^^^^^^^^^^^^^^^^^^^^^^^^^^^^
  File "C:\Users\Lenovo\AppData\Local\Programs\Python\Python311\Lib\socket.py", line 962, in getaddrinfo
    for res in _socket.getaddrinfo(host, port, family, type, proto, flags):
               ^^^^^^^^^^^^^^^^^^^^^^^^^^^^^^^^^^^^^^^^^^^^^^^^^^^^^^^^^^^
socket.gaierror: [Errno 11001] getaddrinfo failed
ERROR 2023-10-05 17:13:33,243 log Internal Server Error: /api/login/
ERROR 2023-10-05 17:17:42,147 views An error occurred: cannot access local variable 'new_user_otp' where it is not associated with a value
Traceback (most recent call last):
  File "C:\Users\Lenovo\Downloads\Appstack\Appstack\freelance_project\customer_engine\views.py", line 336, in post
    message = f'Your OTP is: {new_user_otp.otp}'
                              ^^^^^^^^^^^^
UnboundLocalError: cannot access local variable 'new_user_otp' where it is not associated with a value
ERROR 2023-10-05 17:17:42,150 log Internal Server Error: /api/login/
ERROR 2023-10-05 17:18:30,404 views An error occurred: cannot access local variable 'logger' where it is not associated with a value
Traceback (most recent call last):
  File "C:\Users\Lenovo\Downloads\Appstack\Appstack\freelance_project\customer_engine\views.py", line 339, in post
    send_mail(
  File "C:\Users\Lenovo\Downloads\Appstack\Appstack\env\Lib\site-packages\django\core\mail\__init__.py", line 87, in send_mail
    return mail.send()
           ^^^^^^^^^^^
  File "C:\Users\Lenovo\Downloads\Appstack\Appstack\env\Lib\site-packages\django\core\mail\message.py", line 298, in send
    return self.get_connection(fail_silently).send_messages([self])
           ^^^^^^^^^^^^^^^^^^^^^^^^^^^^^^^^^^^^^^^^^^^^^^^^^^^^^^^^
  File "C:\Users\Lenovo\Downloads\Appstack\Appstack\env\Lib\site-packages\django\core\mail\backends\smtp.py", line 127, in send_messages
    new_conn_created = self.open()
                       ^^^^^^^^^^^
  File "C:\Users\Lenovo\Downloads\Appstack\Appstack\env\Lib\site-packages\django\core\mail\backends\smtp.py", line 85, in open
    self.connection = self.connection_class(
                      ^^^^^^^^^^^^^^^^^^^^^^
  File "C:\Users\Lenovo\AppData\Local\Programs\Python\Python311\Lib\smtplib.py", line 255, in __init__
    (code, msg) = self.connect(host, port)
                  ^^^^^^^^^^^^^^^^^^^^^^^^
  File "C:\Users\Lenovo\AppData\Local\Programs\Python\Python311\Lib\smtplib.py", line 341, in connect
    self.sock = self._get_socket(host, port, self.timeout)
                ^^^^^^^^^^^^^^^^^^^^^^^^^^^^^^^^^^^^^^^^^^
  File "C:\Users\Lenovo\AppData\Local\Programs\Python\Python311\Lib\smtplib.py", line 312, in _get_socket
    return socket.create_connection((host, port), timeout,
           ^^^^^^^^^^^^^^^^^^^^^^^^^^^^^^^^^^^^^^^^^^^^^^^
  File "C:\Users\Lenovo\AppData\Local\Programs\Python\Python311\Lib\socket.py", line 827, in create_connection
    for res in getaddrinfo(host, port, 0, SOCK_STREAM):
               ^^^^^^^^^^^^^^^^^^^^^^^^^^^^^^^^^^^^^^^
  File "C:\Users\Lenovo\AppData\Local\Programs\Python\Python311\Lib\socket.py", line 962, in getaddrinfo
    for res in _socket.getaddrinfo(host, port, family, type, proto, flags):
               ^^^^^^^^^^^^^^^^^^^^^^^^^^^^^^^^^^^^^^^^^^^^^^^^^^^^^^^^^^^
socket.gaierror: [Errno 11001] getaddrinfo failed

During handling of the above exception, another exception occurred:

Traceback (most recent call last):
  File "C:\Users\Lenovo\Downloads\Appstack\Appstack\freelance_project\customer_engine\views.py", line 348, in post
    logger.error("Error sending email: %s", str(email_error))
    ^^^^^^
UnboundLocalError: cannot access local variable 'logger' where it is not associated with a value
ERROR 2023-10-05 17:18:30,414 log Internal Server Error: /api/login/
ERROR 2023-10-05 17:21:32,735 views An error occurred: cannot access local variable 'logger' where it is not associated with a value
Traceback (most recent call last):
  File "C:\Users\Lenovo\Downloads\Appstack\Appstack\freelance_project\customer_engine\views.py", line 339, in post
    send_mail(
  File "C:\Users\Lenovo\Downloads\Appstack\Appstack\env\Lib\site-packages\django\core\mail\__init__.py", line 87, in send_mail
    return mail.send()
           ^^^^^^^^^^^
  File "C:\Users\Lenovo\Downloads\Appstack\Appstack\env\Lib\site-packages\django\core\mail\message.py", line 298, in send
    return self.get_connection(fail_silently).send_messages([self])
           ^^^^^^^^^^^^^^^^^^^^^^^^^^^^^^^^^^^^^^^^^^^^^^^^^^^^^^^^
  File "C:\Users\Lenovo\Downloads\Appstack\Appstack\env\Lib\site-packages\django\core\mail\backends\smtp.py", line 127, in send_messages
    new_conn_created = self.open()
                       ^^^^^^^^^^^
  File "C:\Users\Lenovo\Downloads\Appstack\Appstack\env\Lib\site-packages\django\core\mail\backends\smtp.py", line 85, in open
    self.connection = self.connection_class(
                      ^^^^^^^^^^^^^^^^^^^^^^
  File "C:\Users\Lenovo\AppData\Local\Programs\Python\Python311\Lib\smtplib.py", line 255, in __init__
    (code, msg) = self.connect(host, port)
                  ^^^^^^^^^^^^^^^^^^^^^^^^
  File "C:\Users\Lenovo\AppData\Local\Programs\Python\Python311\Lib\smtplib.py", line 341, in connect
    self.sock = self._get_socket(host, port, self.timeout)
                ^^^^^^^^^^^^^^^^^^^^^^^^^^^^^^^^^^^^^^^^^^
  File "C:\Users\Lenovo\AppData\Local\Programs\Python\Python311\Lib\smtplib.py", line 312, in _get_socket
    return socket.create_connection((host, port), timeout,
           ^^^^^^^^^^^^^^^^^^^^^^^^^^^^^^^^^^^^^^^^^^^^^^^
  File "C:\Users\Lenovo\AppData\Local\Programs\Python\Python311\Lib\socket.py", line 827, in create_connection
    for res in getaddrinfo(host, port, 0, SOCK_STREAM):
               ^^^^^^^^^^^^^^^^^^^^^^^^^^^^^^^^^^^^^^^
  File "C:\Users\Lenovo\AppData\Local\Programs\Python\Python311\Lib\socket.py", line 962, in getaddrinfo
    for res in _socket.getaddrinfo(host, port, family, type, proto, flags):
               ^^^^^^^^^^^^^^^^^^^^^^^^^^^^^^^^^^^^^^^^^^^^^^^^^^^^^^^^^^^
socket.gaierror: [Errno 11001] getaddrinfo failed

During handling of the above exception, another exception occurred:

Traceback (most recent call last):
  File "C:\Users\Lenovo\Downloads\Appstack\Appstack\freelance_project\customer_engine\views.py", line 348, in post
    logger.error("Error sending email: %s", str(email_error))
    ^^^^^^
UnboundLocalError: cannot access local variable 'logger' where it is not associated with a value
ERROR 2023-10-05 17:21:32,745 log Internal Server Error: /api/login/
ERROR 2023-10-05 17:21:36,311 views An error occurred: cannot access local variable 'logger' where it is not associated with a value
Traceback (most recent call last):
  File "C:\Users\Lenovo\Downloads\Appstack\Appstack\freelance_project\customer_engine\views.py", line 339, in post
    send_mail(
  File "C:\Users\Lenovo\Downloads\Appstack\Appstack\env\Lib\site-packages\django\core\mail\__init__.py", line 87, in send_mail
    return mail.send()
           ^^^^^^^^^^^
  File "C:\Users\Lenovo\Downloads\Appstack\Appstack\env\Lib\site-packages\django\core\mail\message.py", line 298, in send
    return self.get_connection(fail_silently).send_messages([self])
           ^^^^^^^^^^^^^^^^^^^^^^^^^^^^^^^^^^^^^^^^^^^^^^^^^^^^^^^^
  File "C:\Users\Lenovo\Downloads\Appstack\Appstack\env\Lib\site-packages\django\core\mail\backends\smtp.py", line 127, in send_messages
    new_conn_created = self.open()
                       ^^^^^^^^^^^
  File "C:\Users\Lenovo\Downloads\Appstack\Appstack\env\Lib\site-packages\django\core\mail\backends\smtp.py", line 85, in open
    self.connection = self.connection_class(
                      ^^^^^^^^^^^^^^^^^^^^^^
  File "C:\Users\Lenovo\AppData\Local\Programs\Python\Python311\Lib\smtplib.py", line 255, in __init__
    (code, msg) = self.connect(host, port)
                  ^^^^^^^^^^^^^^^^^^^^^^^^
  File "C:\Users\Lenovo\AppData\Local\Programs\Python\Python311\Lib\smtplib.py", line 341, in connect
    self.sock = self._get_socket(host, port, self.timeout)
                ^^^^^^^^^^^^^^^^^^^^^^^^^^^^^^^^^^^^^^^^^^
  File "C:\Users\Lenovo\AppData\Local\Programs\Python\Python311\Lib\smtplib.py", line 312, in _get_socket
    return socket.create_connection((host, port), timeout,
           ^^^^^^^^^^^^^^^^^^^^^^^^^^^^^^^^^^^^^^^^^^^^^^^
  File "C:\Users\Lenovo\AppData\Local\Programs\Python\Python311\Lib\socket.py", line 827, in create_connection
    for res in getaddrinfo(host, port, 0, SOCK_STREAM):
               ^^^^^^^^^^^^^^^^^^^^^^^^^^^^^^^^^^^^^^^
  File "C:\Users\Lenovo\AppData\Local\Programs\Python\Python311\Lib\socket.py", line 962, in getaddrinfo
    for res in _socket.getaddrinfo(host, port, family, type, proto, flags):
               ^^^^^^^^^^^^^^^^^^^^^^^^^^^^^^^^^^^^^^^^^^^^^^^^^^^^^^^^^^^
socket.gaierror: [Errno 11001] getaddrinfo failed

During handling of the above exception, another exception occurred:

Traceback (most recent call last):
  File "C:\Users\Lenovo\Downloads\Appstack\Appstack\freelance_project\customer_engine\views.py", line 348, in post
    logger.error("Error sending email: %s", str(email_error))
    ^^^^^^
UnboundLocalError: cannot access local variable 'logger' where it is not associated with a value
ERROR 2023-10-05 17:21:36,314 log Internal Server Error: /api/login/
ERROR 2023-10-05 17:22:12,981 views An error occurred: [Errno 11001] getaddrinfo failed
Traceback (most recent call last):
  File "C:\Users\Lenovo\Downloads\Appstack\Appstack\freelance_project\customer_engine\views.py", line 338, in post
    # send_mail(
  File "C:\Users\Lenovo\Downloads\Appstack\Appstack\env\Lib\site-packages\django\core\mail\__init__.py", line 87, in send_mail
    return mail.send()
           ^^^^^^^^^^^
  File "C:\Users\Lenovo\Downloads\Appstack\Appstack\env\Lib\site-packages\django\core\mail\message.py", line 298, in send
    return self.get_connection(fail_silently).send_messages([self])
           ^^^^^^^^^^^^^^^^^^^^^^^^^^^^^^^^^^^^^^^^^^^^^^^^^^^^^^^^
  File "C:\Users\Lenovo\Downloads\Appstack\Appstack\env\Lib\site-packages\django\core\mail\backends\smtp.py", line 127, in send_messages
    new_conn_created = self.open()
                       ^^^^^^^^^^^
  File "C:\Users\Lenovo\Downloads\Appstack\Appstack\env\Lib\site-packages\django\core\mail\backends\smtp.py", line 85, in open
    self.connection = self.connection_class(
                      ^^^^^^^^^^^^^^^^^^^^^^
  File "C:\Users\Lenovo\AppData\Local\Programs\Python\Python311\Lib\smtplib.py", line 255, in __init__
    (code, msg) = self.connect(host, port)
                  ^^^^^^^^^^^^^^^^^^^^^^^^
  File "C:\Users\Lenovo\AppData\Local\Programs\Python\Python311\Lib\smtplib.py", line 341, in connect
    self.sock = self._get_socket(host, port, self.timeout)
                ^^^^^^^^^^^^^^^^^^^^^^^^^^^^^^^^^^^^^^^^^^
  File "C:\Users\Lenovo\AppData\Local\Programs\Python\Python311\Lib\smtplib.py", line 312, in _get_socket
    return socket.create_connection((host, port), timeout,
           ^^^^^^^^^^^^^^^^^^^^^^^^^^^^^^^^^^^^^^^^^^^^^^^
  File "C:\Users\Lenovo\AppData\Local\Programs\Python\Python311\Lib\socket.py", line 827, in create_connection
    for res in getaddrinfo(host, port, 0, SOCK_STREAM):
               ^^^^^^^^^^^^^^^^^^^^^^^^^^^^^^^^^^^^^^^
  File "C:\Users\Lenovo\AppData\Local\Programs\Python\Python311\Lib\socket.py", line 962, in getaddrinfo
    for res in _socket.getaddrinfo(host, port, family, type, proto, flags):
               ^^^^^^^^^^^^^^^^^^^^^^^^^^^^^^^^^^^^^^^^^^^^^^^^^^^^^^^^^^^
socket.gaierror: [Errno 11001] getaddrinfo failed
ERROR 2023-10-05 17:22:13,020 log Internal Server Error: /api/login/
ERROR 2023-10-05 17:22:24,853 views An error occurred: [Errno 11001] getaddrinfo failed
Traceback (most recent call last):
  File "C:\Users\Lenovo\Downloads\Appstack\Appstack\freelance_project\customer_engine\views.py", line 338, in post
    # send_mail(
  File "C:\Users\Lenovo\Downloads\Appstack\Appstack\env\Lib\site-packages\django\core\mail\__init__.py", line 87, in send_mail
    return mail.send()
           ^^^^^^^^^^^
  File "C:\Users\Lenovo\Downloads\Appstack\Appstack\env\Lib\site-packages\django\core\mail\message.py", line 298, in send
    return self.get_connection(fail_silently).send_messages([self])
           ^^^^^^^^^^^^^^^^^^^^^^^^^^^^^^^^^^^^^^^^^^^^^^^^^^^^^^^^
  File "C:\Users\Lenovo\Downloads\Appstack\Appstack\env\Lib\site-packages\django\core\mail\backends\smtp.py", line 127, in send_messages
    new_conn_created = self.open()
                       ^^^^^^^^^^^
  File "C:\Users\Lenovo\Downloads\Appstack\Appstack\env\Lib\site-packages\django\core\mail\backends\smtp.py", line 85, in open
    self.connection = self.connection_class(
                      ^^^^^^^^^^^^^^^^^^^^^^
  File "C:\Users\Lenovo\AppData\Local\Programs\Python\Python311\Lib\smtplib.py", line 255, in __init__
    (code, msg) = self.connect(host, port)
                  ^^^^^^^^^^^^^^^^^^^^^^^^
  File "C:\Users\Lenovo\AppData\Local\Programs\Python\Python311\Lib\smtplib.py", line 341, in connect
    self.sock = self._get_socket(host, port, self.timeout)
                ^^^^^^^^^^^^^^^^^^^^^^^^^^^^^^^^^^^^^^^^^^
  File "C:\Users\Lenovo\AppData\Local\Programs\Python\Python311\Lib\smtplib.py", line 312, in _get_socket
    return socket.create_connection((host, port), timeout,
           ^^^^^^^^^^^^^^^^^^^^^^^^^^^^^^^^^^^^^^^^^^^^^^^
  File "C:\Users\Lenovo\AppData\Local\Programs\Python\Python311\Lib\socket.py", line 827, in create_connection
    for res in getaddrinfo(host, port, 0, SOCK_STREAM):
               ^^^^^^^^^^^^^^^^^^^^^^^^^^^^^^^^^^^^^^^
  File "C:\Users\Lenovo\AppData\Local\Programs\Python\Python311\Lib\socket.py", line 962, in getaddrinfo
    for res in _socket.getaddrinfo(host, port, family, type, proto, flags):
               ^^^^^^^^^^^^^^^^^^^^^^^^^^^^^^^^^^^^^^^^^^^^^^^^^^^^^^^^^^^
socket.gaierror: [Errno 11001] getaddrinfo failed
ERROR 2023-10-05 17:22:24,857 log Internal Server Error: /api/login/
ERROR 2023-10-05 17:29:22,265 views An error occurred: [Errno 11001] getaddrinfo failed
Traceback (most recent call last):
  File "C:\Users\Lenovo\Downloads\Appstack\Appstack\freelance_project\customer_engine\views.py", line 337, in post
    send_mail(
  File "C:\Users\Lenovo\Downloads\Appstack\Appstack\env\Lib\site-packages\django\core\mail\__init__.py", line 87, in send_mail
    return mail.send()
           ^^^^^^^^^^^
  File "C:\Users\Lenovo\Downloads\Appstack\Appstack\env\Lib\site-packages\django\core\mail\message.py", line 298, in send
    return self.get_connection(fail_silently).send_messages([self])
           ^^^^^^^^^^^^^^^^^^^^^^^^^^^^^^^^^^^^^^^^^^^^^^^^^^^^^^^^
  File "C:\Users\Lenovo\Downloads\Appstack\Appstack\env\Lib\site-packages\django\core\mail\backends\smtp.py", line 127, in send_messages
    new_conn_created = self.open()
                       ^^^^^^^^^^^
  File "C:\Users\Lenovo\Downloads\Appstack\Appstack\env\Lib\site-packages\django\core\mail\backends\smtp.py", line 85, in open
    self.connection = self.connection_class(
                      ^^^^^^^^^^^^^^^^^^^^^^
  File "C:\Users\Lenovo\AppData\Local\Programs\Python\Python311\Lib\smtplib.py", line 255, in __init__
    (code, msg) = self.connect(host, port)
                  ^^^^^^^^^^^^^^^^^^^^^^^^
  File "C:\Users\Lenovo\AppData\Local\Programs\Python\Python311\Lib\smtplib.py", line 341, in connect
    self.sock = self._get_socket(host, port, self.timeout)
                ^^^^^^^^^^^^^^^^^^^^^^^^^^^^^^^^^^^^^^^^^^
  File "C:\Users\Lenovo\AppData\Local\Programs\Python\Python311\Lib\smtplib.py", line 312, in _get_socket
    return socket.create_connection((host, port), timeout,
           ^^^^^^^^^^^^^^^^^^^^^^^^^^^^^^^^^^^^^^^^^^^^^^^
  File "C:\Users\Lenovo\AppData\Local\Programs\Python\Python311\Lib\socket.py", line 827, in create_connection
    for res in getaddrinfo(host, port, 0, SOCK_STREAM):
               ^^^^^^^^^^^^^^^^^^^^^^^^^^^^^^^^^^^^^^^
  File "C:\Users\Lenovo\AppData\Local\Programs\Python\Python311\Lib\socket.py", line 962, in getaddrinfo
    for res in _socket.getaddrinfo(host, port, family, type, proto, flags):
               ^^^^^^^^^^^^^^^^^^^^^^^^^^^^^^^^^^^^^^^^^^^^^^^^^^^^^^^^^^^
socket.gaierror: [Errno 11001] getaddrinfo failed
ERROR 2023-10-05 17:29:22,275 log Internal Server Error: /api/login/
ERROR 2023-10-05 17:41:12,633 views An error occurred: [Errno 11001] getaddrinfo failed
Traceback (most recent call last):
  File "C:\Users\Lenovo\Downloads\Appstack\Appstack\freelance_project\customer_engine\views.py", line 337, in post
    send_mail(
  File "C:\Users\Lenovo\Downloads\Appstack\Appstack\env\Lib\site-packages\django\core\mail\__init__.py", line 87, in send_mail
    return mail.send()
           ^^^^^^^^^^^
  File "C:\Users\Lenovo\Downloads\Appstack\Appstack\env\Lib\site-packages\django\core\mail\message.py", line 298, in send
    return self.get_connection(fail_silently).send_messages([self])
           ^^^^^^^^^^^^^^^^^^^^^^^^^^^^^^^^^^^^^^^^^^^^^^^^^^^^^^^^
  File "C:\Users\Lenovo\Downloads\Appstack\Appstack\env\Lib\site-packages\django\core\mail\backends\smtp.py", line 127, in send_messages
    new_conn_created = self.open()
                       ^^^^^^^^^^^
  File "C:\Users\Lenovo\Downloads\Appstack\Appstack\env\Lib\site-packages\django\core\mail\backends\smtp.py", line 85, in open
    self.connection = self.connection_class(
                      ^^^^^^^^^^^^^^^^^^^^^^
  File "C:\Users\Lenovo\AppData\Local\Programs\Python\Python311\Lib\smtplib.py", line 255, in __init__
    (code, msg) = self.connect(host, port)
                  ^^^^^^^^^^^^^^^^^^^^^^^^
  File "C:\Users\Lenovo\AppData\Local\Programs\Python\Python311\Lib\smtplib.py", line 341, in connect
    self.sock = self._get_socket(host, port, self.timeout)
                ^^^^^^^^^^^^^^^^^^^^^^^^^^^^^^^^^^^^^^^^^^
  File "C:\Users\Lenovo\AppData\Local\Programs\Python\Python311\Lib\smtplib.py", line 312, in _get_socket
    return socket.create_connection((host, port), timeout,
           ^^^^^^^^^^^^^^^^^^^^^^^^^^^^^^^^^^^^^^^^^^^^^^^
  File "C:\Users\Lenovo\AppData\Local\Programs\Python\Python311\Lib\socket.py", line 827, in create_connection
    for res in getaddrinfo(host, port, 0, SOCK_STREAM):
               ^^^^^^^^^^^^^^^^^^^^^^^^^^^^^^^^^^^^^^^
  File "C:\Users\Lenovo\AppData\Local\Programs\Python\Python311\Lib\socket.py", line 962, in getaddrinfo
    for res in _socket.getaddrinfo(host, port, family, type, proto, flags):
               ^^^^^^^^^^^^^^^^^^^^^^^^^^^^^^^^^^^^^^^^^^^^^^^^^^^^^^^^^^^
socket.gaierror: [Errno 11001] getaddrinfo failed
ERROR 2023-10-05 17:41:12,643 log Internal Server Error: /api/login/
ERROR 2023-10-05 17:58:29,124 views An error occurred: [Errno 11001] getaddrinfo failed
Traceback (most recent call last):
  File "C:\Users\Lenovo\Downloads\Appstack\Appstack\freelance_project\customer_engine\views.py", line 337, in post
    send_mail(
  File "C:\Users\Lenovo\Downloads\Appstack\Appstack\env\Lib\site-packages\django\core\mail\__init__.py", line 87, in send_mail
    return mail.send()
           ^^^^^^^^^^^
  File "C:\Users\Lenovo\Downloads\Appstack\Appstack\env\Lib\site-packages\django\core\mail\message.py", line 298, in send
    return self.get_connection(fail_silently).send_messages([self])
           ^^^^^^^^^^^^^^^^^^^^^^^^^^^^^^^^^^^^^^^^^^^^^^^^^^^^^^^^
  File "C:\Users\Lenovo\Downloads\Appstack\Appstack\env\Lib\site-packages\django\core\mail\backends\smtp.py", line 127, in send_messages
    new_conn_created = self.open()
                       ^^^^^^^^^^^
  File "C:\Users\Lenovo\Downloads\Appstack\Appstack\env\Lib\site-packages\django\core\mail\backends\smtp.py", line 85, in open
    self.connection = self.connection_class(
                      ^^^^^^^^^^^^^^^^^^^^^^
  File "C:\Users\Lenovo\AppData\Local\Programs\Python\Python311\Lib\smtplib.py", line 255, in __init__
    (code, msg) = self.connect(host, port)
                  ^^^^^^^^^^^^^^^^^^^^^^^^
  File "C:\Users\Lenovo\AppData\Local\Programs\Python\Python311\Lib\smtplib.py", line 341, in connect
    self.sock = self._get_socket(host, port, self.timeout)
                ^^^^^^^^^^^^^^^^^^^^^^^^^^^^^^^^^^^^^^^^^^
  File "C:\Users\Lenovo\AppData\Local\Programs\Python\Python311\Lib\smtplib.py", line 312, in _get_socket
    return socket.create_connection((host, port), timeout,
           ^^^^^^^^^^^^^^^^^^^^^^^^^^^^^^^^^^^^^^^^^^^^^^^
  File "C:\Users\Lenovo\AppData\Local\Programs\Python\Python311\Lib\socket.py", line 827, in create_connection
    for res in getaddrinfo(host, port, 0, SOCK_STREAM):
               ^^^^^^^^^^^^^^^^^^^^^^^^^^^^^^^^^^^^^^^
  File "C:\Users\Lenovo\AppData\Local\Programs\Python\Python311\Lib\socket.py", line 962, in getaddrinfo
    for res in _socket.getaddrinfo(host, port, family, type, proto, flags):
               ^^^^^^^^^^^^^^^^^^^^^^^^^^^^^^^^^^^^^^^^^^^^^^^^^^^^^^^^^^^
socket.gaierror: [Errno 11001] getaddrinfo failed
ERROR 2023-10-05 17:58:29,132 log Internal Server Error: /api/login/
ERROR 2023-10-05 18:18:40,356 log Internal Server Error: /recipe/management/
Traceback (most recent call last):
  File "C:\Users\Lenovo\Downloads\Appstack\Appstack\env\Lib\site-packages\django\core\handlers\exception.py", line 55, in inner
    response = get_response(request)
               ^^^^^^^^^^^^^^^^^^^^^
  File "C:\Users\Lenovo\Downloads\Appstack\Appstack\env\Lib\site-packages\django\core\handlers\base.py", line 197, in _get_response
    response = wrapped_callback(request, *callback_args, **callback_kwargs)
               ^^^^^^^^^^^^^^^^^^^^^^^^^^^^^^^^^^^^^^^^^^^^^^^^^^^^^^^^^^^^
  File "C:\Users\Lenovo\Downloads\Appstack\Appstack\freelance_project\customer_engine\decorators.py", line 28, in _wrapped_view
    return view_func(request, *args, **kwargs)
           ^^^^^^^^^^^^^^^^^^^^^^^^^^^^^^^^^^^
  File "C:\Users\Lenovo\Downloads\Appstack\Appstack\freelance_project\backoffice_engine\views.py", line 306, in recipe_management
    return render(request,"recipe-management.html",{
           ^^^^^^^^^^^^^^^^^^^^^^^^^^^^^^^^^^^^^^^^^
  File "C:\Users\Lenovo\Downloads\Appstack\Appstack\env\Lib\site-packages\django\shortcuts.py", line 24, in render
    content = loader.render_to_string(template_name, context, request, using=using)
              ^^^^^^^^^^^^^^^^^^^^^^^^^^^^^^^^^^^^^^^^^^^^^^^^^^^^^^^^^^^^^^^^^^^^^
  File "C:\Users\Lenovo\Downloads\Appstack\Appstack\env\Lib\site-packages\django\template\loader.py", line 62, in render_to_string
    return template.render(context, request)
           ^^^^^^^^^^^^^^^^^^^^^^^^^^^^^^^^^
  File "C:\Users\Lenovo\Downloads\Appstack\Appstack\env\Lib\site-packages\django\template\backends\django.py", line 61, in render
    return self.template.render(context)
           ^^^^^^^^^^^^^^^^^^^^^^^^^^^^^
  File "C:\Users\Lenovo\Downloads\Appstack\Appstack\env\Lib\site-packages\django\template\base.py", line 175, in render
    return self._render(context)
           ^^^^^^^^^^^^^^^^^^^^^
  File "C:\Users\Lenovo\Downloads\Appstack\Appstack\env\Lib\site-packages\django\template\base.py", line 167, in _render
    return self.nodelist.render(context)
           ^^^^^^^^^^^^^^^^^^^^^^^^^^^^^
  File "C:\Users\Lenovo\Downloads\Appstack\Appstack\env\Lib\site-packages\django\template\base.py", line 1005, in render
    return SafeString("".join([node.render_annotated(context) for node in self]))
                              ^^^^^^^^^^^^^^^^^^^^^^^^^^^^^^^^^^^^^^^^^^^^^^^^^
  File "C:\Users\Lenovo\Downloads\Appstack\Appstack\env\Lib\site-packages\django\template\base.py", line 1005, in <listcomp>
    return SafeString("".join([node.render_annotated(context) for node in self]))
                               ^^^^^^^^^^^^^^^^^^^^^^^^^^^^^^
  File "C:\Users\Lenovo\Downloads\Appstack\Appstack\env\Lib\site-packages\django\template\base.py", line 966, in render_annotated
    return self.render(context)
           ^^^^^^^^^^^^^^^^^^^^
  File "C:\Users\Lenovo\Downloads\Appstack\Appstack\env\Lib\site-packages\django\template\defaulttags.py", line 471, in render
    url = reverse(view_name, args=args, kwargs=kwargs, current_app=current_app)
          ^^^^^^^^^^^^^^^^^^^^^^^^^^^^^^^^^^^^^^^^^^^^^^^^^^^^^^^^^^^^^^^^^^^^^
  File "C:\Users\Lenovo\Downloads\Appstack\Appstack\env\Lib\site-packages\django\urls\base.py", line 88, in reverse
    return resolver._reverse_with_prefix(view, prefix, *args, **kwargs)
           ^^^^^^^^^^^^^^^^^^^^^^^^^^^^^^^^^^^^^^^^^^^^^^^^^^^^^^^^^^^^
  File "C:\Users\Lenovo\Downloads\Appstack\Appstack\env\Lib\site-packages\django\urls\resolvers.py", line 828, in _reverse_with_prefix
    raise NoReverseMatch(msg)
django.urls.exceptions.NoReverseMatch: Reverse for 'customers_datatable' not found. 'customers_datatable' is not a valid view function or pattern name.
ERROR 2023-10-05 18:18:44,606 log Internal Server Error: /recipe/management/
Traceback (most recent call last):
  File "C:\Users\Lenovo\Downloads\Appstack\Appstack\env\Lib\site-packages\django\core\handlers\exception.py", line 55, in inner
    response = get_response(request)
               ^^^^^^^^^^^^^^^^^^^^^
  File "C:\Users\Lenovo\Downloads\Appstack\Appstack\env\Lib\site-packages\django\core\handlers\base.py", line 197, in _get_response
    response = wrapped_callback(request, *callback_args, **callback_kwargs)
               ^^^^^^^^^^^^^^^^^^^^^^^^^^^^^^^^^^^^^^^^^^^^^^^^^^^^^^^^^^^^
  File "C:\Users\Lenovo\Downloads\Appstack\Appstack\freelance_project\customer_engine\decorators.py", line 28, in _wrapped_view
    return view_func(request, *args, **kwargs)
           ^^^^^^^^^^^^^^^^^^^^^^^^^^^^^^^^^^^
  File "C:\Users\Lenovo\Downloads\Appstack\Appstack\freelance_project\backoffice_engine\views.py", line 306, in recipe_management
    return render(request,"recipe-management.html",{
           ^^^^^^^^^^^^^^^^^^^^^^^^^^^^^^^^^^^^^^^^^
  File "C:\Users\Lenovo\Downloads\Appstack\Appstack\env\Lib\site-packages\django\shortcuts.py", line 24, in render
    content = loader.render_to_string(template_name, context, request, using=using)
              ^^^^^^^^^^^^^^^^^^^^^^^^^^^^^^^^^^^^^^^^^^^^^^^^^^^^^^^^^^^^^^^^^^^^^
  File "C:\Users\Lenovo\Downloads\Appstack\Appstack\env\Lib\site-packages\django\template\loader.py", line 62, in render_to_string
    return template.render(context, request)
           ^^^^^^^^^^^^^^^^^^^^^^^^^^^^^^^^^
  File "C:\Users\Lenovo\Downloads\Appstack\Appstack\env\Lib\site-packages\django\template\backends\django.py", line 61, in render
    return self.template.render(context)
           ^^^^^^^^^^^^^^^^^^^^^^^^^^^^^
  File "C:\Users\Lenovo\Downloads\Appstack\Appstack\env\Lib\site-packages\django\template\base.py", line 175, in render
    return self._render(context)
           ^^^^^^^^^^^^^^^^^^^^^
  File "C:\Users\Lenovo\Downloads\Appstack\Appstack\env\Lib\site-packages\django\template\base.py", line 167, in _render
    return self.nodelist.render(context)
           ^^^^^^^^^^^^^^^^^^^^^^^^^^^^^
  File "C:\Users\Lenovo\Downloads\Appstack\Appstack\env\Lib\site-packages\django\template\base.py", line 1005, in render
    return SafeString("".join([node.render_annotated(context) for node in self]))
                              ^^^^^^^^^^^^^^^^^^^^^^^^^^^^^^^^^^^^^^^^^^^^^^^^^
  File "C:\Users\Lenovo\Downloads\Appstack\Appstack\env\Lib\site-packages\django\template\base.py", line 1005, in <listcomp>
    return SafeString("".join([node.render_annotated(context) for node in self]))
                               ^^^^^^^^^^^^^^^^^^^^^^^^^^^^^^
  File "C:\Users\Lenovo\Downloads\Appstack\Appstack\env\Lib\site-packages\django\template\base.py", line 966, in render_annotated
    return self.render(context)
           ^^^^^^^^^^^^^^^^^^^^
  File "C:\Users\Lenovo\Downloads\Appstack\Appstack\env\Lib\site-packages\django\template\defaulttags.py", line 471, in render
    url = reverse(view_name, args=args, kwargs=kwargs, current_app=current_app)
          ^^^^^^^^^^^^^^^^^^^^^^^^^^^^^^^^^^^^^^^^^^^^^^^^^^^^^^^^^^^^^^^^^^^^^
  File "C:\Users\Lenovo\Downloads\Appstack\Appstack\env\Lib\site-packages\django\urls\base.py", line 88, in reverse
    return resolver._reverse_with_prefix(view, prefix, *args, **kwargs)
           ^^^^^^^^^^^^^^^^^^^^^^^^^^^^^^^^^^^^^^^^^^^^^^^^^^^^^^^^^^^^
  File "C:\Users\Lenovo\Downloads\Appstack\Appstack\env\Lib\site-packages\django\urls\resolvers.py", line 828, in _reverse_with_prefix
    raise NoReverseMatch(msg)
django.urls.exceptions.NoReverseMatch: Reverse for 'customers_datatable' not found. 'customers_datatable' is not a valid view function or pattern name.
ERROR 2023-10-05 18:21:22,546 log Internal Server Error: /recipe/management/
Traceback (most recent call last):
  File "C:\Users\Lenovo\Downloads\Appstack\Appstack\env\Lib\site-packages\django\core\handlers\exception.py", line 55, in inner
    response = get_response(request)
               ^^^^^^^^^^^^^^^^^^^^^
  File "C:\Users\Lenovo\Downloads\Appstack\Appstack\env\Lib\site-packages\django\core\handlers\base.py", line 197, in _get_response
    response = wrapped_callback(request, *callback_args, **callback_kwargs)
               ^^^^^^^^^^^^^^^^^^^^^^^^^^^^^^^^^^^^^^^^^^^^^^^^^^^^^^^^^^^^
  File "C:\Users\Lenovo\Downloads\Appstack\Appstack\freelance_project\customer_engine\decorators.py", line 28, in _wrapped_view
    return view_func(request, *args, **kwargs)
           ^^^^^^^^^^^^^^^^^^^^^^^^^^^^^^^^^^^
  File "C:\Users\Lenovo\Downloads\Appstack\Appstack\freelance_project\backoffice_engine\views.py", line 306, in recipe_management
    return render(request,"recipe-management.html",{
           ^^^^^^^^^^^^^^^^^^^^^^^^^^^^^^^^^^^^^^^^^
  File "C:\Users\Lenovo\Downloads\Appstack\Appstack\env\Lib\site-packages\django\shortcuts.py", line 24, in render
    content = loader.render_to_string(template_name, context, request, using=using)
              ^^^^^^^^^^^^^^^^^^^^^^^^^^^^^^^^^^^^^^^^^^^^^^^^^^^^^^^^^^^^^^^^^^^^^
  File "C:\Users\Lenovo\Downloads\Appstack\Appstack\env\Lib\site-packages\django\template\loader.py", line 62, in render_to_string
    return template.render(context, request)
           ^^^^^^^^^^^^^^^^^^^^^^^^^^^^^^^^^
  File "C:\Users\Lenovo\Downloads\Appstack\Appstack\env\Lib\site-packages\django\template\backends\django.py", line 61, in render
    return self.template.render(context)
           ^^^^^^^^^^^^^^^^^^^^^^^^^^^^^
  File "C:\Users\Lenovo\Downloads\Appstack\Appstack\env\Lib\site-packages\django\template\base.py", line 175, in render
    return self._render(context)
           ^^^^^^^^^^^^^^^^^^^^^
  File "C:\Users\Lenovo\Downloads\Appstack\Appstack\env\Lib\site-packages\django\template\base.py", line 167, in _render
    return self.nodelist.render(context)
           ^^^^^^^^^^^^^^^^^^^^^^^^^^^^^
  File "C:\Users\Lenovo\Downloads\Appstack\Appstack\env\Lib\site-packages\django\template\base.py", line 1005, in render
    return SafeString("".join([node.render_annotated(context) for node in self]))
                              ^^^^^^^^^^^^^^^^^^^^^^^^^^^^^^^^^^^^^^^^^^^^^^^^^
  File "C:\Users\Lenovo\Downloads\Appstack\Appstack\env\Lib\site-packages\django\template\base.py", line 1005, in <listcomp>
    return SafeString("".join([node.render_annotated(context) for node in self]))
                               ^^^^^^^^^^^^^^^^^^^^^^^^^^^^^^
  File "C:\Users\Lenovo\Downloads\Appstack\Appstack\env\Lib\site-packages\django\template\base.py", line 966, in render_annotated
    return self.render(context)
           ^^^^^^^^^^^^^^^^^^^^
  File "C:\Users\Lenovo\Downloads\Appstack\Appstack\env\Lib\site-packages\django\template\defaulttags.py", line 471, in render
    url = reverse(view_name, args=args, kwargs=kwargs, current_app=current_app)
          ^^^^^^^^^^^^^^^^^^^^^^^^^^^^^^^^^^^^^^^^^^^^^^^^^^^^^^^^^^^^^^^^^^^^^
  File "C:\Users\Lenovo\Downloads\Appstack\Appstack\env\Lib\site-packages\django\urls\base.py", line 88, in reverse
    return resolver._reverse_with_prefix(view, prefix, *args, **kwargs)
           ^^^^^^^^^^^^^^^^^^^^^^^^^^^^^^^^^^^^^^^^^^^^^^^^^^^^^^^^^^^^
  File "C:\Users\Lenovo\Downloads\Appstack\Appstack\env\Lib\site-packages\django\urls\resolvers.py", line 828, in _reverse_with_prefix
    raise NoReverseMatch(msg)
django.urls.exceptions.NoReverseMatch: Reverse for 'ingredient_items' not found. 'ingredient_items' is not a valid view function or pattern name.
ERROR 2023-10-05 18:21:23,807 log Internal Server Error: /recipe/management/
Traceback (most recent call last):
  File "C:\Users\Lenovo\Downloads\Appstack\Appstack\env\Lib\site-packages\django\core\handlers\exception.py", line 55, in inner
    response = get_response(request)
               ^^^^^^^^^^^^^^^^^^^^^
  File "C:\Users\Lenovo\Downloads\Appstack\Appstack\env\Lib\site-packages\django\core\handlers\base.py", line 197, in _get_response
    response = wrapped_callback(request, *callback_args, **callback_kwargs)
               ^^^^^^^^^^^^^^^^^^^^^^^^^^^^^^^^^^^^^^^^^^^^^^^^^^^^^^^^^^^^
  File "C:\Users\Lenovo\Downloads\Appstack\Appstack\freelance_project\customer_engine\decorators.py", line 28, in _wrapped_view
    return view_func(request, *args, **kwargs)
           ^^^^^^^^^^^^^^^^^^^^^^^^^^^^^^^^^^^
  File "C:\Users\Lenovo\Downloads\Appstack\Appstack\freelance_project\backoffice_engine\views.py", line 306, in recipe_management
    return render(request,"recipe-management.html",{
           ^^^^^^^^^^^^^^^^^^^^^^^^^^^^^^^^^^^^^^^^^
  File "C:\Users\Lenovo\Downloads\Appstack\Appstack\env\Lib\site-packages\django\shortcuts.py", line 24, in render
    content = loader.render_to_string(template_name, context, request, using=using)
              ^^^^^^^^^^^^^^^^^^^^^^^^^^^^^^^^^^^^^^^^^^^^^^^^^^^^^^^^^^^^^^^^^^^^^
  File "C:\Users\Lenovo\Downloads\Appstack\Appstack\env\Lib\site-packages\django\template\loader.py", line 62, in render_to_string
    return template.render(context, request)
           ^^^^^^^^^^^^^^^^^^^^^^^^^^^^^^^^^
  File "C:\Users\Lenovo\Downloads\Appstack\Appstack\env\Lib\site-packages\django\template\backends\django.py", line 61, in render
    return self.template.render(context)
           ^^^^^^^^^^^^^^^^^^^^^^^^^^^^^
  File "C:\Users\Lenovo\Downloads\Appstack\Appstack\env\Lib\site-packages\django\template\base.py", line 175, in render
    return self._render(context)
           ^^^^^^^^^^^^^^^^^^^^^
  File "C:\Users\Lenovo\Downloads\Appstack\Appstack\env\Lib\site-packages\django\template\base.py", line 167, in _render
    return self.nodelist.render(context)
           ^^^^^^^^^^^^^^^^^^^^^^^^^^^^^
  File "C:\Users\Lenovo\Downloads\Appstack\Appstack\env\Lib\site-packages\django\template\base.py", line 1005, in render
    return SafeString("".join([node.render_annotated(context) for node in self]))
                              ^^^^^^^^^^^^^^^^^^^^^^^^^^^^^^^^^^^^^^^^^^^^^^^^^
  File "C:\Users\Lenovo\Downloads\Appstack\Appstack\env\Lib\site-packages\django\template\base.py", line 1005, in <listcomp>
    return SafeString("".join([node.render_annotated(context) for node in self]))
                               ^^^^^^^^^^^^^^^^^^^^^^^^^^^^^^
  File "C:\Users\Lenovo\Downloads\Appstack\Appstack\env\Lib\site-packages\django\template\base.py", line 966, in render_annotated
    return self.render(context)
           ^^^^^^^^^^^^^^^^^^^^
  File "C:\Users\Lenovo\Downloads\Appstack\Appstack\env\Lib\site-packages\django\template\defaulttags.py", line 471, in render
    url = reverse(view_name, args=args, kwargs=kwargs, current_app=current_app)
          ^^^^^^^^^^^^^^^^^^^^^^^^^^^^^^^^^^^^^^^^^^^^^^^^^^^^^^^^^^^^^^^^^^^^^
  File "C:\Users\Lenovo\Downloads\Appstack\Appstack\env\Lib\site-packages\django\urls\base.py", line 88, in reverse
    return resolver._reverse_with_prefix(view, prefix, *args, **kwargs)
           ^^^^^^^^^^^^^^^^^^^^^^^^^^^^^^^^^^^^^^^^^^^^^^^^^^^^^^^^^^^^
  File "C:\Users\Lenovo\Downloads\Appstack\Appstack\env\Lib\site-packages\django\urls\resolvers.py", line 828, in _reverse_with_prefix
    raise NoReverseMatch(msg)
django.urls.exceptions.NoReverseMatch: Reverse for 'ingredient_items' not found. 'ingredient_items' is not a valid view function or pattern name.
ERROR 2023-10-05 18:23:53,559 log Internal Server Error: /recipe/management/
Traceback (most recent call last):
  File "C:\Users\Lenovo\Downloads\Appstack\Appstack\env\Lib\site-packages\django\core\handlers\exception.py", line 55, in inner
    response = get_response(request)
               ^^^^^^^^^^^^^^^^^^^^^
  File "C:\Users\Lenovo\Downloads\Appstack\Appstack\env\Lib\site-packages\django\core\handlers\base.py", line 197, in _get_response
    response = wrapped_callback(request, *callback_args, **callback_kwargs)
               ^^^^^^^^^^^^^^^^^^^^^^^^^^^^^^^^^^^^^^^^^^^^^^^^^^^^^^^^^^^^
  File "C:\Users\Lenovo\Downloads\Appstack\Appstack\freelance_project\customer_engine\decorators.py", line 28, in _wrapped_view
    return view_func(request, *args, **kwargs)
           ^^^^^^^^^^^^^^^^^^^^^^^^^^^^^^^^^^^
  File "C:\Users\Lenovo\Downloads\Appstack\Appstack\freelance_project\backoffice_engine\views.py", line 306, in recipe_management
    return render(request,"recipe-management.html",{
           ^^^^^^^^^^^^^^^^^^^^^^^^^^^^^^^^^^^^^^^^^
  File "C:\Users\Lenovo\Downloads\Appstack\Appstack\env\Lib\site-packages\django\shortcuts.py", line 24, in render
    content = loader.render_to_string(template_name, context, request, using=using)
              ^^^^^^^^^^^^^^^^^^^^^^^^^^^^^^^^^^^^^^^^^^^^^^^^^^^^^^^^^^^^^^^^^^^^^
  File "C:\Users\Lenovo\Downloads\Appstack\Appstack\env\Lib\site-packages\django\template\loader.py", line 62, in render_to_string
    return template.render(context, request)
           ^^^^^^^^^^^^^^^^^^^^^^^^^^^^^^^^^
  File "C:\Users\Lenovo\Downloads\Appstack\Appstack\env\Lib\site-packages\django\template\backends\django.py", line 61, in render
    return self.template.render(context)
           ^^^^^^^^^^^^^^^^^^^^^^^^^^^^^
  File "C:\Users\Lenovo\Downloads\Appstack\Appstack\env\Lib\site-packages\django\template\base.py", line 175, in render
    return self._render(context)
           ^^^^^^^^^^^^^^^^^^^^^
  File "C:\Users\Lenovo\Downloads\Appstack\Appstack\env\Lib\site-packages\django\template\base.py", line 167, in _render
    return self.nodelist.render(context)
           ^^^^^^^^^^^^^^^^^^^^^^^^^^^^^
  File "C:\Users\Lenovo\Downloads\Appstack\Appstack\env\Lib\site-packages\django\template\base.py", line 1005, in render
    return SafeString("".join([node.render_annotated(context) for node in self]))
                              ^^^^^^^^^^^^^^^^^^^^^^^^^^^^^^^^^^^^^^^^^^^^^^^^^
  File "C:\Users\Lenovo\Downloads\Appstack\Appstack\env\Lib\site-packages\django\template\base.py", line 1005, in <listcomp>
    return SafeString("".join([node.render_annotated(context) for node in self]))
                               ^^^^^^^^^^^^^^^^^^^^^^^^^^^^^^
  File "C:\Users\Lenovo\Downloads\Appstack\Appstack\env\Lib\site-packages\django\template\base.py", line 966, in render_annotated
    return self.render(context)
           ^^^^^^^^^^^^^^^^^^^^
  File "C:\Users\Lenovo\Downloads\Appstack\Appstack\env\Lib\site-packages\django\template\defaulttags.py", line 471, in render
    url = reverse(view_name, args=args, kwargs=kwargs, current_app=current_app)
          ^^^^^^^^^^^^^^^^^^^^^^^^^^^^^^^^^^^^^^^^^^^^^^^^^^^^^^^^^^^^^^^^^^^^^
  File "C:\Users\Lenovo\Downloads\Appstack\Appstack\env\Lib\site-packages\django\urls\base.py", line 88, in reverse
    return resolver._reverse_with_prefix(view, prefix, *args, **kwargs)
           ^^^^^^^^^^^^^^^^^^^^^^^^^^^^^^^^^^^^^^^^^^^^^^^^^^^^^^^^^^^^
  File "C:\Users\Lenovo\Downloads\Appstack\Appstack\env\Lib\site-packages\django\urls\resolvers.py", line 828, in _reverse_with_prefix
    raise NoReverseMatch(msg)
django.urls.exceptions.NoReverseMatch: Reverse for 'upload_csv' not found. 'upload_csv' is not a valid view function or pattern name.
ERROR 2023-10-05 18:35:41,557 views An error occurred: [Errno 11001] getaddrinfo failed
Traceback (most recent call last):
  File "C:\Users\Lenovo\Downloads\Appstack\Appstack\freelance_project\customer_engine\views.py", line 337, in post
    send_mail(
  File "C:\Users\Lenovo\Downloads\Appstack\Appstack\env\Lib\site-packages\django\core\mail\__init__.py", line 87, in send_mail
    return mail.send()
           ^^^^^^^^^^^
  File "C:\Users\Lenovo\Downloads\Appstack\Appstack\env\Lib\site-packages\django\core\mail\message.py", line 298, in send
    return self.get_connection(fail_silently).send_messages([self])
           ^^^^^^^^^^^^^^^^^^^^^^^^^^^^^^^^^^^^^^^^^^^^^^^^^^^^^^^^
  File "C:\Users\Lenovo\Downloads\Appstack\Appstack\env\Lib\site-packages\django\core\mail\backends\smtp.py", line 127, in send_messages
    new_conn_created = self.open()
                       ^^^^^^^^^^^
  File "C:\Users\Lenovo\Downloads\Appstack\Appstack\env\Lib\site-packages\django\core\mail\backends\smtp.py", line 85, in open
    self.connection = self.connection_class(
                      ^^^^^^^^^^^^^^^^^^^^^^
  File "C:\Users\Lenovo\AppData\Local\Programs\Python\Python311\Lib\smtplib.py", line 255, in __init__
    (code, msg) = self.connect(host, port)
                  ^^^^^^^^^^^^^^^^^^^^^^^^
  File "C:\Users\Lenovo\AppData\Local\Programs\Python\Python311\Lib\smtplib.py", line 341, in connect
    self.sock = self._get_socket(host, port, self.timeout)
                ^^^^^^^^^^^^^^^^^^^^^^^^^^^^^^^^^^^^^^^^^^
  File "C:\Users\Lenovo\AppData\Local\Programs\Python\Python311\Lib\smtplib.py", line 312, in _get_socket
    return socket.create_connection((host, port), timeout,
           ^^^^^^^^^^^^^^^^^^^^^^^^^^^^^^^^^^^^^^^^^^^^^^^
  File "C:\Users\Lenovo\AppData\Local\Programs\Python\Python311\Lib\socket.py", line 827, in create_connection
    for res in getaddrinfo(host, port, 0, SOCK_STREAM):
               ^^^^^^^^^^^^^^^^^^^^^^^^^^^^^^^^^^^^^^^
  File "C:\Users\Lenovo\AppData\Local\Programs\Python\Python311\Lib\socket.py", line 962, in getaddrinfo
    for res in _socket.getaddrinfo(host, port, family, type, proto, flags):
               ^^^^^^^^^^^^^^^^^^^^^^^^^^^^^^^^^^^^^^^^^^^^^^^^^^^^^^^^^^^
socket.gaierror: [Errno 11001] getaddrinfo failed
ERROR 2023-10-05 18:35:41,565 log Internal Server Error: /api/login/
ERROR 2023-10-05 18:49:13,495 views An error occurred: [Errno 11001] getaddrinfo failed
Traceback (most recent call last):
  File "C:\Users\Lenovo\Downloads\Appstack\Appstack\freelance_project\customer_engine\views.py", line 341, in post
    send_mail(
  File "C:\Users\Lenovo\Downloads\Appstack\Appstack\env\Lib\site-packages\django\core\mail\__init__.py", line 87, in send_mail
    return mail.send()
           ^^^^^^^^^^^
  File "C:\Users\Lenovo\Downloads\Appstack\Appstack\env\Lib\site-packages\django\core\mail\message.py", line 298, in send
    return self.get_connection(fail_silently).send_messages([self])
           ^^^^^^^^^^^^^^^^^^^^^^^^^^^^^^^^^^^^^^^^^^^^^^^^^^^^^^^^
  File "C:\Users\Lenovo\Downloads\Appstack\Appstack\env\Lib\site-packages\django\core\mail\backends\smtp.py", line 127, in send_messages
    new_conn_created = self.open()
                       ^^^^^^^^^^^
  File "C:\Users\Lenovo\Downloads\Appstack\Appstack\env\Lib\site-packages\django\core\mail\backends\smtp.py", line 85, in open
    self.connection = self.connection_class(
                      ^^^^^^^^^^^^^^^^^^^^^^
  File "C:\Users\Lenovo\AppData\Local\Programs\Python\Python311\Lib\smtplib.py", line 255, in __init__
    (code, msg) = self.connect(host, port)
                  ^^^^^^^^^^^^^^^^^^^^^^^^
  File "C:\Users\Lenovo\AppData\Local\Programs\Python\Python311\Lib\smtplib.py", line 341, in connect
    self.sock = self._get_socket(host, port, self.timeout)
                ^^^^^^^^^^^^^^^^^^^^^^^^^^^^^^^^^^^^^^^^^^
  File "C:\Users\Lenovo\AppData\Local\Programs\Python\Python311\Lib\smtplib.py", line 312, in _get_socket
    return socket.create_connection((host, port), timeout,
           ^^^^^^^^^^^^^^^^^^^^^^^^^^^^^^^^^^^^^^^^^^^^^^^
  File "C:\Users\Lenovo\AppData\Local\Programs\Python\Python311\Lib\socket.py", line 827, in create_connection
    for res in getaddrinfo(host, port, 0, SOCK_STREAM):
               ^^^^^^^^^^^^^^^^^^^^^^^^^^^^^^^^^^^^^^^
  File "C:\Users\Lenovo\AppData\Local\Programs\Python\Python311\Lib\socket.py", line 962, in getaddrinfo
    for res in _socket.getaddrinfo(host, port, family, type, proto, flags):
               ^^^^^^^^^^^^^^^^^^^^^^^^^^^^^^^^^^^^^^^^^^^^^^^^^^^^^^^^^^^
socket.gaierror: [Errno 11001] getaddrinfo failed
ERROR 2023-10-05 18:49:13,520 log Internal Server Error: /api/login/
ERROR 2023-10-05 18:51:15,053 views An error occurred: [Errno 11001] getaddrinfo failed
Traceback (most recent call last):
  File "C:\Users\Lenovo\Downloads\Appstack\Appstack\freelance_project\customer_engine\views.py", line 341, in post
    send_mail(
  File "C:\Users\Lenovo\Downloads\Appstack\Appstack\env\Lib\site-packages\django\core\mail\__init__.py", line 87, in send_mail
    return mail.send()
           ^^^^^^^^^^^
  File "C:\Users\Lenovo\Downloads\Appstack\Appstack\env\Lib\site-packages\django\core\mail\message.py", line 298, in send
    return self.get_connection(fail_silently).send_messages([self])
           ^^^^^^^^^^^^^^^^^^^^^^^^^^^^^^^^^^^^^^^^^^^^^^^^^^^^^^^^
  File "C:\Users\Lenovo\Downloads\Appstack\Appstack\env\Lib\site-packages\django\core\mail\backends\smtp.py", line 127, in send_messages
    new_conn_created = self.open()
                       ^^^^^^^^^^^
  File "C:\Users\Lenovo\Downloads\Appstack\Appstack\env\Lib\site-packages\django\core\mail\backends\smtp.py", line 85, in open
    self.connection = self.connection_class(
                      ^^^^^^^^^^^^^^^^^^^^^^
  File "C:\Users\Lenovo\AppData\Local\Programs\Python\Python311\Lib\smtplib.py", line 255, in __init__
    (code, msg) = self.connect(host, port)
                  ^^^^^^^^^^^^^^^^^^^^^^^^
  File "C:\Users\Lenovo\AppData\Local\Programs\Python\Python311\Lib\smtplib.py", line 341, in connect
    self.sock = self._get_socket(host, port, self.timeout)
                ^^^^^^^^^^^^^^^^^^^^^^^^^^^^^^^^^^^^^^^^^^
  File "C:\Users\Lenovo\AppData\Local\Programs\Python\Python311\Lib\smtplib.py", line 312, in _get_socket
    return socket.create_connection((host, port), timeout,
           ^^^^^^^^^^^^^^^^^^^^^^^^^^^^^^^^^^^^^^^^^^^^^^^
  File "C:\Users\Lenovo\AppData\Local\Programs\Python\Python311\Lib\socket.py", line 827, in create_connection
    for res in getaddrinfo(host, port, 0, SOCK_STREAM):
               ^^^^^^^^^^^^^^^^^^^^^^^^^^^^^^^^^^^^^^^
  File "C:\Users\Lenovo\AppData\Local\Programs\Python\Python311\Lib\socket.py", line 962, in getaddrinfo
    for res in _socket.getaddrinfo(host, port, family, type, proto, flags):
               ^^^^^^^^^^^^^^^^^^^^^^^^^^^^^^^^^^^^^^^^^^^^^^^^^^^^^^^^^^^
socket.gaierror: [Errno 11001] getaddrinfo failed
ERROR 2023-10-05 18:51:15,077 log Internal Server Error: /api/login/
ERROR 2023-10-05 18:51:23,573 views An error occurred: [Errno 11001] getaddrinfo failed
Traceback (most recent call last):
  File "C:\Users\Lenovo\Downloads\Appstack\Appstack\freelance_project\customer_engine\views.py", line 341, in post
    send_mail(
  File "C:\Users\Lenovo\Downloads\Appstack\Appstack\env\Lib\site-packages\django\core\mail\__init__.py", line 87, in send_mail
    return mail.send()
           ^^^^^^^^^^^
  File "C:\Users\Lenovo\Downloads\Appstack\Appstack\env\Lib\site-packages\django\core\mail\message.py", line 298, in send
    return self.get_connection(fail_silently).send_messages([self])
           ^^^^^^^^^^^^^^^^^^^^^^^^^^^^^^^^^^^^^^^^^^^^^^^^^^^^^^^^
  File "C:\Users\Lenovo\Downloads\Appstack\Appstack\env\Lib\site-packages\django\core\mail\backends\smtp.py", line 127, in send_messages
    new_conn_created = self.open()
                       ^^^^^^^^^^^
  File "C:\Users\Lenovo\Downloads\Appstack\Appstack\env\Lib\site-packages\django\core\mail\backends\smtp.py", line 85, in open
    self.connection = self.connection_class(
                      ^^^^^^^^^^^^^^^^^^^^^^
  File "C:\Users\Lenovo\AppData\Local\Programs\Python\Python311\Lib\smtplib.py", line 255, in __init__
    (code, msg) = self.connect(host, port)
                  ^^^^^^^^^^^^^^^^^^^^^^^^
  File "C:\Users\Lenovo\AppData\Local\Programs\Python\Python311\Lib\smtplib.py", line 341, in connect
    self.sock = self._get_socket(host, port, self.timeout)
                ^^^^^^^^^^^^^^^^^^^^^^^^^^^^^^^^^^^^^^^^^^
  File "C:\Users\Lenovo\AppData\Local\Programs\Python\Python311\Lib\smtplib.py", line 312, in _get_socket
    return socket.create_connection((host, port), timeout,
           ^^^^^^^^^^^^^^^^^^^^^^^^^^^^^^^^^^^^^^^^^^^^^^^
  File "C:\Users\Lenovo\AppData\Local\Programs\Python\Python311\Lib\socket.py", line 827, in create_connection
    for res in getaddrinfo(host, port, 0, SOCK_STREAM):
               ^^^^^^^^^^^^^^^^^^^^^^^^^^^^^^^^^^^^^^^
  File "C:\Users\Lenovo\AppData\Local\Programs\Python\Python311\Lib\socket.py", line 962, in getaddrinfo
    for res in _socket.getaddrinfo(host, port, family, type, proto, flags):
               ^^^^^^^^^^^^^^^^^^^^^^^^^^^^^^^^^^^^^^^^^^^^^^^^^^^^^^^^^^^
socket.gaierror: [Errno 11001] getaddrinfo failed
ERROR 2023-10-05 18:51:23,573 log Internal Server Error: /api/login/
ERROR 2023-10-05 18:51:26,355 views An error occurred: [Errno 11001] getaddrinfo failed
Traceback (most recent call last):
  File "C:\Users\Lenovo\Downloads\Appstack\Appstack\freelance_project\customer_engine\views.py", line 341, in post
    send_mail(
  File "C:\Users\Lenovo\Downloads\Appstack\Appstack\env\Lib\site-packages\django\core\mail\__init__.py", line 87, in send_mail
    return mail.send()
           ^^^^^^^^^^^
  File "C:\Users\Lenovo\Downloads\Appstack\Appstack\env\Lib\site-packages\django\core\mail\message.py", line 298, in send
    return self.get_connection(fail_silently).send_messages([self])
           ^^^^^^^^^^^^^^^^^^^^^^^^^^^^^^^^^^^^^^^^^^^^^^^^^^^^^^^^
  File "C:\Users\Lenovo\Downloads\Appstack\Appstack\env\Lib\site-packages\django\core\mail\backends\smtp.py", line 127, in send_messages
    new_conn_created = self.open()
                       ^^^^^^^^^^^
  File "C:\Users\Lenovo\Downloads\Appstack\Appstack\env\Lib\site-packages\django\core\mail\backends\smtp.py", line 85, in open
    self.connection = self.connection_class(
                      ^^^^^^^^^^^^^^^^^^^^^^
  File "C:\Users\Lenovo\AppData\Local\Programs\Python\Python311\Lib\smtplib.py", line 255, in __init__
    (code, msg) = self.connect(host, port)
                  ^^^^^^^^^^^^^^^^^^^^^^^^
  File "C:\Users\Lenovo\AppData\Local\Programs\Python\Python311\Lib\smtplib.py", line 341, in connect
    self.sock = self._get_socket(host, port, self.timeout)
                ^^^^^^^^^^^^^^^^^^^^^^^^^^^^^^^^^^^^^^^^^^
  File "C:\Users\Lenovo\AppData\Local\Programs\Python\Python311\Lib\smtplib.py", line 312, in _get_socket
    return socket.create_connection((host, port), timeout,
           ^^^^^^^^^^^^^^^^^^^^^^^^^^^^^^^^^^^^^^^^^^^^^^^
  File "C:\Users\Lenovo\AppData\Local\Programs\Python\Python311\Lib\socket.py", line 827, in create_connection
    for res in getaddrinfo(host, port, 0, SOCK_STREAM):
               ^^^^^^^^^^^^^^^^^^^^^^^^^^^^^^^^^^^^^^^
  File "C:\Users\Lenovo\AppData\Local\Programs\Python\Python311\Lib\socket.py", line 962, in getaddrinfo
    for res in _socket.getaddrinfo(host, port, family, type, proto, flags):
               ^^^^^^^^^^^^^^^^^^^^^^^^^^^^^^^^^^^^^^^^^^^^^^^^^^^^^^^^^^^
socket.gaierror: [Errno 11001] getaddrinfo failed
ERROR 2023-10-05 18:51:26,355 log Internal Server Error: /api/login/
ERROR 2023-10-05 18:52:57,179 views An error occurred: [Errno 11001] getaddrinfo failed
Traceback (most recent call last):
  File "C:\Users\Lenovo\Downloads\Appstack\Appstack\freelance_project\customer_engine\views.py", line 340, in post
    send_mail(
  File "C:\Users\Lenovo\Downloads\Appstack\Appstack\env\Lib\site-packages\django\core\mail\__init__.py", line 87, in send_mail
    return mail.send()
           ^^^^^^^^^^^
  File "C:\Users\Lenovo\Downloads\Appstack\Appstack\env\Lib\site-packages\django\core\mail\message.py", line 298, in send
    return self.get_connection(fail_silently).send_messages([self])
           ^^^^^^^^^^^^^^^^^^^^^^^^^^^^^^^^^^^^^^^^^^^^^^^^^^^^^^^^
  File "C:\Users\Lenovo\Downloads\Appstack\Appstack\env\Lib\site-packages\django\core\mail\backends\smtp.py", line 127, in send_messages
    new_conn_created = self.open()
                       ^^^^^^^^^^^
  File "C:\Users\Lenovo\Downloads\Appstack\Appstack\env\Lib\site-packages\django\core\mail\backends\smtp.py", line 85, in open
    self.connection = self.connection_class(
                      ^^^^^^^^^^^^^^^^^^^^^^
  File "C:\Users\Lenovo\AppData\Local\Programs\Python\Python311\Lib\smtplib.py", line 255, in __init__
    (code, msg) = self.connect(host, port)
                  ^^^^^^^^^^^^^^^^^^^^^^^^
  File "C:\Users\Lenovo\AppData\Local\Programs\Python\Python311\Lib\smtplib.py", line 341, in connect
    self.sock = self._get_socket(host, port, self.timeout)
                ^^^^^^^^^^^^^^^^^^^^^^^^^^^^^^^^^^^^^^^^^^
  File "C:\Users\Lenovo\AppData\Local\Programs\Python\Python311\Lib\smtplib.py", line 312, in _get_socket
    return socket.create_connection((host, port), timeout,
           ^^^^^^^^^^^^^^^^^^^^^^^^^^^^^^^^^^^^^^^^^^^^^^^
  File "C:\Users\Lenovo\AppData\Local\Programs\Python\Python311\Lib\socket.py", line 827, in create_connection
    for res in getaddrinfo(host, port, 0, SOCK_STREAM):
               ^^^^^^^^^^^^^^^^^^^^^^^^^^^^^^^^^^^^^^^
  File "C:\Users\Lenovo\AppData\Local\Programs\Python\Python311\Lib\socket.py", line 962, in getaddrinfo
    for res in _socket.getaddrinfo(host, port, family, type, proto, flags):
               ^^^^^^^^^^^^^^^^^^^^^^^^^^^^^^^^^^^^^^^^^^^^^^^^^^^^^^^^^^^
socket.gaierror: [Errno 11001] getaddrinfo failed
ERROR 2023-10-05 18:52:57,211 log Internal Server Error: /api/login/
ERROR 2023-10-05 19:00:41,431 log Internal Server Error: /customers/detail/30/
Traceback (most recent call last):
  File "C:\Users\Lenovo\Downloads\Appstack\Appstack\env\Lib\site-packages\django\core\handlers\exception.py", line 55, in inner
    response = get_response(request)
               ^^^^^^^^^^^^^^^^^^^^^
  File "C:\Users\Lenovo\Downloads\Appstack\Appstack\env\Lib\site-packages\django\core\handlers\base.py", line 197, in _get_response
    response = wrapped_callback(request, *callback_args, **callback_kwargs)
               ^^^^^^^^^^^^^^^^^^^^^^^^^^^^^^^^^^^^^^^^^^^^^^^^^^^^^^^^^^^^
  File "C:\Users\Lenovo\Downloads\Appstack\Appstack\freelance_project\customer_engine\decorators.py", line 28, in _wrapped_view
    return view_func(request, *args, **kwargs)
           ^^^^^^^^^^^^^^^^^^^^^^^^^^^^^^^^^^^
  File "C:\Users\Lenovo\Downloads\Appstack\Appstack\freelance_project\backoffice_engine\views.py", line 347, in customers_detail
    data = UserSnacks.objects.get(customer = user_id)
           ^^^^^^^^^^^^^^^^^^^^^^^^^^^^^^^^^^^^^^^^^^
  File "C:\Users\Lenovo\Downloads\Appstack\Appstack\env\Lib\site-packages\django\db\models\manager.py", line 87, in manager_method
    return getattr(self.get_queryset(), name)(*args, **kwargs)
           ^^^^^^^^^^^^^^^^^^^^^^^^^^^^^^^^^^^^^^^^^^^^^^^^^^^
  File "C:\Users\Lenovo\Downloads\Appstack\Appstack\env\Lib\site-packages\django\db\models\query.py", line 637, in get
    raise self.model.DoesNotExist(
customer_engine.models.UserSnacks.DoesNotExist: UserSnacks matching query does not exist.
ERROR 2023-10-05 19:00:51,512 log Internal Server Error: /customers/detail/31/
Traceback (most recent call last):
  File "C:\Users\Lenovo\Downloads\Appstack\Appstack\env\Lib\site-packages\django\core\handlers\exception.py", line 55, in inner
    response = get_response(request)
               ^^^^^^^^^^^^^^^^^^^^^
  File "C:\Users\Lenovo\Downloads\Appstack\Appstack\env\Lib\site-packages\django\core\handlers\base.py", line 197, in _get_response
    response = wrapped_callback(request, *callback_args, **callback_kwargs)
               ^^^^^^^^^^^^^^^^^^^^^^^^^^^^^^^^^^^^^^^^^^^^^^^^^^^^^^^^^^^^
  File "C:\Users\Lenovo\Downloads\Appstack\Appstack\freelance_project\customer_engine\decorators.py", line 28, in _wrapped_view
    return view_func(request, *args, **kwargs)
           ^^^^^^^^^^^^^^^^^^^^^^^^^^^^^^^^^^^
  File "C:\Users\Lenovo\Downloads\Appstack\Appstack\freelance_project\backoffice_engine\views.py", line 347, in customers_detail
    data = UserSnacks.objects.get(customer = user_id)
           ^^^^^^^^^^^^^^^^^^^^^^^^^^^^^^^^^^^^^^^^^^
  File "C:\Users\Lenovo\Downloads\Appstack\Appstack\env\Lib\site-packages\django\db\models\manager.py", line 87, in manager_method
    return getattr(self.get_queryset(), name)(*args, **kwargs)
           ^^^^^^^^^^^^^^^^^^^^^^^^^^^^^^^^^^^^^^^^^^^^^^^^^^^
  File "C:\Users\Lenovo\Downloads\Appstack\Appstack\env\Lib\site-packages\django\db\models\query.py", line 637, in get
    raise self.model.DoesNotExist(
customer_engine.models.UserSnacks.DoesNotExist: UserSnacks matching query does not exist.
ERROR 2023-10-05 19:00:58,582 log Internal Server Error: /customers/detail/30/
Traceback (most recent call last):
  File "C:\Users\Lenovo\Downloads\Appstack\Appstack\env\Lib\site-packages\django\core\handlers\exception.py", line 55, in inner
    response = get_response(request)
               ^^^^^^^^^^^^^^^^^^^^^
  File "C:\Users\Lenovo\Downloads\Appstack\Appstack\env\Lib\site-packages\django\core\handlers\base.py", line 197, in _get_response
    response = wrapped_callback(request, *callback_args, **callback_kwargs)
               ^^^^^^^^^^^^^^^^^^^^^^^^^^^^^^^^^^^^^^^^^^^^^^^^^^^^^^^^^^^^
  File "C:\Users\Lenovo\Downloads\Appstack\Appstack\freelance_project\customer_engine\decorators.py", line 28, in _wrapped_view
    return view_func(request, *args, **kwargs)
           ^^^^^^^^^^^^^^^^^^^^^^^^^^^^^^^^^^^
  File "C:\Users\Lenovo\Downloads\Appstack\Appstack\freelance_project\backoffice_engine\views.py", line 347, in customers_detail
    data = UserSnacks.objects.get(customer = user_id)
           ^^^^^^^^^^^^^^^^^^^^^^^^^^^^^^^^^^^^^^^^^^
  File "C:\Users\Lenovo\Downloads\Appstack\Appstack\env\Lib\site-packages\django\db\models\manager.py", line 87, in manager_method
    return getattr(self.get_queryset(), name)(*args, **kwargs)
           ^^^^^^^^^^^^^^^^^^^^^^^^^^^^^^^^^^^^^^^^^^^^^^^^^^^
  File "C:\Users\Lenovo\Downloads\Appstack\Appstack\env\Lib\site-packages\django\db\models\query.py", line 637, in get
    raise self.model.DoesNotExist(
customer_engine.models.UserSnacks.DoesNotExist: UserSnacks matching query does not exist.
ERROR 2023-10-05 19:08:57,646 views An error occurred: name 'settings' is not defined
Traceback (most recent call last):
  File "C:\Users\Lenovo\Downloads\Appstack\Appstack\freelance_project\customer_engine\views.py", line 337, in post
    from_email = settings.EMAIL_HOST_USER
                 ^^^^^^^^
NameError: name 'settings' is not defined
ERROR 2023-10-05 19:08:57,654 log Internal Server Error: /api/login/
ERROR 2023-10-05 19:13:20,922 views An error occurred: name 'settings' is not defined
Traceback (most recent call last):
  File "C:\Users\Lenovo\Downloads\Appstack\Appstack\freelance_project\customer_engine\views.py", line 337, in post
    from_email = settings.EMAIL_HOST_USER
                 ^^^^^^^^
NameError: name 'settings' is not defined
ERROR 2023-10-05 19:13:20,930 log Internal Server Error: /api/login/
ERROR 2023-10-05 19:16:04,185 views An error occurred: name 'settings' is not defined
Traceback (most recent call last):
  File "C:\Users\Lenovo\Downloads\Appstack\Appstack\freelance_project\customer_engine\views.py", line 337, in post
    from_email = settings.EMAIL_HOST_USER
                 ^^^^^^^^
NameError: name 'settings' is not defined
ERROR 2023-10-05 19:16:04,242 log Internal Server Error: /api/login/
ERROR 2023-10-05 19:20:54,563 views An error occurred: [Errno 11001] getaddrinfo failed
Traceback (most recent call last):
  File "C:\Users\Lenovo\Downloads\Appstack\Appstack\freelance_project\customer_engine\views.py", line 340, in post
    send_mail(
  File "C:\Users\Lenovo\Downloads\Appstack\Appstack\env\Lib\site-packages\django\core\mail\__init__.py", line 87, in send_mail
    return mail.send()
           ^^^^^^^^^^^
  File "C:\Users\Lenovo\Downloads\Appstack\Appstack\env\Lib\site-packages\django\core\mail\message.py", line 298, in send
    return self.get_connection(fail_silently).send_messages([self])
           ^^^^^^^^^^^^^^^^^^^^^^^^^^^^^^^^^^^^^^^^^^^^^^^^^^^^^^^^
  File "C:\Users\Lenovo\Downloads\Appstack\Appstack\env\Lib\site-packages\django\core\mail\backends\smtp.py", line 127, in send_messages
    new_conn_created = self.open()
                       ^^^^^^^^^^^
  File "C:\Users\Lenovo\Downloads\Appstack\Appstack\env\Lib\site-packages\django\core\mail\backends\smtp.py", line 85, in open
    self.connection = self.connection_class(
                      ^^^^^^^^^^^^^^^^^^^^^^
  File "C:\Users\Lenovo\AppData\Local\Programs\Python\Python311\Lib\smtplib.py", line 255, in __init__
    (code, msg) = self.connect(host, port)
                  ^^^^^^^^^^^^^^^^^^^^^^^^
  File "C:\Users\Lenovo\AppData\Local\Programs\Python\Python311\Lib\smtplib.py", line 341, in connect
    self.sock = self._get_socket(host, port, self.timeout)
                ^^^^^^^^^^^^^^^^^^^^^^^^^^^^^^^^^^^^^^^^^^
  File "C:\Users\Lenovo\AppData\Local\Programs\Python\Python311\Lib\smtplib.py", line 312, in _get_socket
    return socket.create_connection((host, port), timeout,
           ^^^^^^^^^^^^^^^^^^^^^^^^^^^^^^^^^^^^^^^^^^^^^^^
  File "C:\Users\Lenovo\AppData\Local\Programs\Python\Python311\Lib\socket.py", line 827, in create_connection
    for res in getaddrinfo(host, port, 0, SOCK_STREAM):
               ^^^^^^^^^^^^^^^^^^^^^^^^^^^^^^^^^^^^^^^
  File "C:\Users\Lenovo\AppData\Local\Programs\Python\Python311\Lib\socket.py", line 962, in getaddrinfo
    for res in _socket.getaddrinfo(host, port, family, type, proto, flags):
               ^^^^^^^^^^^^^^^^^^^^^^^^^^^^^^^^^^^^^^^^^^^^^^^^^^^^^^^^^^^
socket.gaierror: [Errno 11001] getaddrinfo failed
ERROR 2023-10-05 19:20:54,586 log Internal Server Error: /api/login/
ERROR 2023-10-05 19:23:27,135 views An error occurred: name 'settings' is not defined
Traceback (most recent call last):
  File "C:\Users\Lenovo\Downloads\Appstack\Appstack\freelance_project\customer_engine\views.py", line 337, in post
    from_email = settings.EMAIL_HOST_USER
                 ^^^^^^^^
NameError: name 'settings' is not defined
ERROR 2023-10-05 19:23:27,143 log Internal Server Error: /api/login/
ERROR 2023-10-05 19:25:42,175 views An error occurred: name 'settings' is not defined
Traceback (most recent call last):
  File "C:\Users\Lenovo\Downloads\Appstack\Appstack\freelance_project\customer_engine\views.py", line 337, in post
    from_email = settings.EMAIL_HOST_USER
                 ^^^^^^^^
NameError: name 'settings' is not defined
ERROR 2023-10-05 19:25:42,175 log Internal Server Error: /api/login/
ERROR 2023-10-05 19:27:47,316 views An error occurred: name 'settings' is not defined
Traceback (most recent call last):
  File "C:\Users\Lenovo\Downloads\Appstack\Appstack\freelance_project\customer_engine\views.py", line 337, in post
    from_email = settings.EMAIL_HOST_USER
                 ^^^^^^^^
NameError: name 'settings' is not defined
ERROR 2023-10-05 19:27:47,320 log Internal Server Error: /api/login/
ERROR 2023-10-05 19:32:53,717 views An error occurred: name 'settings' is not defined
Traceback (most recent call last):
  File "C:\Users\Lenovo\Downloads\Appstack\Appstack\freelance_project\customer_engine\views.py", line 337, in post
    from_email = settings.EMAIL_HOST_USER
                 ^^^^^^^^
NameError: name 'settings' is not defined
ERROR 2023-10-05 19:32:53,725 log Internal Server Error: /api/login/
ERROR 2023-10-05 19:35:57,052 log Internal Server Error: /customers/detail/30/
Traceback (most recent call last):
  File "C:\Users\Lenovo\Downloads\Appstack\Appstack\env\Lib\site-packages\django\core\handlers\exception.py", line 55, in inner
    response = get_response(request)
               ^^^^^^^^^^^^^^^^^^^^^
  File "C:\Users\Lenovo\Downloads\Appstack\Appstack\env\Lib\site-packages\django\core\handlers\base.py", line 197, in _get_response
    response = wrapped_callback(request, *callback_args, **callback_kwargs)
               ^^^^^^^^^^^^^^^^^^^^^^^^^^^^^^^^^^^^^^^^^^^^^^^^^^^^^^^^^^^^
  File "C:\Users\Lenovo\Downloads\Appstack\Appstack\freelance_project\customer_engine\decorators.py", line 28, in _wrapped_view
    return view_func(request, *args, **kwargs)
           ^^^^^^^^^^^^^^^^^^^^^^^^^^^^^^^^^^^
  File "C:\Users\Lenovo\Downloads\Appstack\Appstack\freelance_project\backoffice_engine\views.py", line 347, in customers_detail
    data = UserSnacks.objects.get(customer = user_id)
           ^^^^^^^^^^^^^^^^^^^^^^^^^^^^^^^^^^^^^^^^^^
  File "C:\Users\Lenovo\Downloads\Appstack\Appstack\env\Lib\site-packages\django\db\models\manager.py", line 87, in manager_method
    return getattr(self.get_queryset(), name)(*args, **kwargs)
           ^^^^^^^^^^^^^^^^^^^^^^^^^^^^^^^^^^^^^^^^^^^^^^^^^^^
  File "C:\Users\Lenovo\Downloads\Appstack\Appstack\env\Lib\site-packages\django\db\models\query.py", line 637, in get
    raise self.model.DoesNotExist(
customer_engine.models.UserSnacks.DoesNotExist: UserSnacks matching query does not exist.
ERROR 2023-10-05 19:36:02,329 log Internal Server Error: /customers/detail/32/
Traceback (most recent call last):
  File "C:\Users\Lenovo\Downloads\Appstack\Appstack\env\Lib\site-packages\django\core\handlers\exception.py", line 55, in inner
    response = get_response(request)
               ^^^^^^^^^^^^^^^^^^^^^
  File "C:\Users\Lenovo\Downloads\Appstack\Appstack\env\Lib\site-packages\django\core\handlers\base.py", line 197, in _get_response
    response = wrapped_callback(request, *callback_args, **callback_kwargs)
               ^^^^^^^^^^^^^^^^^^^^^^^^^^^^^^^^^^^^^^^^^^^^^^^^^^^^^^^^^^^^
  File "C:\Users\Lenovo\Downloads\Appstack\Appstack\freelance_project\customer_engine\decorators.py", line 28, in _wrapped_view
    return view_func(request, *args, **kwargs)
           ^^^^^^^^^^^^^^^^^^^^^^^^^^^^^^^^^^^
  File "C:\Users\Lenovo\Downloads\Appstack\Appstack\freelance_project\backoffice_engine\views.py", line 347, in customers_detail
    data = UserSnacks.objects.get(customer = user_id)
           ^^^^^^^^^^^^^^^^^^^^^^^^^^^^^^^^^^^^^^^^^^
  File "C:\Users\Lenovo\Downloads\Appstack\Appstack\env\Lib\site-packages\django\db\models\manager.py", line 87, in manager_method
    return getattr(self.get_queryset(), name)(*args, **kwargs)
           ^^^^^^^^^^^^^^^^^^^^^^^^^^^^^^^^^^^^^^^^^^^^^^^^^^^
  File "C:\Users\Lenovo\Downloads\Appstack\Appstack\env\Lib\site-packages\django\db\models\query.py", line 640, in get
    raise self.model.MultipleObjectsReturned(
customer_engine.models.UserSnacks.MultipleObjectsReturned: get() returned more than one UserSnacks -- it returned 4!
ERROR 2023-10-05 19:36:09,214 log Internal Server Error: /customers/detail/31/
Traceback (most recent call last):
  File "C:\Users\Lenovo\Downloads\Appstack\Appstack\env\Lib\site-packages\django\core\handlers\exception.py", line 55, in inner
    response = get_response(request)
               ^^^^^^^^^^^^^^^^^^^^^
  File "C:\Users\Lenovo\Downloads\Appstack\Appstack\env\Lib\site-packages\django\core\handlers\base.py", line 197, in _get_response
    response = wrapped_callback(request, *callback_args, **callback_kwargs)
               ^^^^^^^^^^^^^^^^^^^^^^^^^^^^^^^^^^^^^^^^^^^^^^^^^^^^^^^^^^^^
  File "C:\Users\Lenovo\Downloads\Appstack\Appstack\freelance_project\customer_engine\decorators.py", line 28, in _wrapped_view
    return view_func(request, *args, **kwargs)
           ^^^^^^^^^^^^^^^^^^^^^^^^^^^^^^^^^^^
  File "C:\Users\Lenovo\Downloads\Appstack\Appstack\freelance_project\backoffice_engine\views.py", line 347, in customers_detail
    data = UserSnacks.objects.get(customer = user_id)
           ^^^^^^^^^^^^^^^^^^^^^^^^^^^^^^^^^^^^^^^^^^
  File "C:\Users\Lenovo\Downloads\Appstack\Appstack\env\Lib\site-packages\django\db\models\manager.py", line 87, in manager_method
    return getattr(self.get_queryset(), name)(*args, **kwargs)
           ^^^^^^^^^^^^^^^^^^^^^^^^^^^^^^^^^^^^^^^^^^^^^^^^^^^
  File "C:\Users\Lenovo\Downloads\Appstack\Appstack\env\Lib\site-packages\django\db\models\query.py", line 637, in get
    raise self.model.DoesNotExist(
customer_engine.models.UserSnacks.DoesNotExist: UserSnacks matching query does not exist.
ERROR 2023-10-05 19:39:16,547 views An error occurred: name 'settings' is not defined
Traceback (most recent call last):
  File "C:\Users\Lenovo\Downloads\Appstack\Appstack\freelance_project\customer_engine\views.py", line 338, in post
    from_email = settings.EMAIL_HOST_USER
                 ^^^^^^^^
NameError: name 'settings' is not defined
ERROR 2023-10-05 19:39:16,563 log Internal Server Error: /api/login/
ERROR 2023-10-05 19:39:26,211 views An error occurred: name 'settings' is not defined
Traceback (most recent call last):
  File "C:\Users\Lenovo\Downloads\Appstack\Appstack\freelance_project\customer_engine\views.py", line 338, in post
    from_email = settings.EMAIL_HOST_USER
                 ^^^^^^^^
NameError: name 'settings' is not defined
ERROR 2023-10-05 19:39:26,211 log Internal Server Error: /api/login/
ERROR 2023-10-05 19:41:00,605 views An error occurred: name 'settings' is not defined
Traceback (most recent call last):
  File "C:\Users\Lenovo\Downloads\Appstack\Appstack\freelance_project\customer_engine\views.py", line 338, in post
    from_email = settings.EMAIL_HOST_USER
                 ^^^^^^^^
NameError: name 'settings' is not defined
ERROR 2023-10-05 19:41:00,613 log Internal Server Error: /api/login/
ERROR 2023-10-05 22:58:31,328 views An error occurred: name 'settings' is not defined
Traceback (most recent call last):
  File "C:\Users\Lenovo\Downloads\Appstack\Appstack\freelance_project\customer_engine\views.py", line 338, in post
    from_email = settings.EMAIL_HOST_USER
                 ^^^^^^^^
NameError: name 'settings' is not defined
ERROR 2023-10-05 22:58:31,456 log Internal Server Error: /api/login/
ERROR 2023-10-05 23:01:07,309 log Internal Server Error: /api/login/
ERROR 2023-10-05 23:35:31,740 views An error occurred: cannot access local variable 'otp' where it is not associated with a value
Traceback (most recent call last):
  File "C:\Users\Lenovo\Downloads\Appstack\Appstack\freelance_project\customer_engine\views.py", line 337, in post
    message = f'Your OTP is: {otp}'
                              ^^^
UnboundLocalError: cannot access local variable 'otp' where it is not associated with a value
ERROR 2023-10-05 23:35:31,750 log Internal Server Error: /api/login/
ERROR 2023-10-05 23:40:38,608 views An error occurred: cannot access local variable 'subject' where it is not associated with a value
Traceback (most recent call last):
  File "C:\Users\Lenovo\Downloads\Appstack\Appstack\freelance_project\customer_engine\views.py", line 339, in post
    send_mail(subject, message, from_email, recipient_list)
              ^^^^^^^
UnboundLocalError: cannot access local variable 'subject' where it is not associated with a value
ERROR 2023-10-05 23:40:38,616 log Internal Server Error: /api/login/
ERROR 2023-10-05 23:46:12,508 views An error occurred: name 'settings' is not defined
Traceback (most recent call last):
  File "C:\Users\Lenovo\Downloads\Appstack\Appstack\freelance_project\customer_engine\views.py", line 336, in post
    from_email = settings.EMAIL_HOST_USER
                 ^^^^^^^^
NameError: name 'settings' is not defined
ERROR 2023-10-05 23:46:12,516 log Internal Server Error: /api/login/
ERROR 2023-10-05 23:47:51,515 views An error occurred: name 'subject' is not defined
Traceback (most recent call last):
  File "C:\Users\Lenovo\Downloads\Appstack\Appstack\freelance_project\customer_engine\views.py", line 339, in post
    send_mail(subject, message, from_email, recipient_list)
              ^^^^^^^
NameError: name 'subject' is not defined
ERROR 2023-10-05 23:47:51,527 log Internal Server Error: /api/login/
ERROR 2023-10-05 23:49:10,307 views An error occurred: send_mail() missing 1 required positional argument: 'recipient_list'
Traceback (most recent call last):
  File "C:\Users\Lenovo\Downloads\Appstack\Appstack\freelance_project\customer_engine\views.py", line 339, in post
    send_mail( message, from_email, recipient_list)
TypeError: send_mail() missing 1 required positional argument: 'recipient_list'
ERROR 2023-10-05 23:49:10,403 log Internal Server Error: /api/login/
ERROR 2023-10-05 23:51:00,814 views An error occurred: [Errno 11001] getaddrinfo failed
Traceback (most recent call last):
  File "C:\Users\Lenovo\Downloads\Appstack\Appstack\freelance_project\customer_engine\views.py", line 340, in post
    send_mail(subject, message, from_email, recipient_list)
  File "C:\Users\Lenovo\Downloads\Appstack\Appstack\env\Lib\site-packages\django\core\mail\__init__.py", line 87, in send_mail
    return mail.send()
           ^^^^^^^^^^^
  File "C:\Users\Lenovo\Downloads\Appstack\Appstack\env\Lib\site-packages\django\core\mail\message.py", line 298, in send
    return self.get_connection(fail_silently).send_messages([self])
           ^^^^^^^^^^^^^^^^^^^^^^^^^^^^^^^^^^^^^^^^^^^^^^^^^^^^^^^^
  File "C:\Users\Lenovo\Downloads\Appstack\Appstack\env\Lib\site-packages\django\core\mail\backends\smtp.py", line 127, in send_messages
    new_conn_created = self.open()
                       ^^^^^^^^^^^
  File "C:\Users\Lenovo\Downloads\Appstack\Appstack\env\Lib\site-packages\django\core\mail\backends\smtp.py", line 85, in open
    self.connection = self.connection_class(
                      ^^^^^^^^^^^^^^^^^^^^^^
  File "C:\Users\Lenovo\AppData\Local\Programs\Python\Python311\Lib\smtplib.py", line 255, in __init__
    (code, msg) = self.connect(host, port)
                  ^^^^^^^^^^^^^^^^^^^^^^^^
  File "C:\Users\Lenovo\AppData\Local\Programs\Python\Python311\Lib\smtplib.py", line 341, in connect
    self.sock = self._get_socket(host, port, self.timeout)
                ^^^^^^^^^^^^^^^^^^^^^^^^^^^^^^^^^^^^^^^^^^
  File "C:\Users\Lenovo\AppData\Local\Programs\Python\Python311\Lib\smtplib.py", line 312, in _get_socket
    return socket.create_connection((host, port), timeout,
           ^^^^^^^^^^^^^^^^^^^^^^^^^^^^^^^^^^^^^^^^^^^^^^^
  File "C:\Users\Lenovo\AppData\Local\Programs\Python\Python311\Lib\socket.py", line 827, in create_connection
    for res in getaddrinfo(host, port, 0, SOCK_STREAM):
               ^^^^^^^^^^^^^^^^^^^^^^^^^^^^^^^^^^^^^^^
  File "C:\Users\Lenovo\AppData\Local\Programs\Python\Python311\Lib\socket.py", line 962, in getaddrinfo
    for res in _socket.getaddrinfo(host, port, family, type, proto, flags):
               ^^^^^^^^^^^^^^^^^^^^^^^^^^^^^^^^^^^^^^^^^^^^^^^^^^^^^^^^^^^
socket.gaierror: [Errno 11001] getaddrinfo failed
ERROR 2023-10-05 23:51:00,825 log Internal Server Error: /api/login/
ERROR 2023-10-06 10:42:40,915 views An error occurred: [Errno 11001] getaddrinfo failed
Traceback (most recent call last):
  File "C:\Users\Lenovo\Downloads\Appstack\Appstack\freelance_project\customer_engine\views.py", line 340, in post
    send_mail(subject, message, from_email, recipient_list)
  File "C:\Users\Lenovo\Downloads\Appstack\Appstack\env\Lib\site-packages\django\core\mail\__init__.py", line 87, in send_mail
    return mail.send()
           ^^^^^^^^^^^
  File "C:\Users\Lenovo\Downloads\Appstack\Appstack\env\Lib\site-packages\django\core\mail\message.py", line 298, in send
    return self.get_connection(fail_silently).send_messages([self])
           ^^^^^^^^^^^^^^^^^^^^^^^^^^^^^^^^^^^^^^^^^^^^^^^^^^^^^^^^
  File "C:\Users\Lenovo\Downloads\Appstack\Appstack\env\Lib\site-packages\django\core\mail\backends\smtp.py", line 127, in send_messages
    new_conn_created = self.open()
                       ^^^^^^^^^^^
  File "C:\Users\Lenovo\Downloads\Appstack\Appstack\env\Lib\site-packages\django\core\mail\backends\smtp.py", line 85, in open
    self.connection = self.connection_class(
                      ^^^^^^^^^^^^^^^^^^^^^^
  File "C:\Users\Lenovo\AppData\Local\Programs\Python\Python311\Lib\smtplib.py", line 255, in __init__
    (code, msg) = self.connect(host, port)
                  ^^^^^^^^^^^^^^^^^^^^^^^^
  File "C:\Users\Lenovo\AppData\Local\Programs\Python\Python311\Lib\smtplib.py", line 341, in connect
    self.sock = self._get_socket(host, port, self.timeout)
                ^^^^^^^^^^^^^^^^^^^^^^^^^^^^^^^^^^^^^^^^^^
  File "C:\Users\Lenovo\AppData\Local\Programs\Python\Python311\Lib\smtplib.py", line 312, in _get_socket
    return socket.create_connection((host, port), timeout,
           ^^^^^^^^^^^^^^^^^^^^^^^^^^^^^^^^^^^^^^^^^^^^^^^
  File "C:\Users\Lenovo\AppData\Local\Programs\Python\Python311\Lib\socket.py", line 827, in create_connection
    for res in getaddrinfo(host, port, 0, SOCK_STREAM):
               ^^^^^^^^^^^^^^^^^^^^^^^^^^^^^^^^^^^^^^^
  File "C:\Users\Lenovo\AppData\Local\Programs\Python\Python311\Lib\socket.py", line 962, in getaddrinfo
    for res in _socket.getaddrinfo(host, port, family, type, proto, flags):
               ^^^^^^^^^^^^^^^^^^^^^^^^^^^^^^^^^^^^^^^^^^^^^^^^^^^^^^^^^^^
socket.gaierror: [Errno 11001] getaddrinfo failed
ERROR 2023-10-06 10:42:40,982 log Internal Server Error: /api/login/
ERROR 2023-10-06 10:47:29,624 log Internal Server Error: /customers/detail/30/
Traceback (most recent call last):
  File "C:\Users\Lenovo\Downloads\Appstack\Appstack\env\Lib\site-packages\django\core\handlers\exception.py", line 55, in inner
    response = get_response(request)
               ^^^^^^^^^^^^^^^^^^^^^
  File "C:\Users\Lenovo\Downloads\Appstack\Appstack\env\Lib\site-packages\django\core\handlers\base.py", line 197, in _get_response
    response = wrapped_callback(request, *callback_args, **callback_kwargs)
               ^^^^^^^^^^^^^^^^^^^^^^^^^^^^^^^^^^^^^^^^^^^^^^^^^^^^^^^^^^^^
  File "C:\Users\Lenovo\Downloads\Appstack\Appstack\freelance_project\customer_engine\decorators.py", line 28, in _wrapped_view
    return view_func(request, *args, **kwargs)
           ^^^^^^^^^^^^^^^^^^^^^^^^^^^^^^^^^^^
  File "C:\Users\Lenovo\Downloads\Appstack\Appstack\freelance_project\backoffice_engine\views.py", line 347, in customers_detail
    data = UserSnacks.objects.get(customer = user_id)
           ^^^^^^^^^^^^^^^^^^^^^^^^^^^^^^^^^^^^^^^^^^
  File "C:\Users\Lenovo\Downloads\Appstack\Appstack\env\Lib\site-packages\django\db\models\manager.py", line 87, in manager_method
    return getattr(self.get_queryset(), name)(*args, **kwargs)
           ^^^^^^^^^^^^^^^^^^^^^^^^^^^^^^^^^^^^^^^^^^^^^^^^^^^
  File "C:\Users\Lenovo\Downloads\Appstack\Appstack\env\Lib\site-packages\django\db\models\query.py", line 637, in get
    raise self.model.DoesNotExist(
customer_engine.models.UserSnacks.DoesNotExist: UserSnacks matching query does not exist.
ERROR 2023-10-06 10:47:36,803 log Internal Server Error: /customers/detail/31/
Traceback (most recent call last):
  File "C:\Users\Lenovo\Downloads\Appstack\Appstack\env\Lib\site-packages\django\core\handlers\exception.py", line 55, in inner
    response = get_response(request)
               ^^^^^^^^^^^^^^^^^^^^^
  File "C:\Users\Lenovo\Downloads\Appstack\Appstack\env\Lib\site-packages\django\core\handlers\base.py", line 197, in _get_response
    response = wrapped_callback(request, *callback_args, **callback_kwargs)
               ^^^^^^^^^^^^^^^^^^^^^^^^^^^^^^^^^^^^^^^^^^^^^^^^^^^^^^^^^^^^
  File "C:\Users\Lenovo\Downloads\Appstack\Appstack\freelance_project\customer_engine\decorators.py", line 28, in _wrapped_view
    return view_func(request, *args, **kwargs)
           ^^^^^^^^^^^^^^^^^^^^^^^^^^^^^^^^^^^
  File "C:\Users\Lenovo\Downloads\Appstack\Appstack\freelance_project\backoffice_engine\views.py", line 347, in customers_detail
    data = UserSnacks.objects.get(customer = user_id)
           ^^^^^^^^^^^^^^^^^^^^^^^^^^^^^^^^^^^^^^^^^^
  File "C:\Users\Lenovo\Downloads\Appstack\Appstack\env\Lib\site-packages\django\db\models\manager.py", line 87, in manager_method
    return getattr(self.get_queryset(), name)(*args, **kwargs)
           ^^^^^^^^^^^^^^^^^^^^^^^^^^^^^^^^^^^^^^^^^^^^^^^^^^^
  File "C:\Users\Lenovo\Downloads\Appstack\Appstack\env\Lib\site-packages\django\db\models\query.py", line 637, in get
    raise self.model.DoesNotExist(
customer_engine.models.UserSnacks.DoesNotExist: UserSnacks matching query does not exist.
ERROR 2023-10-06 10:47:57,199 log Internal Server Error: /customers/detail/30/
Traceback (most recent call last):
  File "C:\Users\Lenovo\Downloads\Appstack\Appstack\env\Lib\site-packages\django\core\handlers\exception.py", line 55, in inner
    response = get_response(request)
               ^^^^^^^^^^^^^^^^^^^^^
  File "C:\Users\Lenovo\Downloads\Appstack\Appstack\env\Lib\site-packages\django\core\handlers\base.py", line 197, in _get_response
    response = wrapped_callback(request, *callback_args, **callback_kwargs)
               ^^^^^^^^^^^^^^^^^^^^^^^^^^^^^^^^^^^^^^^^^^^^^^^^^^^^^^^^^^^^
  File "C:\Users\Lenovo\Downloads\Appstack\Appstack\freelance_project\customer_engine\decorators.py", line 28, in _wrapped_view
    return view_func(request, *args, **kwargs)
           ^^^^^^^^^^^^^^^^^^^^^^^^^^^^^^^^^^^
  File "C:\Users\Lenovo\Downloads\Appstack\Appstack\freelance_project\backoffice_engine\views.py", line 347, in customers_detail
    data = UserSnacks.objects.get(customer = user_id)
           ^^^^^^^^^^^^^^^^^^^^^^^^^^^^^^^^^^^^^^^^^^
  File "C:\Users\Lenovo\Downloads\Appstack\Appstack\env\Lib\site-packages\django\db\models\manager.py", line 87, in manager_method
    return getattr(self.get_queryset(), name)(*args, **kwargs)
           ^^^^^^^^^^^^^^^^^^^^^^^^^^^^^^^^^^^^^^^^^^^^^^^^^^^
  File "C:\Users\Lenovo\Downloads\Appstack\Appstack\env\Lib\site-packages\django\db\models\query.py", line 637, in get
    raise self.model.DoesNotExist(
customer_engine.models.UserSnacks.DoesNotExist: UserSnacks matching query does not exist.
ERROR 2023-10-06 10:51:38,821 views An error occurred: [Errno 11001] getaddrinfo failed
Traceback (most recent call last):
  File "C:\Users\Lenovo\Downloads\Appstack\Appstack\freelance_project\customer_engine\views.py", line 340, in post
    send_mail(subject, message, from_email, recipient_list)
  File "C:\Users\Lenovo\Downloads\Appstack\Appstack\env\Lib\site-packages\django\core\mail\__init__.py", line 87, in send_mail
    return mail.send()
           ^^^^^^^^^^^
  File "C:\Users\Lenovo\Downloads\Appstack\Appstack\env\Lib\site-packages\django\core\mail\message.py", line 298, in send
    return self.get_connection(fail_silently).send_messages([self])
           ^^^^^^^^^^^^^^^^^^^^^^^^^^^^^^^^^^^^^^^^^^^^^^^^^^^^^^^^
  File "C:\Users\Lenovo\Downloads\Appstack\Appstack\env\Lib\site-packages\django\core\mail\backends\smtp.py", line 127, in send_messages
    new_conn_created = self.open()
                       ^^^^^^^^^^^
  File "C:\Users\Lenovo\Downloads\Appstack\Appstack\env\Lib\site-packages\django\core\mail\backends\smtp.py", line 85, in open
    self.connection = self.connection_class(
                      ^^^^^^^^^^^^^^^^^^^^^^
  File "C:\Users\Lenovo\AppData\Local\Programs\Python\Python311\Lib\smtplib.py", line 255, in __init__
    (code, msg) = self.connect(host, port)
                  ^^^^^^^^^^^^^^^^^^^^^^^^
  File "C:\Users\Lenovo\AppData\Local\Programs\Python\Python311\Lib\smtplib.py", line 341, in connect
    self.sock = self._get_socket(host, port, self.timeout)
                ^^^^^^^^^^^^^^^^^^^^^^^^^^^^^^^^^^^^^^^^^^
  File "C:\Users\Lenovo\AppData\Local\Programs\Python\Python311\Lib\smtplib.py", line 312, in _get_socket
    return socket.create_connection((host, port), timeout,
           ^^^^^^^^^^^^^^^^^^^^^^^^^^^^^^^^^^^^^^^^^^^^^^^
  File "C:\Users\Lenovo\AppData\Local\Programs\Python\Python311\Lib\socket.py", line 827, in create_connection
    for res in getaddrinfo(host, port, 0, SOCK_STREAM):
               ^^^^^^^^^^^^^^^^^^^^^^^^^^^^^^^^^^^^^^^
  File "C:\Users\Lenovo\AppData\Local\Programs\Python\Python311\Lib\socket.py", line 962, in getaddrinfo
    for res in _socket.getaddrinfo(host, port, family, type, proto, flags):
               ^^^^^^^^^^^^^^^^^^^^^^^^^^^^^^^^^^^^^^^^^^^^^^^^^^^^^^^^^^^
socket.gaierror: [Errno 11001] getaddrinfo failed
ERROR 2023-10-06 10:51:38,852 log Internal Server Error: /api/login/
ERROR 2023-10-06 11:00:47,532 views An error occurred: [Errno 11001] getaddrinfo failed
Traceback (most recent call last):
  File "C:\Users\Lenovo\Downloads\Appstack\Appstack\freelance_project\customer_engine\views.py", line 340, in post
    send_mail(subject, message, from_email, recipient_list)
  File "C:\Users\Lenovo\Downloads\Appstack\Appstack\env\Lib\site-packages\django\core\mail\__init__.py", line 87, in send_mail
    return mail.send()
           ^^^^^^^^^^^
  File "C:\Users\Lenovo\Downloads\Appstack\Appstack\env\Lib\site-packages\django\core\mail\message.py", line 298, in send
    return self.get_connection(fail_silently).send_messages([self])
           ^^^^^^^^^^^^^^^^^^^^^^^^^^^^^^^^^^^^^^^^^^^^^^^^^^^^^^^^
  File "C:\Users\Lenovo\Downloads\Appstack\Appstack\env\Lib\site-packages\django\core\mail\backends\smtp.py", line 127, in send_messages
    new_conn_created = self.open()
                       ^^^^^^^^^^^
  File "C:\Users\Lenovo\Downloads\Appstack\Appstack\env\Lib\site-packages\django\core\mail\backends\smtp.py", line 85, in open
    self.connection = self.connection_class(
                      ^^^^^^^^^^^^^^^^^^^^^^
  File "C:\Users\Lenovo\AppData\Local\Programs\Python\Python311\Lib\smtplib.py", line 255, in __init__
    (code, msg) = self.connect(host, port)
                  ^^^^^^^^^^^^^^^^^^^^^^^^
  File "C:\Users\Lenovo\AppData\Local\Programs\Python\Python311\Lib\smtplib.py", line 341, in connect
    self.sock = self._get_socket(host, port, self.timeout)
                ^^^^^^^^^^^^^^^^^^^^^^^^^^^^^^^^^^^^^^^^^^
  File "C:\Users\Lenovo\AppData\Local\Programs\Python\Python311\Lib\smtplib.py", line 312, in _get_socket
    return socket.create_connection((host, port), timeout,
           ^^^^^^^^^^^^^^^^^^^^^^^^^^^^^^^^^^^^^^^^^^^^^^^
  File "C:\Users\Lenovo\AppData\Local\Programs\Python\Python311\Lib\socket.py", line 827, in create_connection
    for res in getaddrinfo(host, port, 0, SOCK_STREAM):
               ^^^^^^^^^^^^^^^^^^^^^^^^^^^^^^^^^^^^^^^
  File "C:\Users\Lenovo\AppData\Local\Programs\Python\Python311\Lib\socket.py", line 962, in getaddrinfo
    for res in _socket.getaddrinfo(host, port, family, type, proto, flags):
               ^^^^^^^^^^^^^^^^^^^^^^^^^^^^^^^^^^^^^^^^^^^^^^^^^^^^^^^^^^^
socket.gaierror: [Errno 11001] getaddrinfo failed
ERROR 2023-10-06 11:00:47,540 log Internal Server Error: /api/login/
ERROR 2023-10-06 11:01:13,108 views An error occurred: [Errno 11001] getaddrinfo failed
Traceback (most recent call last):
  File "C:\Users\Lenovo\Downloads\Appstack\Appstack\freelance_project\customer_engine\views.py", line 340, in post
    send_mail(subject, message, from_email, recipient_list)
  File "C:\Users\Lenovo\Downloads\Appstack\Appstack\env\Lib\site-packages\django\core\mail\__init__.py", line 87, in send_mail
    return mail.send()
           ^^^^^^^^^^^
  File "C:\Users\Lenovo\Downloads\Appstack\Appstack\env\Lib\site-packages\django\core\mail\message.py", line 298, in send
    return self.get_connection(fail_silently).send_messages([self])
           ^^^^^^^^^^^^^^^^^^^^^^^^^^^^^^^^^^^^^^^^^^^^^^^^^^^^^^^^
  File "C:\Users\Lenovo\Downloads\Appstack\Appstack\env\Lib\site-packages\django\core\mail\backends\smtp.py", line 127, in send_messages
    new_conn_created = self.open()
                       ^^^^^^^^^^^
  File "C:\Users\Lenovo\Downloads\Appstack\Appstack\env\Lib\site-packages\django\core\mail\backends\smtp.py", line 85, in open
    self.connection = self.connection_class(
                      ^^^^^^^^^^^^^^^^^^^^^^
  File "C:\Users\Lenovo\AppData\Local\Programs\Python\Python311\Lib\smtplib.py", line 255, in __init__
    (code, msg) = self.connect(host, port)
                  ^^^^^^^^^^^^^^^^^^^^^^^^
  File "C:\Users\Lenovo\AppData\Local\Programs\Python\Python311\Lib\smtplib.py", line 341, in connect
    self.sock = self._get_socket(host, port, self.timeout)
                ^^^^^^^^^^^^^^^^^^^^^^^^^^^^^^^^^^^^^^^^^^
  File "C:\Users\Lenovo\AppData\Local\Programs\Python\Python311\Lib\smtplib.py", line 312, in _get_socket
    return socket.create_connection((host, port), timeout,
           ^^^^^^^^^^^^^^^^^^^^^^^^^^^^^^^^^^^^^^^^^^^^^^^
  File "C:\Users\Lenovo\AppData\Local\Programs\Python\Python311\Lib\socket.py", line 827, in create_connection
    for res in getaddrinfo(host, port, 0, SOCK_STREAM):
               ^^^^^^^^^^^^^^^^^^^^^^^^^^^^^^^^^^^^^^^
  File "C:\Users\Lenovo\AppData\Local\Programs\Python\Python311\Lib\socket.py", line 962, in getaddrinfo
    for res in _socket.getaddrinfo(host, port, family, type, proto, flags):
               ^^^^^^^^^^^^^^^^^^^^^^^^^^^^^^^^^^^^^^^^^^^^^^^^^^^^^^^^^^^
socket.gaierror: [Errno 11001] getaddrinfo failed
ERROR 2023-10-06 11:01:13,114 log Internal Server Error: /api/login/
ERROR 2023-10-06 11:01:15,243 views An error occurred: [Errno 11001] getaddrinfo failed
Traceback (most recent call last):
  File "C:\Users\Lenovo\Downloads\Appstack\Appstack\freelance_project\customer_engine\views.py", line 340, in post
    send_mail(subject, message, from_email, recipient_list)
  File "C:\Users\Lenovo\Downloads\Appstack\Appstack\env\Lib\site-packages\django\core\mail\__init__.py", line 87, in send_mail
    return mail.send()
           ^^^^^^^^^^^
  File "C:\Users\Lenovo\Downloads\Appstack\Appstack\env\Lib\site-packages\django\core\mail\message.py", line 298, in send
    return self.get_connection(fail_silently).send_messages([self])
           ^^^^^^^^^^^^^^^^^^^^^^^^^^^^^^^^^^^^^^^^^^^^^^^^^^^^^^^^
  File "C:\Users\Lenovo\Downloads\Appstack\Appstack\env\Lib\site-packages\django\core\mail\backends\smtp.py", line 127, in send_messages
    new_conn_created = self.open()
                       ^^^^^^^^^^^
  File "C:\Users\Lenovo\Downloads\Appstack\Appstack\env\Lib\site-packages\django\core\mail\backends\smtp.py", line 85, in open
    self.connection = self.connection_class(
                      ^^^^^^^^^^^^^^^^^^^^^^
  File "C:\Users\Lenovo\AppData\Local\Programs\Python\Python311\Lib\smtplib.py", line 255, in __init__
    (code, msg) = self.connect(host, port)
                  ^^^^^^^^^^^^^^^^^^^^^^^^
  File "C:\Users\Lenovo\AppData\Local\Programs\Python\Python311\Lib\smtplib.py", line 341, in connect
    self.sock = self._get_socket(host, port, self.timeout)
                ^^^^^^^^^^^^^^^^^^^^^^^^^^^^^^^^^^^^^^^^^^
  File "C:\Users\Lenovo\AppData\Local\Programs\Python\Python311\Lib\smtplib.py", line 312, in _get_socket
    return socket.create_connection((host, port), timeout,
           ^^^^^^^^^^^^^^^^^^^^^^^^^^^^^^^^^^^^^^^^^^^^^^^
  File "C:\Users\Lenovo\AppData\Local\Programs\Python\Python311\Lib\socket.py", line 827, in create_connection
    for res in getaddrinfo(host, port, 0, SOCK_STREAM):
               ^^^^^^^^^^^^^^^^^^^^^^^^^^^^^^^^^^^^^^^
  File "C:\Users\Lenovo\AppData\Local\Programs\Python\Python311\Lib\socket.py", line 962, in getaddrinfo
    for res in _socket.getaddrinfo(host, port, family, type, proto, flags):
               ^^^^^^^^^^^^^^^^^^^^^^^^^^^^^^^^^^^^^^^^^^^^^^^^^^^^^^^^^^^
socket.gaierror: [Errno 11001] getaddrinfo failed
ERROR 2023-10-06 11:01:15,246 log Internal Server Error: /api/login/
ERROR 2023-10-06 11:32:49,288 views An error occurred: [Errno 11001] getaddrinfo failed
Traceback (most recent call last):
  File "C:\Users\Lenovo\Downloads\Appstack\Appstack\freelance_project\customer_engine\views.py", line 340, in post
    send_mail(subject, message, from_email, recipient_list)
  File "C:\Users\Lenovo\Downloads\Appstack\Appstack\env\Lib\site-packages\django\core\mail\__init__.py", line 87, in send_mail
    return mail.send()
           ^^^^^^^^^^^
  File "C:\Users\Lenovo\Downloads\Appstack\Appstack\env\Lib\site-packages\django\core\mail\message.py", line 298, in send
    return self.get_connection(fail_silently).send_messages([self])
           ^^^^^^^^^^^^^^^^^^^^^^^^^^^^^^^^^^^^^^^^^^^^^^^^^^^^^^^^
  File "C:\Users\Lenovo\Downloads\Appstack\Appstack\env\Lib\site-packages\django\core\mail\backends\smtp.py", line 127, in send_messages
    new_conn_created = self.open()
                       ^^^^^^^^^^^
  File "C:\Users\Lenovo\Downloads\Appstack\Appstack\env\Lib\site-packages\django\core\mail\backends\smtp.py", line 85, in open
    self.connection = self.connection_class(
                      ^^^^^^^^^^^^^^^^^^^^^^
  File "C:\Users\Lenovo\AppData\Local\Programs\Python\Python311\Lib\smtplib.py", line 255, in __init__
    (code, msg) = self.connect(host, port)
                  ^^^^^^^^^^^^^^^^^^^^^^^^
  File "C:\Users\Lenovo\AppData\Local\Programs\Python\Python311\Lib\smtplib.py", line 341, in connect
    self.sock = self._get_socket(host, port, self.timeout)
                ^^^^^^^^^^^^^^^^^^^^^^^^^^^^^^^^^^^^^^^^^^
  File "C:\Users\Lenovo\AppData\Local\Programs\Python\Python311\Lib\smtplib.py", line 312, in _get_socket
    return socket.create_connection((host, port), timeout,
           ^^^^^^^^^^^^^^^^^^^^^^^^^^^^^^^^^^^^^^^^^^^^^^^
  File "C:\Users\Lenovo\AppData\Local\Programs\Python\Python311\Lib\socket.py", line 827, in create_connection
    for res in getaddrinfo(host, port, 0, SOCK_STREAM):
               ^^^^^^^^^^^^^^^^^^^^^^^^^^^^^^^^^^^^^^^
  File "C:\Users\Lenovo\AppData\Local\Programs\Python\Python311\Lib\socket.py", line 962, in getaddrinfo
    for res in _socket.getaddrinfo(host, port, family, type, proto, flags):
               ^^^^^^^^^^^^^^^^^^^^^^^^^^^^^^^^^^^^^^^^^^^^^^^^^^^^^^^^^^^
socket.gaierror: [Errno 11001] getaddrinfo failed
ERROR 2023-10-06 11:32:49,299 log Internal Server Error: /api/login/
ERROR 2023-10-06 11:33:17,546 log Internal Server Error: /customers/detail/30/
Traceback (most recent call last):
  File "C:\Users\Lenovo\Downloads\Appstack\Appstack\env\Lib\site-packages\django\core\handlers\exception.py", line 55, in inner
    response = get_response(request)
               ^^^^^^^^^^^^^^^^^^^^^
  File "C:\Users\Lenovo\Downloads\Appstack\Appstack\env\Lib\site-packages\django\core\handlers\base.py", line 197, in _get_response
    response = wrapped_callback(request, *callback_args, **callback_kwargs)
               ^^^^^^^^^^^^^^^^^^^^^^^^^^^^^^^^^^^^^^^^^^^^^^^^^^^^^^^^^^^^
  File "C:\Users\Lenovo\Downloads\Appstack\Appstack\freelance_project\customer_engine\decorators.py", line 28, in _wrapped_view
    return view_func(request, *args, **kwargs)
           ^^^^^^^^^^^^^^^^^^^^^^^^^^^^^^^^^^^
  File "C:\Users\Lenovo\Downloads\Appstack\Appstack\freelance_project\backoffice_engine\views.py", line 347, in customers_detail
    data = UserSnacks.objects.get(customer = user_id)
           ^^^^^^^^^^^^^^^^^^^^^^^^^^^^^^^^^^^^^^^^^^
  File "C:\Users\Lenovo\Downloads\Appstack\Appstack\env\Lib\site-packages\django\db\models\manager.py", line 87, in manager_method
    return getattr(self.get_queryset(), name)(*args, **kwargs)
           ^^^^^^^^^^^^^^^^^^^^^^^^^^^^^^^^^^^^^^^^^^^^^^^^^^^
  File "C:\Users\Lenovo\Downloads\Appstack\Appstack\env\Lib\site-packages\django\db\models\query.py", line 637, in get
    raise self.model.DoesNotExist(
customer_engine.models.UserSnacks.DoesNotExist: UserSnacks matching query does not exist.
ERROR 2023-10-06 11:41:27,803 log Internal Server Error: /customers/detail/31/
Traceback (most recent call last):
  File "C:\Users\Lenovo\Downloads\Appstack\Appstack\env\Lib\site-packages\django\core\handlers\exception.py", line 55, in inner
    response = get_response(request)
               ^^^^^^^^^^^^^^^^^^^^^
  File "C:\Users\Lenovo\Downloads\Appstack\Appstack\env\Lib\site-packages\django\core\handlers\base.py", line 197, in _get_response
    response = wrapped_callback(request, *callback_args, **callback_kwargs)
               ^^^^^^^^^^^^^^^^^^^^^^^^^^^^^^^^^^^^^^^^^^^^^^^^^^^^^^^^^^^^
  File "C:\Users\Lenovo\Downloads\Appstack\Appstack\freelance_project\customer_engine\decorators.py", line 28, in _wrapped_view
    return view_func(request, *args, **kwargs)
           ^^^^^^^^^^^^^^^^^^^^^^^^^^^^^^^^^^^
  File "C:\Users\Lenovo\Downloads\Appstack\Appstack\freelance_project\backoffice_engine\views.py", line 347, in customers_detail
    data = UserSnacks.objects.get(customer = user_id)
           ^^^^^^^^^^^^^^^^^^^^^^^^^^^^^^^^^^^^^^^^^^
  File "C:\Users\Lenovo\Downloads\Appstack\Appstack\env\Lib\site-packages\django\db\models\manager.py", line 87, in manager_method
    return getattr(self.get_queryset(), name)(*args, **kwargs)
           ^^^^^^^^^^^^^^^^^^^^^^^^^^^^^^^^^^^^^^^^^^^^^^^^^^^
  File "C:\Users\Lenovo\Downloads\Appstack\Appstack\env\Lib\site-packages\django\db\models\query.py", line 637, in get
    raise self.model.DoesNotExist(
customer_engine.models.UserSnacks.DoesNotExist: UserSnacks matching query does not exist.
ERROR 2023-10-06 11:42:15,958 log Internal Server Error: /customers/detail/31/
Traceback (most recent call last):
  File "C:\Users\Lenovo\Downloads\Appstack\Appstack\env\Lib\site-packages\django\core\handlers\exception.py", line 55, in inner
    response = get_response(request)
               ^^^^^^^^^^^^^^^^^^^^^
  File "C:\Users\Lenovo\Downloads\Appstack\Appstack\env\Lib\site-packages\django\core\handlers\base.py", line 197, in _get_response
    response = wrapped_callback(request, *callback_args, **callback_kwargs)
               ^^^^^^^^^^^^^^^^^^^^^^^^^^^^^^^^^^^^^^^^^^^^^^^^^^^^^^^^^^^^
  File "C:\Users\Lenovo\Downloads\Appstack\Appstack\freelance_project\customer_engine\decorators.py", line 28, in _wrapped_view
    return view_func(request, *args, **kwargs)
           ^^^^^^^^^^^^^^^^^^^^^^^^^^^^^^^^^^^
  File "C:\Users\Lenovo\Downloads\Appstack\Appstack\freelance_project\backoffice_engine\views.py", line 347, in customers_detail
    data = UserSnacks.objects.get(customer = user_id)
           ^^^^^^^^^^^^^^^^^^^^^^^^^^^^^^^^^^^^^^^^^^
  File "C:\Users\Lenovo\Downloads\Appstack\Appstack\env\Lib\site-packages\django\db\models\manager.py", line 87, in manager_method
    return getattr(self.get_queryset(), name)(*args, **kwargs)
           ^^^^^^^^^^^^^^^^^^^^^^^^^^^^^^^^^^^^^^^^^^^^^^^^^^^
  File "C:\Users\Lenovo\Downloads\Appstack\Appstack\env\Lib\site-packages\django\db\models\query.py", line 637, in get
    raise self.model.DoesNotExist(
customer_engine.models.UserSnacks.DoesNotExist: UserSnacks matching query does not exist.
ERROR 2023-10-06 11:43:58,501 log Internal Server Error: /customers/detail/31/
Traceback (most recent call last):
  File "C:\Users\Lenovo\Downloads\Appstack\Appstack\env\Lib\site-packages\django\core\handlers\exception.py", line 55, in inner
    response = get_response(request)
               ^^^^^^^^^^^^^^^^^^^^^
  File "C:\Users\Lenovo\Downloads\Appstack\Appstack\env\Lib\site-packages\django\core\handlers\base.py", line 197, in _get_response
    response = wrapped_callback(request, *callback_args, **callback_kwargs)
               ^^^^^^^^^^^^^^^^^^^^^^^^^^^^^^^^^^^^^^^^^^^^^^^^^^^^^^^^^^^^
  File "C:\Users\Lenovo\Downloads\Appstack\Appstack\freelance_project\customer_engine\decorators.py", line 28, in _wrapped_view
    return view_func(request, *args, **kwargs)
           ^^^^^^^^^^^^^^^^^^^^^^^^^^^^^^^^^^^
  File "C:\Users\Lenovo\Downloads\Appstack\Appstack\freelance_project\backoffice_engine\views.py", line 347, in customers_detail
    data = UserSnacks.objects.get(customer = user_id)
           ^^^^^^^^^^^^^^^^^^^^^^^^^^^^^^^^^^^^^^^^^^
  File "C:\Users\Lenovo\Downloads\Appstack\Appstack\env\Lib\site-packages\django\db\models\manager.py", line 87, in manager_method
    return getattr(self.get_queryset(), name)(*args, **kwargs)
           ^^^^^^^^^^^^^^^^^^^^^^^^^^^^^^^^^^^^^^^^^^^^^^^^^^^
  File "C:\Users\Lenovo\Downloads\Appstack\Appstack\env\Lib\site-packages\django\db\models\query.py", line 637, in get
    raise self.model.DoesNotExist(
customer_engine.models.UserSnacks.DoesNotExist: UserSnacks matching query does not exist.
ERROR 2023-10-06 11:44:07,608 log Internal Server Error: /customers/detail/32/
Traceback (most recent call last):
  File "C:\Users\Lenovo\Downloads\Appstack\Appstack\env\Lib\site-packages\django\core\handlers\exception.py", line 55, in inner
    response = get_response(request)
               ^^^^^^^^^^^^^^^^^^^^^
  File "C:\Users\Lenovo\Downloads\Appstack\Appstack\env\Lib\site-packages\django\core\handlers\base.py", line 197, in _get_response
    response = wrapped_callback(request, *callback_args, **callback_kwargs)
               ^^^^^^^^^^^^^^^^^^^^^^^^^^^^^^^^^^^^^^^^^^^^^^^^^^^^^^^^^^^^
  File "C:\Users\Lenovo\Downloads\Appstack\Appstack\freelance_project\customer_engine\decorators.py", line 28, in _wrapped_view
    return view_func(request, *args, **kwargs)
           ^^^^^^^^^^^^^^^^^^^^^^^^^^^^^^^^^^^
  File "C:\Users\Lenovo\Downloads\Appstack\Appstack\freelance_project\backoffice_engine\views.py", line 347, in customers_detail
    data = UserSnacks.objects.get(customer = user_id)
           ^^^^^^^^^^^^^^^^^^^^^^^^^^^^^^^^^^^^^^^^^^
  File "C:\Users\Lenovo\Downloads\Appstack\Appstack\env\Lib\site-packages\django\db\models\manager.py", line 87, in manager_method
    return getattr(self.get_queryset(), name)(*args, **kwargs)
           ^^^^^^^^^^^^^^^^^^^^^^^^^^^^^^^^^^^^^^^^^^^^^^^^^^^
  File "C:\Users\Lenovo\Downloads\Appstack\Appstack\env\Lib\site-packages\django\db\models\query.py", line 640, in get
    raise self.model.MultipleObjectsReturned(
customer_engine.models.UserSnacks.MultipleObjectsReturned: get() returned more than one UserSnacks -- it returned 3!
ERROR 2023-10-06 11:45:07,372 log Internal Server Error: /customers/detail/34/
Traceback (most recent call last):
  File "C:\Users\Lenovo\Downloads\Appstack\Appstack\env\Lib\site-packages\django\core\handlers\exception.py", line 55, in inner
    response = get_response(request)
               ^^^^^^^^^^^^^^^^^^^^^
  File "C:\Users\Lenovo\Downloads\Appstack\Appstack\env\Lib\site-packages\django\core\handlers\base.py", line 197, in _get_response
    response = wrapped_callback(request, *callback_args, **callback_kwargs)
               ^^^^^^^^^^^^^^^^^^^^^^^^^^^^^^^^^^^^^^^^^^^^^^^^^^^^^^^^^^^^
  File "C:\Users\Lenovo\Downloads\Appstack\Appstack\freelance_project\customer_engine\decorators.py", line 28, in _wrapped_view
    return view_func(request, *args, **kwargs)
           ^^^^^^^^^^^^^^^^^^^^^^^^^^^^^^^^^^^
  File "C:\Users\Lenovo\Downloads\Appstack\Appstack\freelance_project\backoffice_engine\views.py", line 347, in customers_detail
    data = UserSnacks.objects.get(customer = user_id)
           ^^^^^^^^^^^^^^^^^^^^^^^^^^^^^^^^^^^^^^^^^^
  File "C:\Users\Lenovo\Downloads\Appstack\Appstack\env\Lib\site-packages\django\db\models\manager.py", line 87, in manager_method
    return getattr(self.get_queryset(), name)(*args, **kwargs)
           ^^^^^^^^^^^^^^^^^^^^^^^^^^^^^^^^^^^^^^^^^^^^^^^^^^^
  File "C:\Users\Lenovo\Downloads\Appstack\Appstack\env\Lib\site-packages\django\db\models\query.py", line 637, in get
    raise self.model.DoesNotExist(
customer_engine.models.UserSnacks.DoesNotExist: UserSnacks matching query does not exist.
ERROR 2023-10-06 11:45:12,620 log Internal Server Error: /customers/detail/32/
Traceback (most recent call last):
  File "C:\Users\Lenovo\Downloads\Appstack\Appstack\env\Lib\site-packages\django\core\handlers\exception.py", line 55, in inner
    response = get_response(request)
               ^^^^^^^^^^^^^^^^^^^^^
  File "C:\Users\Lenovo\Downloads\Appstack\Appstack\env\Lib\site-packages\django\core\handlers\base.py", line 197, in _get_response
    response = wrapped_callback(request, *callback_args, **callback_kwargs)
               ^^^^^^^^^^^^^^^^^^^^^^^^^^^^^^^^^^^^^^^^^^^^^^^^^^^^^^^^^^^^
  File "C:\Users\Lenovo\Downloads\Appstack\Appstack\freelance_project\customer_engine\decorators.py", line 28, in _wrapped_view
    return view_func(request, *args, **kwargs)
           ^^^^^^^^^^^^^^^^^^^^^^^^^^^^^^^^^^^
  File "C:\Users\Lenovo\Downloads\Appstack\Appstack\freelance_project\backoffice_engine\views.py", line 347, in customers_detail
    data = UserSnacks.objects.get(customer = user_id)
           ^^^^^^^^^^^^^^^^^^^^^^^^^^^^^^^^^^^^^^^^^^
  File "C:\Users\Lenovo\Downloads\Appstack\Appstack\env\Lib\site-packages\django\db\models\manager.py", line 87, in manager_method
    return getattr(self.get_queryset(), name)(*args, **kwargs)
           ^^^^^^^^^^^^^^^^^^^^^^^^^^^^^^^^^^^^^^^^^^^^^^^^^^^
  File "C:\Users\Lenovo\Downloads\Appstack\Appstack\env\Lib\site-packages\django\db\models\query.py", line 640, in get
    raise self.model.MultipleObjectsReturned(
customer_engine.models.UserSnacks.MultipleObjectsReturned: get() returned more than one UserSnacks -- it returned 3!
ERROR 2023-10-06 11:45:18,177 log Internal Server Error: /customers/detail/32/
Traceback (most recent call last):
  File "C:\Users\Lenovo\Downloads\Appstack\Appstack\env\Lib\site-packages\django\core\handlers\exception.py", line 55, in inner
    response = get_response(request)
               ^^^^^^^^^^^^^^^^^^^^^
  File "C:\Users\Lenovo\Downloads\Appstack\Appstack\env\Lib\site-packages\django\core\handlers\base.py", line 197, in _get_response
    response = wrapped_callback(request, *callback_args, **callback_kwargs)
               ^^^^^^^^^^^^^^^^^^^^^^^^^^^^^^^^^^^^^^^^^^^^^^^^^^^^^^^^^^^^
  File "C:\Users\Lenovo\Downloads\Appstack\Appstack\freelance_project\customer_engine\decorators.py", line 28, in _wrapped_view
    return view_func(request, *args, **kwargs)
           ^^^^^^^^^^^^^^^^^^^^^^^^^^^^^^^^^^^
  File "C:\Users\Lenovo\Downloads\Appstack\Appstack\freelance_project\backoffice_engine\views.py", line 347, in customers_detail
    data = UserSnacks.objects.get(customer = user_id)
           ^^^^^^^^^^^^^^^^^^^^^^^^^^^^^^^^^^^^^^^^^^
  File "C:\Users\Lenovo\Downloads\Appstack\Appstack\env\Lib\site-packages\django\db\models\manager.py", line 87, in manager_method
    return getattr(self.get_queryset(), name)(*args, **kwargs)
           ^^^^^^^^^^^^^^^^^^^^^^^^^^^^^^^^^^^^^^^^^^^^^^^^^^^
  File "C:\Users\Lenovo\Downloads\Appstack\Appstack\env\Lib\site-packages\django\db\models\query.py", line 640, in get
    raise self.model.MultipleObjectsReturned(
customer_engine.models.UserSnacks.MultipleObjectsReturned: get() returned more than one UserSnacks -- it returned 3!
ERROR 2023-10-06 11:45:23,682 log Internal Server Error: /customers/detail/31/
Traceback (most recent call last):
  File "C:\Users\Lenovo\Downloads\Appstack\Appstack\env\Lib\site-packages\django\core\handlers\exception.py", line 55, in inner
    response = get_response(request)
               ^^^^^^^^^^^^^^^^^^^^^
  File "C:\Users\Lenovo\Downloads\Appstack\Appstack\env\Lib\site-packages\django\core\handlers\base.py", line 197, in _get_response
    response = wrapped_callback(request, *callback_args, **callback_kwargs)
               ^^^^^^^^^^^^^^^^^^^^^^^^^^^^^^^^^^^^^^^^^^^^^^^^^^^^^^^^^^^^
  File "C:\Users\Lenovo\Downloads\Appstack\Appstack\freelance_project\customer_engine\decorators.py", line 28, in _wrapped_view
    return view_func(request, *args, **kwargs)
           ^^^^^^^^^^^^^^^^^^^^^^^^^^^^^^^^^^^
  File "C:\Users\Lenovo\Downloads\Appstack\Appstack\freelance_project\backoffice_engine\views.py", line 347, in customers_detail
    data = UserSnacks.objects.get(customer = user_id)
           ^^^^^^^^^^^^^^^^^^^^^^^^^^^^^^^^^^^^^^^^^^
  File "C:\Users\Lenovo\Downloads\Appstack\Appstack\env\Lib\site-packages\django\db\models\manager.py", line 87, in manager_method
    return getattr(self.get_queryset(), name)(*args, **kwargs)
           ^^^^^^^^^^^^^^^^^^^^^^^^^^^^^^^^^^^^^^^^^^^^^^^^^^^
  File "C:\Users\Lenovo\Downloads\Appstack\Appstack\env\Lib\site-packages\django\db\models\query.py", line 637, in get
    raise self.model.DoesNotExist(
customer_engine.models.UserSnacks.DoesNotExist: UserSnacks matching query does not exist.
ERROR 2023-10-06 11:53:58,566 log Internal Server Error: /dashboard/
Traceback (most recent call last):
  File "C:\Users\Lenovo\Downloads\Appstack\Appstack\env\Lib\site-packages\django\core\handlers\exception.py", line 55, in inner
    response = get_response(request)
               ^^^^^^^^^^^^^^^^^^^^^
  File "C:\Users\Lenovo\Downloads\Appstack\Appstack\env\Lib\site-packages\django\core\handlers\base.py", line 197, in _get_response
    response = wrapped_callback(request, *callback_args, **callback_kwargs)
               ^^^^^^^^^^^^^^^^^^^^^^^^^^^^^^^^^^^^^^^^^^^^^^^^^^^^^^^^^^^^
  File "C:\Users\Lenovo\Downloads\Appstack\Appstack\freelance_project\customer_engine\decorators.py", line 28, in _wrapped_view
    return view_func(request, *args, **kwargs)
           ^^^^^^^^^^^^^^^^^^^^^^^^^^^^^^^^^^^
  File "C:\Users\Lenovo\Downloads\Appstack\Appstack\freelance_project\backoffice_engine\views.py", line 164, in index
    return render(request,"index.html",{
           ^^^^^^^^^^^^^^^^^^^^^^^^^^^^^
  File "C:\Users\Lenovo\Downloads\Appstack\Appstack\env\Lib\site-packages\django\shortcuts.py", line 24, in render
    content = loader.render_to_string(template_name, context, request, using=using)
              ^^^^^^^^^^^^^^^^^^^^^^^^^^^^^^^^^^^^^^^^^^^^^^^^^^^^^^^^^^^^^^^^^^^^^
  File "C:\Users\Lenovo\Downloads\Appstack\Appstack\env\Lib\site-packages\django\template\loader.py", line 62, in render_to_string
    return template.render(context, request)
           ^^^^^^^^^^^^^^^^^^^^^^^^^^^^^^^^^
  File "C:\Users\Lenovo\Downloads\Appstack\Appstack\env\Lib\site-packages\django\template\backends\django.py", line 61, in render
    return self.template.render(context)
           ^^^^^^^^^^^^^^^^^^^^^^^^^^^^^
  File "C:\Users\Lenovo\Downloads\Appstack\Appstack\env\Lib\site-packages\django\template\base.py", line 175, in render
    return self._render(context)
           ^^^^^^^^^^^^^^^^^^^^^
  File "C:\Users\Lenovo\Downloads\Appstack\Appstack\env\Lib\site-packages\django\template\base.py", line 167, in _render
    return self.nodelist.render(context)
           ^^^^^^^^^^^^^^^^^^^^^^^^^^^^^
  File "C:\Users\Lenovo\Downloads\Appstack\Appstack\env\Lib\site-packages\django\template\base.py", line 1005, in render
    return SafeString("".join([node.render_annotated(context) for node in self]))
                              ^^^^^^^^^^^^^^^^^^^^^^^^^^^^^^^^^^^^^^^^^^^^^^^^^
  File "C:\Users\Lenovo\Downloads\Appstack\Appstack\env\Lib\site-packages\django\template\base.py", line 1005, in <listcomp>
    return SafeString("".join([node.render_annotated(context) for node in self]))
                               ^^^^^^^^^^^^^^^^^^^^^^^^^^^^^^
  File "C:\Users\Lenovo\Downloads\Appstack\Appstack\env\Lib\site-packages\django\template\base.py", line 966, in render_annotated
    return self.render(context)
           ^^^^^^^^^^^^^^^^^^^^
  File "C:\Users\Lenovo\Downloads\Appstack\Appstack\env\Lib\site-packages\django\template\defaulttags.py", line 471, in render
    url = reverse(view_name, args=args, kwargs=kwargs, current_app=current_app)
          ^^^^^^^^^^^^^^^^^^^^^^^^^^^^^^^^^^^^^^^^^^^^^^^^^^^^^^^^^^^^^^^^^^^^^
  File "C:\Users\Lenovo\Downloads\Appstack\Appstack\env\Lib\site-packages\django\urls\base.py", line 88, in reverse
    return resolver._reverse_with_prefix(view, prefix, *args, **kwargs)
           ^^^^^^^^^^^^^^^^^^^^^^^^^^^^^^^^^^^^^^^^^^^^^^^^^^^^^^^^^^^^
  File "C:\Users\Lenovo\Downloads\Appstack\Appstack\env\Lib\site-packages\django\urls\resolvers.py", line 828, in _reverse_with_prefix
    raise NoReverseMatch(msg)
django.urls.exceptions.NoReverseMatch: Reverse for 'dish-calculator-items' not found. 'dish-calculator-items' is not a valid view function or pattern name.
ERROR 2023-10-06 11:56:16,395 log Internal Server Error: /dashboard/
Traceback (most recent call last):
  File "C:\Users\Lenovo\Downloads\Appstack\Appstack\env\Lib\site-packages\django\core\handlers\exception.py", line 55, in inner
    response = get_response(request)
               ^^^^^^^^^^^^^^^^^^^^^
  File "C:\Users\Lenovo\Downloads\Appstack\Appstack\env\Lib\site-packages\django\core\handlers\base.py", line 197, in _get_response
    response = wrapped_callback(request, *callback_args, **callback_kwargs)
               ^^^^^^^^^^^^^^^^^^^^^^^^^^^^^^^^^^^^^^^^^^^^^^^^^^^^^^^^^^^^
  File "C:\Users\Lenovo\Downloads\Appstack\Appstack\freelance_project\customer_engine\decorators.py", line 28, in _wrapped_view
    return view_func(request, *args, **kwargs)
           ^^^^^^^^^^^^^^^^^^^^^^^^^^^^^^^^^^^
  File "C:\Users\Lenovo\Downloads\Appstack\Appstack\freelance_project\backoffice_engine\views.py", line 164, in index
    return render(request,"index.html",{
           ^^^^^^^^^^^^^^^^^^^^^^^^^^^^^
  File "C:\Users\Lenovo\Downloads\Appstack\Appstack\env\Lib\site-packages\django\shortcuts.py", line 24, in render
    content = loader.render_to_string(template_name, context, request, using=using)
              ^^^^^^^^^^^^^^^^^^^^^^^^^^^^^^^^^^^^^^^^^^^^^^^^^^^^^^^^^^^^^^^^^^^^^
  File "C:\Users\Lenovo\Downloads\Appstack\Appstack\env\Lib\site-packages\django\template\loader.py", line 62, in render_to_string
    return template.render(context, request)
           ^^^^^^^^^^^^^^^^^^^^^^^^^^^^^^^^^
  File "C:\Users\Lenovo\Downloads\Appstack\Appstack\env\Lib\site-packages\django\template\backends\django.py", line 61, in render
    return self.template.render(context)
           ^^^^^^^^^^^^^^^^^^^^^^^^^^^^^
  File "C:\Users\Lenovo\Downloads\Appstack\Appstack\env\Lib\site-packages\django\template\base.py", line 175, in render
    return self._render(context)
           ^^^^^^^^^^^^^^^^^^^^^
  File "C:\Users\Lenovo\Downloads\Appstack\Appstack\env\Lib\site-packages\django\template\base.py", line 167, in _render
    return self.nodelist.render(context)
           ^^^^^^^^^^^^^^^^^^^^^^^^^^^^^
  File "C:\Users\Lenovo\Downloads\Appstack\Appstack\env\Lib\site-packages\django\template\base.py", line 1005, in render
    return SafeString("".join([node.render_annotated(context) for node in self]))
                              ^^^^^^^^^^^^^^^^^^^^^^^^^^^^^^^^^^^^^^^^^^^^^^^^^
  File "C:\Users\Lenovo\Downloads\Appstack\Appstack\env\Lib\site-packages\django\template\base.py", line 1005, in <listcomp>
    return SafeString("".join([node.render_annotated(context) for node in self]))
                               ^^^^^^^^^^^^^^^^^^^^^^^^^^^^^^
  File "C:\Users\Lenovo\Downloads\Appstack\Appstack\env\Lib\site-packages\django\template\base.py", line 966, in render_annotated
    return self.render(context)
           ^^^^^^^^^^^^^^^^^^^^
  File "C:\Users\Lenovo\Downloads\Appstack\Appstack\env\Lib\site-packages\django\template\defaulttags.py", line 471, in render
    url = reverse(view_name, args=args, kwargs=kwargs, current_app=current_app)
          ^^^^^^^^^^^^^^^^^^^^^^^^^^^^^^^^^^^^^^^^^^^^^^^^^^^^^^^^^^^^^^^^^^^^^
  File "C:\Users\Lenovo\Downloads\Appstack\Appstack\env\Lib\site-packages\django\urls\base.py", line 88, in reverse
    return resolver._reverse_with_prefix(view, prefix, *args, **kwargs)
           ^^^^^^^^^^^^^^^^^^^^^^^^^^^^^^^^^^^^^^^^^^^^^^^^^^^^^^^^^^^^
  File "C:\Users\Lenovo\Downloads\Appstack\Appstack\env\Lib\site-packages\django\urls\resolvers.py", line 828, in _reverse_with_prefix
    raise NoReverseMatch(msg)
django.urls.exceptions.NoReverseMatch: Reverse for 'ingredient_items' not found. 'ingredient_items' is not a valid view function or pattern name.
ERROR 2023-10-06 12:10:59,848 log Internal Server Error: /add/customer/
Traceback (most recent call last):
  File "C:\Users\Lenovo\Downloads\Appstack\Appstack\env\Lib\site-packages\django\core\handlers\exception.py", line 55, in inner
    response = get_response(request)
               ^^^^^^^^^^^^^^^^^^^^^
  File "C:\Users\Lenovo\Downloads\Appstack\Appstack\env\Lib\site-packages\django\core\handlers\base.py", line 197, in _get_response
    response = wrapped_callback(request, *callback_args, **callback_kwargs)
               ^^^^^^^^^^^^^^^^^^^^^^^^^^^^^^^^^^^^^^^^^^^^^^^^^^^^^^^^^^^^
  File "C:\Users\Lenovo\Downloads\Appstack\Appstack\freelance_project\customer_engine\decorators.py", line 28, in _wrapped_view
    return view_func(request, *args, **kwargs)
           ^^^^^^^^^^^^^^^^^^^^^^^^^^^^^^^^^^^
  File "C:\Users\Lenovo\Downloads\Appstack\Appstack\freelance_project\backoffice_engine\views.py", line 275, in add_customer
    return render(request,"add_customer.html",{
           ^^^^^^^^^^^^^^^^^^^^^^^^^^^^^^^^^^^^
  File "C:\Users\Lenovo\Downloads\Appstack\Appstack\env\Lib\site-packages\django\shortcuts.py", line 24, in render
    content = loader.render_to_string(template_name, context, request, using=using)
              ^^^^^^^^^^^^^^^^^^^^^^^^^^^^^^^^^^^^^^^^^^^^^^^^^^^^^^^^^^^^^^^^^^^^^
  File "C:\Users\Lenovo\Downloads\Appstack\Appstack\env\Lib\site-packages\django\template\loader.py", line 62, in render_to_string
    return template.render(context, request)
           ^^^^^^^^^^^^^^^^^^^^^^^^^^^^^^^^^
  File "C:\Users\Lenovo\Downloads\Appstack\Appstack\env\Lib\site-packages\django\template\backends\django.py", line 61, in render
    return self.template.render(context)
           ^^^^^^^^^^^^^^^^^^^^^^^^^^^^^
  File "C:\Users\Lenovo\Downloads\Appstack\Appstack\env\Lib\site-packages\django\template\base.py", line 175, in render
    return self._render(context)
           ^^^^^^^^^^^^^^^^^^^^^
  File "C:\Users\Lenovo\Downloads\Appstack\Appstack\env\Lib\site-packages\django\template\base.py", line 167, in _render
    return self.nodelist.render(context)
           ^^^^^^^^^^^^^^^^^^^^^^^^^^^^^
  File "C:\Users\Lenovo\Downloads\Appstack\Appstack\env\Lib\site-packages\django\template\base.py", line 1005, in render
    return SafeString("".join([node.render_annotated(context) for node in self]))
                              ^^^^^^^^^^^^^^^^^^^^^^^^^^^^^^^^^^^^^^^^^^^^^^^^^
  File "C:\Users\Lenovo\Downloads\Appstack\Appstack\env\Lib\site-packages\django\template\base.py", line 1005, in <listcomp>
    return SafeString("".join([node.render_annotated(context) for node in self]))
                               ^^^^^^^^^^^^^^^^^^^^^^^^^^^^^^
  File "C:\Users\Lenovo\Downloads\Appstack\Appstack\env\Lib\site-packages\django\template\base.py", line 966, in render_annotated
    return self.render(context)
           ^^^^^^^^^^^^^^^^^^^^
  File "C:\Users\Lenovo\Downloads\Appstack\Appstack\env\Lib\site-packages\django\template\loader_tags.py", line 157, in render
    return compiled_parent._render(context)
           ^^^^^^^^^^^^^^^^^^^^^^^^^^^^^^^^
  File "C:\Users\Lenovo\Downloads\Appstack\Appstack\env\Lib\site-packages\django\template\base.py", line 167, in _render
    return self.nodelist.render(context)
           ^^^^^^^^^^^^^^^^^^^^^^^^^^^^^
  File "C:\Users\Lenovo\Downloads\Appstack\Appstack\env\Lib\site-packages\django\template\base.py", line 1005, in render
    return SafeString("".join([node.render_annotated(context) for node in self]))
                              ^^^^^^^^^^^^^^^^^^^^^^^^^^^^^^^^^^^^^^^^^^^^^^^^^
  File "C:\Users\Lenovo\Downloads\Appstack\Appstack\env\Lib\site-packages\django\template\base.py", line 1005, in <listcomp>
    return SafeString("".join([node.render_annotated(context) for node in self]))
                               ^^^^^^^^^^^^^^^^^^^^^^^^^^^^^^
  File "C:\Users\Lenovo\Downloads\Appstack\Appstack\env\Lib\site-packages\django\template\base.py", line 966, in render_annotated
    return self.render(context)
           ^^^^^^^^^^^^^^^^^^^^
  File "C:\Users\Lenovo\Downloads\Appstack\Appstack\env\Lib\site-packages\django\template\loader_tags.py", line 63, in render
    result = block.nodelist.render(context)
             ^^^^^^^^^^^^^^^^^^^^^^^^^^^^^^
  File "C:\Users\Lenovo\Downloads\Appstack\Appstack\env\Lib\site-packages\django\template\base.py", line 1005, in render
    return SafeString("".join([node.render_annotated(context) for node in self]))
                              ^^^^^^^^^^^^^^^^^^^^^^^^^^^^^^^^^^^^^^^^^^^^^^^^^
  File "C:\Users\Lenovo\Downloads\Appstack\Appstack\env\Lib\site-packages\django\template\base.py", line 1005, in <listcomp>
    return SafeString("".join([node.render_annotated(context) for node in self]))
                               ^^^^^^^^^^^^^^^^^^^^^^^^^^^^^^
  File "C:\Users\Lenovo\Downloads\Appstack\Appstack\env\Lib\site-packages\django\template\base.py", line 966, in render_annotated
    return self.render(context)
           ^^^^^^^^^^^^^^^^^^^^
  File "C:\Users\Lenovo\Downloads\Appstack\Appstack\env\Lib\site-packages\django\template\defaulttags.py", line 471, in render
    url = reverse(view_name, args=args, kwargs=kwargs, current_app=current_app)
          ^^^^^^^^^^^^^^^^^^^^^^^^^^^^^^^^^^^^^^^^^^^^^^^^^^^^^^^^^^^^^^^^^^^^^
  File "C:\Users\Lenovo\Downloads\Appstack\Appstack\env\Lib\site-packages\django\urls\base.py", line 88, in reverse
    return resolver._reverse_with_prefix(view, prefix, *args, **kwargs)
           ^^^^^^^^^^^^^^^^^^^^^^^^^^^^^^^^^^^^^^^^^^^^^^^^^^^^^^^^^^^^
  File "C:\Users\Lenovo\Downloads\Appstack\Appstack\env\Lib\site-packages\django\urls\resolvers.py", line 828, in _reverse_with_prefix
    raise NoReverseMatch(msg)
django.urls.exceptions.NoReverseMatch: Reverse for 'customer-datatable' not found. 'customer-datatable' is not a valid view function or pattern name.
ERROR 2023-10-06 12:11:04,757 log Internal Server Error: /add/customer/
Traceback (most recent call last):
  File "C:\Users\Lenovo\Downloads\Appstack\Appstack\env\Lib\site-packages\django\core\handlers\exception.py", line 55, in inner
    response = get_response(request)
               ^^^^^^^^^^^^^^^^^^^^^
  File "C:\Users\Lenovo\Downloads\Appstack\Appstack\env\Lib\site-packages\django\core\handlers\base.py", line 197, in _get_response
    response = wrapped_callback(request, *callback_args, **callback_kwargs)
               ^^^^^^^^^^^^^^^^^^^^^^^^^^^^^^^^^^^^^^^^^^^^^^^^^^^^^^^^^^^^
  File "C:\Users\Lenovo\Downloads\Appstack\Appstack\freelance_project\customer_engine\decorators.py", line 28, in _wrapped_view
    return view_func(request, *args, **kwargs)
           ^^^^^^^^^^^^^^^^^^^^^^^^^^^^^^^^^^^
  File "C:\Users\Lenovo\Downloads\Appstack\Appstack\freelance_project\backoffice_engine\views.py", line 287, in add_customer
    return render(request,"add_customer.html",{
           ^^^^^^^^^^^^^^^^^^^^^^^^^^^^^^^^^^^^
  File "C:\Users\Lenovo\Downloads\Appstack\Appstack\env\Lib\site-packages\django\shortcuts.py", line 24, in render
    content = loader.render_to_string(template_name, context, request, using=using)
              ^^^^^^^^^^^^^^^^^^^^^^^^^^^^^^^^^^^^^^^^^^^^^^^^^^^^^^^^^^^^^^^^^^^^^
  File "C:\Users\Lenovo\Downloads\Appstack\Appstack\env\Lib\site-packages\django\template\loader.py", line 62, in render_to_string
    return template.render(context, request)
           ^^^^^^^^^^^^^^^^^^^^^^^^^^^^^^^^^
  File "C:\Users\Lenovo\Downloads\Appstack\Appstack\env\Lib\site-packages\django\template\backends\django.py", line 61, in render
    return self.template.render(context)
           ^^^^^^^^^^^^^^^^^^^^^^^^^^^^^
  File "C:\Users\Lenovo\Downloads\Appstack\Appstack\env\Lib\site-packages\django\template\base.py", line 175, in render
    return self._render(context)
           ^^^^^^^^^^^^^^^^^^^^^
  File "C:\Users\Lenovo\Downloads\Appstack\Appstack\env\Lib\site-packages\django\template\base.py", line 167, in _render
    return self.nodelist.render(context)
           ^^^^^^^^^^^^^^^^^^^^^^^^^^^^^
  File "C:\Users\Lenovo\Downloads\Appstack\Appstack\env\Lib\site-packages\django\template\base.py", line 1005, in render
    return SafeString("".join([node.render_annotated(context) for node in self]))
                              ^^^^^^^^^^^^^^^^^^^^^^^^^^^^^^^^^^^^^^^^^^^^^^^^^
  File "C:\Users\Lenovo\Downloads\Appstack\Appstack\env\Lib\site-packages\django\template\base.py", line 1005, in <listcomp>
    return SafeString("".join([node.render_annotated(context) for node in self]))
                               ^^^^^^^^^^^^^^^^^^^^^^^^^^^^^^
  File "C:\Users\Lenovo\Downloads\Appstack\Appstack\env\Lib\site-packages\django\template\base.py", line 966, in render_annotated
    return self.render(context)
           ^^^^^^^^^^^^^^^^^^^^
  File "C:\Users\Lenovo\Downloads\Appstack\Appstack\env\Lib\site-packages\django\template\loader_tags.py", line 157, in render
    return compiled_parent._render(context)
           ^^^^^^^^^^^^^^^^^^^^^^^^^^^^^^^^
  File "C:\Users\Lenovo\Downloads\Appstack\Appstack\env\Lib\site-packages\django\template\base.py", line 167, in _render
    return self.nodelist.render(context)
           ^^^^^^^^^^^^^^^^^^^^^^^^^^^^^
  File "C:\Users\Lenovo\Downloads\Appstack\Appstack\env\Lib\site-packages\django\template\base.py", line 1005, in render
    return SafeString("".join([node.render_annotated(context) for node in self]))
                              ^^^^^^^^^^^^^^^^^^^^^^^^^^^^^^^^^^^^^^^^^^^^^^^^^
  File "C:\Users\Lenovo\Downloads\Appstack\Appstack\env\Lib\site-packages\django\template\base.py", line 1005, in <listcomp>
    return SafeString("".join([node.render_annotated(context) for node in self]))
                               ^^^^^^^^^^^^^^^^^^^^^^^^^^^^^^
  File "C:\Users\Lenovo\Downloads\Appstack\Appstack\env\Lib\site-packages\django\template\base.py", line 966, in render_annotated
    return self.render(context)
           ^^^^^^^^^^^^^^^^^^^^
  File "C:\Users\Lenovo\Downloads\Appstack\Appstack\env\Lib\site-packages\django\template\loader_tags.py", line 63, in render
    result = block.nodelist.render(context)
             ^^^^^^^^^^^^^^^^^^^^^^^^^^^^^^
  File "C:\Users\Lenovo\Downloads\Appstack\Appstack\env\Lib\site-packages\django\template\base.py", line 1005, in render
    return SafeString("".join([node.render_annotated(context) for node in self]))
                              ^^^^^^^^^^^^^^^^^^^^^^^^^^^^^^^^^^^^^^^^^^^^^^^^^
  File "C:\Users\Lenovo\Downloads\Appstack\Appstack\env\Lib\site-packages\django\template\base.py", line 1005, in <listcomp>
    return SafeString("".join([node.render_annotated(context) for node in self]))
                               ^^^^^^^^^^^^^^^^^^^^^^^^^^^^^^
  File "C:\Users\Lenovo\Downloads\Appstack\Appstack\env\Lib\site-packages\django\template\base.py", line 966, in render_annotated
    return self.render(context)
           ^^^^^^^^^^^^^^^^^^^^
  File "C:\Users\Lenovo\Downloads\Appstack\Appstack\env\Lib\site-packages\django\template\defaulttags.py", line 471, in render
    url = reverse(view_name, args=args, kwargs=kwargs, current_app=current_app)
          ^^^^^^^^^^^^^^^^^^^^^^^^^^^^^^^^^^^^^^^^^^^^^^^^^^^^^^^^^^^^^^^^^^^^^
  File "C:\Users\Lenovo\Downloads\Appstack\Appstack\env\Lib\site-packages\django\urls\base.py", line 88, in reverse
    return resolver._reverse_with_prefix(view, prefix, *args, **kwargs)
           ^^^^^^^^^^^^^^^^^^^^^^^^^^^^^^^^^^^^^^^^^^^^^^^^^^^^^^^^^^^^
  File "C:\Users\Lenovo\Downloads\Appstack\Appstack\env\Lib\site-packages\django\urls\resolvers.py", line 828, in _reverse_with_prefix
    raise NoReverseMatch(msg)
django.urls.exceptions.NoReverseMatch: Reverse for 'customer-datatable' not found. 'customer-datatable' is not a valid view function or pattern name.
ERROR 2023-10-06 12:22:15,322 log Internal Server Error: /upload-csv/
Traceback (most recent call last):
  File "C:\Users\Lenovo\Downloads\Appstack\Appstack\env\Lib\site-packages\django\core\handlers\exception.py", line 55, in inner
    response = get_response(request)
               ^^^^^^^^^^^^^^^^^^^^^
  File "C:\Users\Lenovo\Downloads\Appstack\Appstack\env\Lib\site-packages\django\core\handlers\base.py", line 197, in _get_response
    response = wrapped_callback(request, *callback_args, **callback_kwargs)
               ^^^^^^^^^^^^^^^^^^^^^^^^^^^^^^^^^^^^^^^^^^^^^^^^^^^^^^^^^^^^
  File "C:\Users\Lenovo\Downloads\Appstack\Appstack\freelance_project\customer_engine\decorators.py", line 28, in _wrapped_view
    return view_func(request, *args, **kwargs)
           ^^^^^^^^^^^^^^^^^^^^^^^^^^^^^^^^^^^
  File "C:\Users\Lenovo\Downloads\Appstack\Appstack\freelance_project\backoffice_engine\views.py", line 607, in upload_csv
    reader = csv.DictReader(decoded_data.splitlines())
             ^^^
NameError: name 'csv' is not defined
ERROR 2023-10-06 12:22:15,385 log Internal Server Error: /upload-csv/
Traceback (most recent call last):
  File "C:\Users\Lenovo\Downloads\Appstack\Appstack\env\Lib\site-packages\django\core\handlers\exception.py", line 55, in inner
    response = get_response(request)
               ^^^^^^^^^^^^^^^^^^^^^
  File "C:\Users\Lenovo\Downloads\Appstack\Appstack\env\Lib\site-packages\django\core\handlers\base.py", line 197, in _get_response
    response = wrapped_callback(request, *callback_args, **callback_kwargs)
               ^^^^^^^^^^^^^^^^^^^^^^^^^^^^^^^^^^^^^^^^^^^^^^^^^^^^^^^^^^^^
  File "C:\Users\Lenovo\Downloads\Appstack\Appstack\freelance_project\customer_engine\decorators.py", line 28, in _wrapped_view
    return view_func(request, *args, **kwargs)
           ^^^^^^^^^^^^^^^^^^^^^^^^^^^^^^^^^^^
  File "C:\Users\Lenovo\Downloads\Appstack\Appstack\freelance_project\backoffice_engine\views.py", line 607, in upload_csv
    reader = csv.DictReader(decoded_data.splitlines())
             ^^^
NameError: name 'csv' is not defined
ERROR 2023-10-06 12:27:30,800 log Internal Server Error: /add/customer/
Traceback (most recent call last):
  File "C:\Users\Lenovo\Downloads\Appstack\Appstack\env\Lib\site-packages\django\core\handlers\exception.py", line 55, in inner
    response = get_response(request)
               ^^^^^^^^^^^^^^^^^^^^^
  File "C:\Users\Lenovo\Downloads\Appstack\Appstack\env\Lib\site-packages\django\core\handlers\base.py", line 204, in _get_response
    self.check_response(response, callback)
  File "C:\Users\Lenovo\Downloads\Appstack\Appstack\env\Lib\site-packages\django\core\handlers\base.py", line 332, in check_response
    raise ValueError(
ValueError: The view backoffice_engine.views.add_customer didn't return an HttpResponse object. It returned None instead.
ERROR 2023-10-06 12:29:24,348 log Internal Server Error: /upload-csv/
Traceback (most recent call last):
  File "C:\Users\Lenovo\Downloads\Appstack\Appstack\env\Lib\site-packages\django\core\handlers\exception.py", line 55, in inner
    response = get_response(request)
               ^^^^^^^^^^^^^^^^^^^^^
  File "C:\Users\Lenovo\Downloads\Appstack\Appstack\env\Lib\site-packages\django\core\handlers\base.py", line 197, in _get_response
    response = wrapped_callback(request, *callback_args, **callback_kwargs)
               ^^^^^^^^^^^^^^^^^^^^^^^^^^^^^^^^^^^^^^^^^^^^^^^^^^^^^^^^^^^^
  File "C:\Users\Lenovo\Downloads\Appstack\Appstack\freelance_project\customer_engine\decorators.py", line 28, in _wrapped_view
    return view_func(request, *args, **kwargs)
           ^^^^^^^^^^^^^^^^^^^^^^^^^^^^^^^^^^^
  File "C:\Users\Lenovo\Downloads\Appstack\Appstack\freelance_project\backoffice_engine\views.py", line 607, in upload_csv
    reader = csv.DictReader(decoded_data.splitlines())
             ^^^
NameError: name 'csv' is not defined
ERROR 2023-10-06 12:30:23,917 log Internal Server Error: /upload-csv/
Traceback (most recent call last):
  File "C:\Users\Lenovo\Downloads\Appstack\Appstack\env\Lib\site-packages\django\core\handlers\exception.py", line 55, in inner
    response = get_response(request)
               ^^^^^^^^^^^^^^^^^^^^^
  File "C:\Users\Lenovo\Downloads\Appstack\Appstack\env\Lib\site-packages\django\core\handlers\base.py", line 197, in _get_response
    response = wrapped_callback(request, *callback_args, **callback_kwargs)
               ^^^^^^^^^^^^^^^^^^^^^^^^^^^^^^^^^^^^^^^^^^^^^^^^^^^^^^^^^^^^
  File "C:\Users\Lenovo\Downloads\Appstack\Appstack\freelance_project\customer_engine\decorators.py", line 28, in _wrapped_view
    return view_func(request, *args, **kwargs)
           ^^^^^^^^^^^^^^^^^^^^^^^^^^^^^^^^^^^
  File "C:\Users\Lenovo\Downloads\Appstack\Appstack\freelance_project\backoffice_engine\views.py", line 609, in upload_csv
    reader = csv.DictReader(decoded_data.splitlines())
             ^^^
NameError: name 'csv' is not defined
ERROR 2023-10-06 12:31:53,244 log Internal Server Error: /upload-csv/
Traceback (most recent call last):
  File "C:\Users\Lenovo\Downloads\Appstack\Appstack\env\Lib\site-packages\django\core\handlers\exception.py", line 55, in inner
    response = get_response(request)
               ^^^^^^^^^^^^^^^^^^^^^
  File "C:\Users\Lenovo\Downloads\Appstack\Appstack\env\Lib\site-packages\django\core\handlers\base.py", line 197, in _get_response
    response = wrapped_callback(request, *callback_args, **callback_kwargs)
               ^^^^^^^^^^^^^^^^^^^^^^^^^^^^^^^^^^^^^^^^^^^^^^^^^^^^^^^^^^^^
  File "C:\Users\Lenovo\Downloads\Appstack\Appstack\freelance_project\customer_engine\decorators.py", line 28, in _wrapped_view
    return view_func(request, *args, **kwargs)
           ^^^^^^^^^^^^^^^^^^^^^^^^^^^^^^^^^^^
  File "C:\Users\Lenovo\Downloads\Appstack\Appstack\freelance_project\backoffice_engine\views.py", line 650, in upload_csv
    return HttpResponse("CSV file uploaded and processed successfully.")
           ^^^^^^^^^^^^
NameError: name 'HttpResponse' is not defined
ERROR 2023-10-06 12:39:02,003 log Internal Server Error: /dish/calculator/
Traceback (most recent call last):
  File "C:\Users\Lenovo\Downloads\Appstack\Appstack\env\Lib\site-packages\django\core\handlers\exception.py", line 55, in inner
    response = get_response(request)
               ^^^^^^^^^^^^^^^^^^^^^
  File "C:\Users\Lenovo\Downloads\Appstack\Appstack\env\Lib\site-packages\django\core\handlers\base.py", line 197, in _get_response
    response = wrapped_callback(request, *callback_args, **callback_kwargs)
               ^^^^^^^^^^^^^^^^^^^^^^^^^^^^^^^^^^^^^^^^^^^^^^^^^^^^^^^^^^^^
  File "C:\Users\Lenovo\Downloads\Appstack\Appstack\freelance_project\customer_engine\decorators.py", line 28, in _wrapped_view
    return view_func(request, *args, **kwargs)
           ^^^^^^^^^^^^^^^^^^^^^^^^^^^^^^^^^^^
  File "C:\Users\Lenovo\Downloads\Appstack\Appstack\freelance_project\backoffice_engine\views.py", line 249, in dish_calculator
    return render(request,"dish-calculator-items.html",{
           ^^^^^^^^^^^^^^^^^^^^^^^^^^^^^^^^^^^^^^^^^^^^^
  File "C:\Users\Lenovo\Downloads\Appstack\Appstack\env\Lib\site-packages\django\shortcuts.py", line 24, in render
    content = loader.render_to_string(template_name, context, request, using=using)
              ^^^^^^^^^^^^^^^^^^^^^^^^^^^^^^^^^^^^^^^^^^^^^^^^^^^^^^^^^^^^^^^^^^^^^
  File "C:\Users\Lenovo\Downloads\Appstack\Appstack\env\Lib\site-packages\django\template\loader.py", line 62, in render_to_string
    return template.render(context, request)
           ^^^^^^^^^^^^^^^^^^^^^^^^^^^^^^^^^
  File "C:\Users\Lenovo\Downloads\Appstack\Appstack\env\Lib\site-packages\django\template\backends\django.py", line 61, in render
    return self.template.render(context)
           ^^^^^^^^^^^^^^^^^^^^^^^^^^^^^
  File "C:\Users\Lenovo\Downloads\Appstack\Appstack\env\Lib\site-packages\django\template\base.py", line 175, in render
    return self._render(context)
           ^^^^^^^^^^^^^^^^^^^^^
  File "C:\Users\Lenovo\Downloads\Appstack\Appstack\env\Lib\site-packages\django\template\base.py", line 167, in _render
    return self.nodelist.render(context)
           ^^^^^^^^^^^^^^^^^^^^^^^^^^^^^
  File "C:\Users\Lenovo\Downloads\Appstack\Appstack\env\Lib\site-packages\django\template\base.py", line 1005, in render
    return SafeString("".join([node.render_annotated(context) for node in self]))
                              ^^^^^^^^^^^^^^^^^^^^^^^^^^^^^^^^^^^^^^^^^^^^^^^^^
  File "C:\Users\Lenovo\Downloads\Appstack\Appstack\env\Lib\site-packages\django\template\base.py", line 1005, in <listcomp>
    return SafeString("".join([node.render_annotated(context) for node in self]))
                               ^^^^^^^^^^^^^^^^^^^^^^^^^^^^^^
  File "C:\Users\Lenovo\Downloads\Appstack\Appstack\env\Lib\site-packages\django\template\base.py", line 966, in render_annotated
    return self.render(context)
           ^^^^^^^^^^^^^^^^^^^^
  File "C:\Users\Lenovo\Downloads\Appstack\Appstack\env\Lib\site-packages\django\template\loader_tags.py", line 157, in render
    return compiled_parent._render(context)
           ^^^^^^^^^^^^^^^^^^^^^^^^^^^^^^^^
  File "C:\Users\Lenovo\Downloads\Appstack\Appstack\env\Lib\site-packages\django\template\base.py", line 167, in _render
    return self.nodelist.render(context)
           ^^^^^^^^^^^^^^^^^^^^^^^^^^^^^
  File "C:\Users\Lenovo\Downloads\Appstack\Appstack\env\Lib\site-packages\django\template\base.py", line 1005, in render
    return SafeString("".join([node.render_annotated(context) for node in self]))
                              ^^^^^^^^^^^^^^^^^^^^^^^^^^^^^^^^^^^^^^^^^^^^^^^^^
  File "C:\Users\Lenovo\Downloads\Appstack\Appstack\env\Lib\site-packages\django\template\base.py", line 1005, in <listcomp>
    return SafeString("".join([node.render_annotated(context) for node in self]))
                               ^^^^^^^^^^^^^^^^^^^^^^^^^^^^^^
  File "C:\Users\Lenovo\Downloads\Appstack\Appstack\env\Lib\site-packages\django\template\base.py", line 966, in render_annotated
    return self.render(context)
           ^^^^^^^^^^^^^^^^^^^^
  File "C:\Users\Lenovo\Downloads\Appstack\Appstack\env\Lib\site-packages\django\template\loader_tags.py", line 63, in render
    result = block.nodelist.render(context)
             ^^^^^^^^^^^^^^^^^^^^^^^^^^^^^^
  File "C:\Users\Lenovo\Downloads\Appstack\Appstack\env\Lib\site-packages\django\template\base.py", line 1005, in render
    return SafeString("".join([node.render_annotated(context) for node in self]))
                              ^^^^^^^^^^^^^^^^^^^^^^^^^^^^^^^^^^^^^^^^^^^^^^^^^
  File "C:\Users\Lenovo\Downloads\Appstack\Appstack\env\Lib\site-packages\django\template\base.py", line 1005, in <listcomp>
    return SafeString("".join([node.render_annotated(context) for node in self]))
                               ^^^^^^^^^^^^^^^^^^^^^^^^^^^^^^
  File "C:\Users\Lenovo\Downloads\Appstack\Appstack\env\Lib\site-packages\django\template\base.py", line 966, in render_annotated
    return self.render(context)
           ^^^^^^^^^^^^^^^^^^^^
  File "C:\Users\Lenovo\Downloads\Appstack\Appstack\env\Lib\site-packages\django\template\defaulttags.py", line 471, in render
    url = reverse(view_name, args=args, kwargs=kwargs, current_app=current_app)
          ^^^^^^^^^^^^^^^^^^^^^^^^^^^^^^^^^^^^^^^^^^^^^^^^^^^^^^^^^^^^^^^^^^^^^
  File "C:\Users\Lenovo\Downloads\Appstack\Appstack\env\Lib\site-packages\django\urls\base.py", line 88, in reverse
    return resolver._reverse_with_prefix(view, prefix, *args, **kwargs)
           ^^^^^^^^^^^^^^^^^^^^^^^^^^^^^^^^^^^^^^^^^^^^^^^^^^^^^^^^^^^^
  File "C:\Users\Lenovo\Downloads\Appstack\Appstack\env\Lib\site-packages\django\urls\resolvers.py", line 828, in _reverse_with_prefix
    raise NoReverseMatch(msg)
django.urls.exceptions.NoReverseMatch: Reverse for 'add_dish_calculator' not found. 'add_dish_calculator' is not a valid view function or pattern name.
ERROR 2023-10-06 12:44:31,970 log Internal Server Error: /ingredient-items/
Traceback (most recent call last):
  File "C:\Users\Lenovo\Downloads\Appstack\Appstack\env\Lib\site-packages\django\core\handlers\exception.py", line 55, in inner
    response = get_response(request)
               ^^^^^^^^^^^^^^^^^^^^^
  File "C:\Users\Lenovo\Downloads\Appstack\Appstack\env\Lib\site-packages\django\core\handlers\base.py", line 197, in _get_response
    response = wrapped_callback(request, *callback_args, **callback_kwargs)
               ^^^^^^^^^^^^^^^^^^^^^^^^^^^^^^^^^^^^^^^^^^^^^^^^^^^^^^^^^^^^
  File "C:\Users\Lenovo\Downloads\Appstack\Appstack\freelance_project\backoffice_engine\views.py", line 664, in ingredients_items
    return render(request,"ingredients-items.html",{
           ^^^^^^^^^^^^^^^^^^^^^^^^^^^^^^^^^^^^^^^^^
  File "C:\Users\Lenovo\Downloads\Appstack\Appstack\env\Lib\site-packages\django\shortcuts.py", line 24, in render
    content = loader.render_to_string(template_name, context, request, using=using)
              ^^^^^^^^^^^^^^^^^^^^^^^^^^^^^^^^^^^^^^^^^^^^^^^^^^^^^^^^^^^^^^^^^^^^^
  File "C:\Users\Lenovo\Downloads\Appstack\Appstack\env\Lib\site-packages\django\template\loader.py", line 61, in render_to_string
    template = get_template(template_name, using=using)
               ^^^^^^^^^^^^^^^^^^^^^^^^^^^^^^^^^^^^^^^^
  File "C:\Users\Lenovo\Downloads\Appstack\Appstack\env\Lib\site-packages\django\template\loader.py", line 19, in get_template
    raise TemplateDoesNotExist(template_name, chain=chain)
django.template.exceptions.TemplateDoesNotExist: ingredients-items.html
ERROR 2023-10-06 12:44:35,239 log Internal Server Error: /ingredient-items/
Traceback (most recent call last):
  File "C:\Users\Lenovo\Downloads\Appstack\Appstack\env\Lib\site-packages\django\core\handlers\exception.py", line 55, in inner
    response = get_response(request)
               ^^^^^^^^^^^^^^^^^^^^^
  File "C:\Users\Lenovo\Downloads\Appstack\Appstack\env\Lib\site-packages\django\core\handlers\base.py", line 197, in _get_response
    response = wrapped_callback(request, *callback_args, **callback_kwargs)
               ^^^^^^^^^^^^^^^^^^^^^^^^^^^^^^^^^^^^^^^^^^^^^^^^^^^^^^^^^^^^
  File "C:\Users\Lenovo\Downloads\Appstack\Appstack\freelance_project\backoffice_engine\views.py", line 664, in ingredients_items
    return render(request,"ingredients-items.html",{
           ^^^^^^^^^^^^^^^^^^^^^^^^^^^^^^^^^^^^^^^^^
  File "C:\Users\Lenovo\Downloads\Appstack\Appstack\env\Lib\site-packages\django\shortcuts.py", line 24, in render
    content = loader.render_to_string(template_name, context, request, using=using)
              ^^^^^^^^^^^^^^^^^^^^^^^^^^^^^^^^^^^^^^^^^^^^^^^^^^^^^^^^^^^^^^^^^^^^^
  File "C:\Users\Lenovo\Downloads\Appstack\Appstack\env\Lib\site-packages\django\template\loader.py", line 61, in render_to_string
    template = get_template(template_name, using=using)
               ^^^^^^^^^^^^^^^^^^^^^^^^^^^^^^^^^^^^^^^^
  File "C:\Users\Lenovo\Downloads\Appstack\Appstack\env\Lib\site-packages\django\template\loader.py", line 19, in get_template
    raise TemplateDoesNotExist(template_name, chain=chain)
django.template.exceptions.TemplateDoesNotExist: ingredients-items.html
ERROR 2023-10-06 12:50:25,309 log Internal Server Error: /ingredient-items/
Traceback (most recent call last):
  File "C:\Users\Lenovo\Downloads\Appstack\Appstack\env\Lib\site-packages\django\core\handlers\exception.py", line 55, in inner
    response = get_response(request)
               ^^^^^^^^^^^^^^^^^^^^^
  File "C:\Users\Lenovo\Downloads\Appstack\Appstack\env\Lib\site-packages\django\core\handlers\base.py", line 197, in _get_response
    response = wrapped_callback(request, *callback_args, **callback_kwargs)
               ^^^^^^^^^^^^^^^^^^^^^^^^^^^^^^^^^^^^^^^^^^^^^^^^^^^^^^^^^^^^
  File "C:\Users\Lenovo\Downloads\Appstack\Appstack\freelance_project\backoffice_engine\views.py", line 664, in ingredients_items
    return render(request,"ingredients-items.html",{
           ^^^^^^^^^^^^^^^^^^^^^^^^^^^^^^^^^^^^^^^^^
  File "C:\Users\Lenovo\Downloads\Appstack\Appstack\env\Lib\site-packages\django\shortcuts.py", line 24, in render
    content = loader.render_to_string(template_name, context, request, using=using)
              ^^^^^^^^^^^^^^^^^^^^^^^^^^^^^^^^^^^^^^^^^^^^^^^^^^^^^^^^^^^^^^^^^^^^^
  File "C:\Users\Lenovo\Downloads\Appstack\Appstack\env\Lib\site-packages\django\template\loader.py", line 61, in render_to_string
    template = get_template(template_name, using=using)
               ^^^^^^^^^^^^^^^^^^^^^^^^^^^^^^^^^^^^^^^^
  File "C:\Users\Lenovo\Downloads\Appstack\Appstack\env\Lib\site-packages\django\template\loader.py", line 19, in get_template
    raise TemplateDoesNotExist(template_name, chain=chain)
django.template.exceptions.TemplateDoesNotExist: ingredients-items.html
ERROR 2023-10-06 12:52:22,938 log Internal Server Error: /ingredient-items/
Traceback (most recent call last):
  File "C:\Users\Lenovo\Downloads\Appstack\Appstack\env\Lib\site-packages\django\core\handlers\exception.py", line 55, in inner
    response = get_response(request)
               ^^^^^^^^^^^^^^^^^^^^^
  File "C:\Users\Lenovo\Downloads\Appstack\Appstack\env\Lib\site-packages\django\core\handlers\base.py", line 197, in _get_response
    response = wrapped_callback(request, *callback_args, **callback_kwargs)
               ^^^^^^^^^^^^^^^^^^^^^^^^^^^^^^^^^^^^^^^^^^^^^^^^^^^^^^^^^^^^
  File "C:\Users\Lenovo\Downloads\Appstack\Appstack\freelance_project\backoffice_engine\views.py", line 664, in ingredients_items
    return render(request,"ingredients-items.html",{
           ^^^^^^^^^^^^^^^^^^^^^^^^^^^^^^^^^^^^^^^^^
  File "C:\Users\Lenovo\Downloads\Appstack\Appstack\env\Lib\site-packages\django\shortcuts.py", line 24, in render
    content = loader.render_to_string(template_name, context, request, using=using)
              ^^^^^^^^^^^^^^^^^^^^^^^^^^^^^^^^^^^^^^^^^^^^^^^^^^^^^^^^^^^^^^^^^^^^^
  File "C:\Users\Lenovo\Downloads\Appstack\Appstack\env\Lib\site-packages\django\template\loader.py", line 61, in render_to_string
    template = get_template(template_name, using=using)
               ^^^^^^^^^^^^^^^^^^^^^^^^^^^^^^^^^^^^^^^^
  File "C:\Users\Lenovo\Downloads\Appstack\Appstack\env\Lib\site-packages\django\template\loader.py", line 19, in get_template
    raise TemplateDoesNotExist(template_name, chain=chain)
django.template.exceptions.TemplateDoesNotExist: ingredients-items.html
ERROR 2023-10-06 12:52:24,232 log Internal Server Error: /ingredient-items/
Traceback (most recent call last):
  File "C:\Users\Lenovo\Downloads\Appstack\Appstack\env\Lib\site-packages\django\core\handlers\exception.py", line 55, in inner
    response = get_response(request)
               ^^^^^^^^^^^^^^^^^^^^^
  File "C:\Users\Lenovo\Downloads\Appstack\Appstack\env\Lib\site-packages\django\core\handlers\base.py", line 197, in _get_response
    response = wrapped_callback(request, *callback_args, **callback_kwargs)
               ^^^^^^^^^^^^^^^^^^^^^^^^^^^^^^^^^^^^^^^^^^^^^^^^^^^^^^^^^^^^
  File "C:\Users\Lenovo\Downloads\Appstack\Appstack\freelance_project\backoffice_engine\views.py", line 664, in ingredients_items
    return render(request,"ingredients-items.html",{
           ^^^^^^^^^^^^^^^^^^^^^^^^^^^^^^^^^^^^^^^^^
  File "C:\Users\Lenovo\Downloads\Appstack\Appstack\env\Lib\site-packages\django\shortcuts.py", line 24, in render
    content = loader.render_to_string(template_name, context, request, using=using)
              ^^^^^^^^^^^^^^^^^^^^^^^^^^^^^^^^^^^^^^^^^^^^^^^^^^^^^^^^^^^^^^^^^^^^^
  File "C:\Users\Lenovo\Downloads\Appstack\Appstack\env\Lib\site-packages\django\template\loader.py", line 61, in render_to_string
    template = get_template(template_name, using=using)
               ^^^^^^^^^^^^^^^^^^^^^^^^^^^^^^^^^^^^^^^^
  File "C:\Users\Lenovo\Downloads\Appstack\Appstack\env\Lib\site-packages\django\template\loader.py", line 19, in get_template
    raise TemplateDoesNotExist(template_name, chain=chain)
django.template.exceptions.TemplateDoesNotExist: ingredients-items.html
ERROR 2023-10-06 12:53:09,016 log Internal Server Error: /ingredient-items/
Traceback (most recent call last):
  File "C:\Users\Lenovo\Downloads\Appstack\Appstack\env\Lib\site-packages\django\core\handlers\exception.py", line 55, in inner
    response = get_response(request)
               ^^^^^^^^^^^^^^^^^^^^^
  File "C:\Users\Lenovo\Downloads\Appstack\Appstack\env\Lib\site-packages\django\core\handlers\base.py", line 197, in _get_response
    response = wrapped_callback(request, *callback_args, **callback_kwargs)
               ^^^^^^^^^^^^^^^^^^^^^^^^^^^^^^^^^^^^^^^^^^^^^^^^^^^^^^^^^^^^
  File "C:\Users\Lenovo\Downloads\Appstack\Appstack\freelance_project\backoffice_engine\views.py", line 664, in ingredients_items
    return render(request,"ingredients-items.html",{
           ^^^^^^^^^^^^^^^^^^^^^^^^^^^^^^^^^^^^^^^^^
  File "C:\Users\Lenovo\Downloads\Appstack\Appstack\env\Lib\site-packages\django\shortcuts.py", line 24, in render
    content = loader.render_to_string(template_name, context, request, using=using)
              ^^^^^^^^^^^^^^^^^^^^^^^^^^^^^^^^^^^^^^^^^^^^^^^^^^^^^^^^^^^^^^^^^^^^^
  File "C:\Users\Lenovo\Downloads\Appstack\Appstack\env\Lib\site-packages\django\template\loader.py", line 61, in render_to_string
    template = get_template(template_name, using=using)
               ^^^^^^^^^^^^^^^^^^^^^^^^^^^^^^^^^^^^^^^^
  File "C:\Users\Lenovo\Downloads\Appstack\Appstack\env\Lib\site-packages\django\template\loader.py", line 19, in get_template
    raise TemplateDoesNotExist(template_name, chain=chain)
django.template.exceptions.TemplateDoesNotExist: ingredients-items.html
ERROR 2023-10-06 12:53:59,327 log Internal Server Error: /ingredient-items/
Traceback (most recent call last):
  File "C:\Users\Lenovo\Downloads\Appstack\Appstack\env\Lib\site-packages\django\core\handlers\exception.py", line 55, in inner
    response = get_response(request)
               ^^^^^^^^^^^^^^^^^^^^^
  File "C:\Users\Lenovo\Downloads\Appstack\Appstack\env\Lib\site-packages\django\core\handlers\base.py", line 197, in _get_response
    response = wrapped_callback(request, *callback_args, **callback_kwargs)
               ^^^^^^^^^^^^^^^^^^^^^^^^^^^^^^^^^^^^^^^^^^^^^^^^^^^^^^^^^^^^
  File "C:\Users\Lenovo\Downloads\Appstack\Appstack\freelance_project\backoffice_engine\views.py", line 664, in ingredients_items
    return render(request,"ingredients-items.html",{
           ^^^^^^^^^^^^^^^^^^^^^^^^^^^^^^^^^^^^^^^^^
  File "C:\Users\Lenovo\Downloads\Appstack\Appstack\env\Lib\site-packages\django\shortcuts.py", line 24, in render
    content = loader.render_to_string(template_name, context, request, using=using)
              ^^^^^^^^^^^^^^^^^^^^^^^^^^^^^^^^^^^^^^^^^^^^^^^^^^^^^^^^^^^^^^^^^^^^^
  File "C:\Users\Lenovo\Downloads\Appstack\Appstack\env\Lib\site-packages\django\template\loader.py", line 61, in render_to_string
    template = get_template(template_name, using=using)
               ^^^^^^^^^^^^^^^^^^^^^^^^^^^^^^^^^^^^^^^^
  File "C:\Users\Lenovo\Downloads\Appstack\Appstack\env\Lib\site-packages\django\template\loader.py", line 19, in get_template
    raise TemplateDoesNotExist(template_name, chain=chain)
django.template.exceptions.TemplateDoesNotExist: ingredients-items.html
ERROR 2023-10-06 13:04:21,703 log Internal Server Error: /add_ingredient
Traceback (most recent call last):
  File "C:\Users\Lenovo\Downloads\Appstack\Appstack\env\Lib\site-packages\django\core\handlers\exception.py", line 55, in inner
    response = get_response(request)
               ^^^^^^^^^^^^^^^^^^^^^
  File "C:\Users\Lenovo\Downloads\Appstack\Appstack\env\Lib\site-packages\django\core\handlers\base.py", line 197, in _get_response
    response = wrapped_callback(request, *callback_args, **callback_kwargs)
               ^^^^^^^^^^^^^^^^^^^^^^^^^^^^^^^^^^^^^^^^^^^^^^^^^^^^^^^^^^^^
  File "C:\Users\Lenovo\Downloads\Appstack\Appstack\freelance_project\backoffice_engine\views.py", line 523, in add_ingredient
    return render(request,"add_ingredient.html",{
           ^^^^^^^^^^^^^^^^^^^^^^^^^^^^^^^^^^^^^^
  File "C:\Users\Lenovo\Downloads\Appstack\Appstack\env\Lib\site-packages\django\shortcuts.py", line 24, in render
    content = loader.render_to_string(template_name, context, request, using=using)
              ^^^^^^^^^^^^^^^^^^^^^^^^^^^^^^^^^^^^^^^^^^^^^^^^^^^^^^^^^^^^^^^^^^^^^
  File "C:\Users\Lenovo\Downloads\Appstack\Appstack\env\Lib\site-packages\django\template\loader.py", line 62, in render_to_string
    return template.render(context, request)
           ^^^^^^^^^^^^^^^^^^^^^^^^^^^^^^^^^
  File "C:\Users\Lenovo\Downloads\Appstack\Appstack\env\Lib\site-packages\django\template\backends\django.py", line 61, in render
    return self.template.render(context)
           ^^^^^^^^^^^^^^^^^^^^^^^^^^^^^
  File "C:\Users\Lenovo\Downloads\Appstack\Appstack\env\Lib\site-packages\django\template\base.py", line 175, in render
    return self._render(context)
           ^^^^^^^^^^^^^^^^^^^^^
  File "C:\Users\Lenovo\Downloads\Appstack\Appstack\env\Lib\site-packages\django\template\base.py", line 167, in _render
    return self.nodelist.render(context)
           ^^^^^^^^^^^^^^^^^^^^^^^^^^^^^
  File "C:\Users\Lenovo\Downloads\Appstack\Appstack\env\Lib\site-packages\django\template\base.py", line 1005, in render
    return SafeString("".join([node.render_annotated(context) for node in self]))
                              ^^^^^^^^^^^^^^^^^^^^^^^^^^^^^^^^^^^^^^^^^^^^^^^^^
  File "C:\Users\Lenovo\Downloads\Appstack\Appstack\env\Lib\site-packages\django\template\base.py", line 1005, in <listcomp>
    return SafeString("".join([node.render_annotated(context) for node in self]))
                               ^^^^^^^^^^^^^^^^^^^^^^^^^^^^^^
  File "C:\Users\Lenovo\Downloads\Appstack\Appstack\env\Lib\site-packages\django\template\base.py", line 966, in render_annotated
    return self.render(context)
           ^^^^^^^^^^^^^^^^^^^^
  File "C:\Users\Lenovo\Downloads\Appstack\Appstack\env\Lib\site-packages\django\template\defaulttags.py", line 471, in render
    url = reverse(view_name, args=args, kwargs=kwargs, current_app=current_app)
          ^^^^^^^^^^^^^^^^^^^^^^^^^^^^^^^^^^^^^^^^^^^^^^^^^^^^^^^^^^^^^^^^^^^^^
  File "C:\Users\Lenovo\Downloads\Appstack\Appstack\env\Lib\site-packages\django\urls\base.py", line 88, in reverse
    return resolver._reverse_with_prefix(view, prefix, *args, **kwargs)
           ^^^^^^^^^^^^^^^^^^^^^^^^^^^^^^^^^^^^^^^^^^^^^^^^^^^^^^^^^^^^
  File "C:\Users\Lenovo\Downloads\Appstack\Appstack\env\Lib\site-packages\django\urls\resolvers.py", line 828, in _reverse_with_prefix
    raise NoReverseMatch(msg)
django.urls.exceptions.NoReverseMatch: Reverse for 'customers_datatable' not found. 'customers_datatable' is not a valid view function or pattern name.
ERROR 2023-10-06 13:06:44,342 log Internal Server Error: /add_ingredient
Traceback (most recent call last):
  File "C:\Users\Lenovo\Downloads\Appstack\Appstack\env\Lib\site-packages\django\core\handlers\exception.py", line 55, in inner
    response = get_response(request)
               ^^^^^^^^^^^^^^^^^^^^^
  File "C:\Users\Lenovo\Downloads\Appstack\Appstack\env\Lib\site-packages\django\core\handlers\base.py", line 197, in _get_response
    response = wrapped_callback(request, *callback_args, **callback_kwargs)
               ^^^^^^^^^^^^^^^^^^^^^^^^^^^^^^^^^^^^^^^^^^^^^^^^^^^^^^^^^^^^
  File "C:\Users\Lenovo\Downloads\Appstack\Appstack\freelance_project\backoffice_engine\views.py", line 523, in add_ingredient
    return render(request,"add_ingredient.html",{
           ^^^^^^^^^^^^^^^^^^^^^^^^^^^^^^^^^^^^^^
  File "C:\Users\Lenovo\Downloads\Appstack\Appstack\env\Lib\site-packages\django\shortcuts.py", line 24, in render
    content = loader.render_to_string(template_name, context, request, using=using)
              ^^^^^^^^^^^^^^^^^^^^^^^^^^^^^^^^^^^^^^^^^^^^^^^^^^^^^^^^^^^^^^^^^^^^^
  File "C:\Users\Lenovo\Downloads\Appstack\Appstack\env\Lib\site-packages\django\template\loader.py", line 62, in render_to_string
    return template.render(context, request)
           ^^^^^^^^^^^^^^^^^^^^^^^^^^^^^^^^^
  File "C:\Users\Lenovo\Downloads\Appstack\Appstack\env\Lib\site-packages\django\template\backends\django.py", line 61, in render
    return self.template.render(context)
           ^^^^^^^^^^^^^^^^^^^^^^^^^^^^^
  File "C:\Users\Lenovo\Downloads\Appstack\Appstack\env\Lib\site-packages\django\template\base.py", line 175, in render
    return self._render(context)
           ^^^^^^^^^^^^^^^^^^^^^
  File "C:\Users\Lenovo\Downloads\Appstack\Appstack\env\Lib\site-packages\django\template\base.py", line 167, in _render
    return self.nodelist.render(context)
           ^^^^^^^^^^^^^^^^^^^^^^^^^^^^^
  File "C:\Users\Lenovo\Downloads\Appstack\Appstack\env\Lib\site-packages\django\template\base.py", line 1005, in render
    return SafeString("".join([node.render_annotated(context) for node in self]))
                              ^^^^^^^^^^^^^^^^^^^^^^^^^^^^^^^^^^^^^^^^^^^^^^^^^
  File "C:\Users\Lenovo\Downloads\Appstack\Appstack\env\Lib\site-packages\django\template\base.py", line 1005, in <listcomp>
    return SafeString("".join([node.render_annotated(context) for node in self]))
                               ^^^^^^^^^^^^^^^^^^^^^^^^^^^^^^
  File "C:\Users\Lenovo\Downloads\Appstack\Appstack\env\Lib\site-packages\django\template\base.py", line 966, in render_annotated
    return self.render(context)
           ^^^^^^^^^^^^^^^^^^^^
  File "C:\Users\Lenovo\Downloads\Appstack\Appstack\env\Lib\site-packages\django\template\defaulttags.py", line 471, in render
    url = reverse(view_name, args=args, kwargs=kwargs, current_app=current_app)
          ^^^^^^^^^^^^^^^^^^^^^^^^^^^^^^^^^^^^^^^^^^^^^^^^^^^^^^^^^^^^^^^^^^^^^
  File "C:\Users\Lenovo\Downloads\Appstack\Appstack\env\Lib\site-packages\django\urls\base.py", line 88, in reverse
    return resolver._reverse_with_prefix(view, prefix, *args, **kwargs)
           ^^^^^^^^^^^^^^^^^^^^^^^^^^^^^^^^^^^^^^^^^^^^^^^^^^^^^^^^^^^^
  File "C:\Users\Lenovo\Downloads\Appstack\Appstack\env\Lib\site-packages\django\urls\resolvers.py", line 828, in _reverse_with_prefix
    raise NoReverseMatch(msg)
django.urls.exceptions.NoReverseMatch: Reverse for 'dish-calculator-items' not found. 'dish-calculator-items' is not a valid view function or pattern name.
ERROR 2023-10-06 13:07:52,898 log Internal Server Error: /add_ingredient
Traceback (most recent call last):
  File "C:\Users\Lenovo\Downloads\Appstack\Appstack\env\Lib\site-packages\django\core\handlers\exception.py", line 55, in inner
    response = get_response(request)
               ^^^^^^^^^^^^^^^^^^^^^
  File "C:\Users\Lenovo\Downloads\Appstack\Appstack\env\Lib\site-packages\django\core\handlers\base.py", line 197, in _get_response
    response = wrapped_callback(request, *callback_args, **callback_kwargs)
               ^^^^^^^^^^^^^^^^^^^^^^^^^^^^^^^^^^^^^^^^^^^^^^^^^^^^^^^^^^^^
  File "C:\Users\Lenovo\Downloads\Appstack\Appstack\freelance_project\backoffice_engine\views.py", line 523, in add_ingredient
    return render(request,"add_ingredient.html",{
           ^^^^^^^^^^^^^^^^^^^^^^^^^^^^^^^^^^^^^^
  File "C:\Users\Lenovo\Downloads\Appstack\Appstack\env\Lib\site-packages\django\shortcuts.py", line 24, in render
    content = loader.render_to_string(template_name, context, request, using=using)
              ^^^^^^^^^^^^^^^^^^^^^^^^^^^^^^^^^^^^^^^^^^^^^^^^^^^^^^^^^^^^^^^^^^^^^
  File "C:\Users\Lenovo\Downloads\Appstack\Appstack\env\Lib\site-packages\django\template\loader.py", line 62, in render_to_string
    return template.render(context, request)
           ^^^^^^^^^^^^^^^^^^^^^^^^^^^^^^^^^
  File "C:\Users\Lenovo\Downloads\Appstack\Appstack\env\Lib\site-packages\django\template\backends\django.py", line 61, in render
    return self.template.render(context)
           ^^^^^^^^^^^^^^^^^^^^^^^^^^^^^
  File "C:\Users\Lenovo\Downloads\Appstack\Appstack\env\Lib\site-packages\django\template\base.py", line 175, in render
    return self._render(context)
           ^^^^^^^^^^^^^^^^^^^^^
  File "C:\Users\Lenovo\Downloads\Appstack\Appstack\env\Lib\site-packages\django\template\base.py", line 167, in _render
    return self.nodelist.render(context)
           ^^^^^^^^^^^^^^^^^^^^^^^^^^^^^
  File "C:\Users\Lenovo\Downloads\Appstack\Appstack\env\Lib\site-packages\django\template\base.py", line 1005, in render
    return SafeString("".join([node.render_annotated(context) for node in self]))
                              ^^^^^^^^^^^^^^^^^^^^^^^^^^^^^^^^^^^^^^^^^^^^^^^^^
  File "C:\Users\Lenovo\Downloads\Appstack\Appstack\env\Lib\site-packages\django\template\base.py", line 1005, in <listcomp>
    return SafeString("".join([node.render_annotated(context) for node in self]))
                               ^^^^^^^^^^^^^^^^^^^^^^^^^^^^^^
  File "C:\Users\Lenovo\Downloads\Appstack\Appstack\env\Lib\site-packages\django\template\base.py", line 966, in render_annotated
    return self.render(context)
           ^^^^^^^^^^^^^^^^^^^^
  File "C:\Users\Lenovo\Downloads\Appstack\Appstack\env\Lib\site-packages\django\template\defaulttags.py", line 471, in render
    url = reverse(view_name, args=args, kwargs=kwargs, current_app=current_app)
          ^^^^^^^^^^^^^^^^^^^^^^^^^^^^^^^^^^^^^^^^^^^^^^^^^^^^^^^^^^^^^^^^^^^^^
  File "C:\Users\Lenovo\Downloads\Appstack\Appstack\env\Lib\site-packages\django\urls\base.py", line 88, in reverse
    return resolver._reverse_with_prefix(view, prefix, *args, **kwargs)
           ^^^^^^^^^^^^^^^^^^^^^^^^^^^^^^^^^^^^^^^^^^^^^^^^^^^^^^^^^^^^
  File "C:\Users\Lenovo\Downloads\Appstack\Appstack\env\Lib\site-packages\django\urls\resolvers.py", line 828, in _reverse_with_prefix
    raise NoReverseMatch(msg)
django.urls.exceptions.NoReverseMatch: Reverse for 'add_dish_calculator' not found. 'add_dish_calculator' is not a valid view function or pattern name.
ERROR 2023-10-06 13:20:02,842 log Internal Server Error: /dashboard/
Traceback (most recent call last):
  File "C:\Users\Lenovo\Downloads\Appstack\Appstack\env\Lib\site-packages\django\core\handlers\exception.py", line 55, in inner
    response = get_response(request)
               ^^^^^^^^^^^^^^^^^^^^^
  File "C:\Users\Lenovo\Downloads\Appstack\Appstack\env\Lib\site-packages\django\core\handlers\base.py", line 197, in _get_response
    response = wrapped_callback(request, *callback_args, **callback_kwargs)
               ^^^^^^^^^^^^^^^^^^^^^^^^^^^^^^^^^^^^^^^^^^^^^^^^^^^^^^^^^^^^
  File "C:\Users\Lenovo\Downloads\Appstack\Appstack\freelance_project\customer_engine\decorators.py", line 28, in _wrapped_view
    return view_func(request, *args, **kwargs)
           ^^^^^^^^^^^^^^^^^^^^^^^^^^^^^^^^^^^
  File "C:\Users\Lenovo\Downloads\Appstack\Appstack\freelance_project\backoffice_engine\views.py", line 166, in index
    return render(request,"index.html",{
           ^^^^^^^^^^^^^^^^^^^^^^^^^^^^^
  File "C:\Users\Lenovo\Downloads\Appstack\Appstack\env\Lib\site-packages\django\shortcuts.py", line 24, in render
    content = loader.render_to_string(template_name, context, request, using=using)
              ^^^^^^^^^^^^^^^^^^^^^^^^^^^^^^^^^^^^^^^^^^^^^^^^^^^^^^^^^^^^^^^^^^^^^
  File "C:\Users\Lenovo\Downloads\Appstack\Appstack\env\Lib\site-packages\django\template\loader.py", line 62, in render_to_string
    return template.render(context, request)
           ^^^^^^^^^^^^^^^^^^^^^^^^^^^^^^^^^
  File "C:\Users\Lenovo\Downloads\Appstack\Appstack\env\Lib\site-packages\django\template\backends\django.py", line 61, in render
    return self.template.render(context)
           ^^^^^^^^^^^^^^^^^^^^^^^^^^^^^
  File "C:\Users\Lenovo\Downloads\Appstack\Appstack\env\Lib\site-packages\django\template\base.py", line 175, in render
    return self._render(context)
           ^^^^^^^^^^^^^^^^^^^^^
  File "C:\Users\Lenovo\Downloads\Appstack\Appstack\env\Lib\site-packages\django\template\base.py", line 167, in _render
    return self.nodelist.render(context)
           ^^^^^^^^^^^^^^^^^^^^^^^^^^^^^
  File "C:\Users\Lenovo\Downloads\Appstack\Appstack\env\Lib\site-packages\django\template\base.py", line 1005, in render
    return SafeString("".join([node.render_annotated(context) for node in self]))
                              ^^^^^^^^^^^^^^^^^^^^^^^^^^^^^^^^^^^^^^^^^^^^^^^^^
  File "C:\Users\Lenovo\Downloads\Appstack\Appstack\env\Lib\site-packages\django\template\base.py", line 1005, in <listcomp>
    return SafeString("".join([node.render_annotated(context) for node in self]))
                               ^^^^^^^^^^^^^^^^^^^^^^^^^^^^^^
  File "C:\Users\Lenovo\Downloads\Appstack\Appstack\env\Lib\site-packages\django\template\base.py", line 966, in render_annotated
    return self.render(context)
           ^^^^^^^^^^^^^^^^^^^^
  File "C:\Users\Lenovo\Downloads\Appstack\Appstack\env\Lib\site-packages\django\template\defaulttags.py", line 471, in render
    url = reverse(view_name, args=args, kwargs=kwargs, current_app=current_app)
          ^^^^^^^^^^^^^^^^^^^^^^^^^^^^^^^^^^^^^^^^^^^^^^^^^^^^^^^^^^^^^^^^^^^^^
  File "C:\Users\Lenovo\Downloads\Appstack\Appstack\env\Lib\site-packages\django\urls\base.py", line 88, in reverse
    return resolver._reverse_with_prefix(view, prefix, *args, **kwargs)
           ^^^^^^^^^^^^^^^^^^^^^^^^^^^^^^^^^^^^^^^^^^^^^^^^^^^^^^^^^^^^
  File "C:\Users\Lenovo\Downloads\Appstack\Appstack\env\Lib\site-packages\django\urls\resolvers.py", line 828, in _reverse_with_prefix
    raise NoReverseMatch(msg)
django.urls.exceptions.NoReverseMatch: Reverse for 'dish_calculator' not found. 'dish_calculator' is not a valid view function or pattern name.
ERROR 2023-10-06 13:20:06,489 log Internal Server Error: /dashboard/
Traceback (most recent call last):
  File "C:\Users\Lenovo\Downloads\Appstack\Appstack\env\Lib\site-packages\django\core\handlers\exception.py", line 55, in inner
    response = get_response(request)
               ^^^^^^^^^^^^^^^^^^^^^
  File "C:\Users\Lenovo\Downloads\Appstack\Appstack\env\Lib\site-packages\django\core\handlers\base.py", line 197, in _get_response
    response = wrapped_callback(request, *callback_args, **callback_kwargs)
               ^^^^^^^^^^^^^^^^^^^^^^^^^^^^^^^^^^^^^^^^^^^^^^^^^^^^^^^^^^^^
  File "C:\Users\Lenovo\Downloads\Appstack\Appstack\freelance_project\customer_engine\decorators.py", line 28, in _wrapped_view
    return view_func(request, *args, **kwargs)
           ^^^^^^^^^^^^^^^^^^^^^^^^^^^^^^^^^^^
  File "C:\Users\Lenovo\Downloads\Appstack\Appstack\freelance_project\backoffice_engine\views.py", line 166, in index
    return render(request,"index.html",{
           ^^^^^^^^^^^^^^^^^^^^^^^^^^^^^
  File "C:\Users\Lenovo\Downloads\Appstack\Appstack\env\Lib\site-packages\django\shortcuts.py", line 24, in render
    content = loader.render_to_string(template_name, context, request, using=using)
              ^^^^^^^^^^^^^^^^^^^^^^^^^^^^^^^^^^^^^^^^^^^^^^^^^^^^^^^^^^^^^^^^^^^^^
  File "C:\Users\Lenovo\Downloads\Appstack\Appstack\env\Lib\site-packages\django\template\loader.py", line 62, in render_to_string
    return template.render(context, request)
           ^^^^^^^^^^^^^^^^^^^^^^^^^^^^^^^^^
  File "C:\Users\Lenovo\Downloads\Appstack\Appstack\env\Lib\site-packages\django\template\backends\django.py", line 61, in render
    return self.template.render(context)
           ^^^^^^^^^^^^^^^^^^^^^^^^^^^^^
  File "C:\Users\Lenovo\Downloads\Appstack\Appstack\env\Lib\site-packages\django\template\base.py", line 175, in render
    return self._render(context)
           ^^^^^^^^^^^^^^^^^^^^^
  File "C:\Users\Lenovo\Downloads\Appstack\Appstack\env\Lib\site-packages\django\template\base.py", line 167, in _render
    return self.nodelist.render(context)
           ^^^^^^^^^^^^^^^^^^^^^^^^^^^^^
  File "C:\Users\Lenovo\Downloads\Appstack\Appstack\env\Lib\site-packages\django\template\base.py", line 1005, in render
    return SafeString("".join([node.render_annotated(context) for node in self]))
                              ^^^^^^^^^^^^^^^^^^^^^^^^^^^^^^^^^^^^^^^^^^^^^^^^^
  File "C:\Users\Lenovo\Downloads\Appstack\Appstack\env\Lib\site-packages\django\template\base.py", line 1005, in <listcomp>
    return SafeString("".join([node.render_annotated(context) for node in self]))
                               ^^^^^^^^^^^^^^^^^^^^^^^^^^^^^^
  File "C:\Users\Lenovo\Downloads\Appstack\Appstack\env\Lib\site-packages\django\template\base.py", line 966, in render_annotated
    return self.render(context)
           ^^^^^^^^^^^^^^^^^^^^
  File "C:\Users\Lenovo\Downloads\Appstack\Appstack\env\Lib\site-packages\django\template\defaulttags.py", line 471, in render
    url = reverse(view_name, args=args, kwargs=kwargs, current_app=current_app)
          ^^^^^^^^^^^^^^^^^^^^^^^^^^^^^^^^^^^^^^^^^^^^^^^^^^^^^^^^^^^^^^^^^^^^^
  File "C:\Users\Lenovo\Downloads\Appstack\Appstack\env\Lib\site-packages\django\urls\base.py", line 88, in reverse
    return resolver._reverse_with_prefix(view, prefix, *args, **kwargs)
           ^^^^^^^^^^^^^^^^^^^^^^^^^^^^^^^^^^^^^^^^^^^^^^^^^^^^^^^^^^^^
  File "C:\Users\Lenovo\Downloads\Appstack\Appstack\env\Lib\site-packages\django\urls\resolvers.py", line 828, in _reverse_with_prefix
    raise NoReverseMatch(msg)
django.urls.exceptions.NoReverseMatch: Reverse for 'dish_calculator' not found. 'dish_calculator' is not a valid view function or pattern name.
ERROR 2023-10-06 13:20:10,746 log Internal Server Error: /dashboard/
Traceback (most recent call last):
  File "C:\Users\Lenovo\Downloads\Appstack\Appstack\env\Lib\site-packages\django\core\handlers\exception.py", line 55, in inner
    response = get_response(request)
               ^^^^^^^^^^^^^^^^^^^^^
  File "C:\Users\Lenovo\Downloads\Appstack\Appstack\env\Lib\site-packages\django\core\handlers\base.py", line 197, in _get_response
    response = wrapped_callback(request, *callback_args, **callback_kwargs)
               ^^^^^^^^^^^^^^^^^^^^^^^^^^^^^^^^^^^^^^^^^^^^^^^^^^^^^^^^^^^^
  File "C:\Users\Lenovo\Downloads\Appstack\Appstack\freelance_project\customer_engine\decorators.py", line 28, in _wrapped_view
    return view_func(request, *args, **kwargs)
           ^^^^^^^^^^^^^^^^^^^^^^^^^^^^^^^^^^^
  File "C:\Users\Lenovo\Downloads\Appstack\Appstack\freelance_project\backoffice_engine\views.py", line 166, in index
    return render(request,"index.html",{
           ^^^^^^^^^^^^^^^^^^^^^^^^^^^^^
  File "C:\Users\Lenovo\Downloads\Appstack\Appstack\env\Lib\site-packages\django\shortcuts.py", line 24, in render
    content = loader.render_to_string(template_name, context, request, using=using)
              ^^^^^^^^^^^^^^^^^^^^^^^^^^^^^^^^^^^^^^^^^^^^^^^^^^^^^^^^^^^^^^^^^^^^^
  File "C:\Users\Lenovo\Downloads\Appstack\Appstack\env\Lib\site-packages\django\template\loader.py", line 62, in render_to_string
    return template.render(context, request)
           ^^^^^^^^^^^^^^^^^^^^^^^^^^^^^^^^^
  File "C:\Users\Lenovo\Downloads\Appstack\Appstack\env\Lib\site-packages\django\template\backends\django.py", line 61, in render
    return self.template.render(context)
           ^^^^^^^^^^^^^^^^^^^^^^^^^^^^^
  File "C:\Users\Lenovo\Downloads\Appstack\Appstack\env\Lib\site-packages\django\template\base.py", line 175, in render
    return self._render(context)
           ^^^^^^^^^^^^^^^^^^^^^
  File "C:\Users\Lenovo\Downloads\Appstack\Appstack\env\Lib\site-packages\django\template\base.py", line 167, in _render
    return self.nodelist.render(context)
           ^^^^^^^^^^^^^^^^^^^^^^^^^^^^^
  File "C:\Users\Lenovo\Downloads\Appstack\Appstack\env\Lib\site-packages\django\template\base.py", line 1005, in render
    return SafeString("".join([node.render_annotated(context) for node in self]))
                              ^^^^^^^^^^^^^^^^^^^^^^^^^^^^^^^^^^^^^^^^^^^^^^^^^
  File "C:\Users\Lenovo\Downloads\Appstack\Appstack\env\Lib\site-packages\django\template\base.py", line 1005, in <listcomp>
    return SafeString("".join([node.render_annotated(context) for node in self]))
                               ^^^^^^^^^^^^^^^^^^^^^^^^^^^^^^
  File "C:\Users\Lenovo\Downloads\Appstack\Appstack\env\Lib\site-packages\django\template\base.py", line 966, in render_annotated
    return self.render(context)
           ^^^^^^^^^^^^^^^^^^^^
  File "C:\Users\Lenovo\Downloads\Appstack\Appstack\env\Lib\site-packages\django\template\defaulttags.py", line 471, in render
    url = reverse(view_name, args=args, kwargs=kwargs, current_app=current_app)
          ^^^^^^^^^^^^^^^^^^^^^^^^^^^^^^^^^^^^^^^^^^^^^^^^^^^^^^^^^^^^^^^^^^^^^
  File "C:\Users\Lenovo\Downloads\Appstack\Appstack\env\Lib\site-packages\django\urls\base.py", line 88, in reverse
    return resolver._reverse_with_prefix(view, prefix, *args, **kwargs)
           ^^^^^^^^^^^^^^^^^^^^^^^^^^^^^^^^^^^^^^^^^^^^^^^^^^^^^^^^^^^^
  File "C:\Users\Lenovo\Downloads\Appstack\Appstack\env\Lib\site-packages\django\urls\resolvers.py", line 828, in _reverse_with_prefix
    raise NoReverseMatch(msg)
django.urls.exceptions.NoReverseMatch: Reverse for 'dish_calculator' not found. 'dish_calculator' is not a valid view function or pattern name.
ERROR 2023-10-06 13:20:39,971 log Internal Server Error: /dashboard/
Traceback (most recent call last):
  File "C:\Users\Lenovo\Downloads\Appstack\Appstack\env\Lib\site-packages\django\core\handlers\exception.py", line 55, in inner
    response = get_response(request)
               ^^^^^^^^^^^^^^^^^^^^^
  File "C:\Users\Lenovo\Downloads\Appstack\Appstack\env\Lib\site-packages\django\core\handlers\base.py", line 197, in _get_response
    response = wrapped_callback(request, *callback_args, **callback_kwargs)
               ^^^^^^^^^^^^^^^^^^^^^^^^^^^^^^^^^^^^^^^^^^^^^^^^^^^^^^^^^^^^
  File "C:\Users\Lenovo\Downloads\Appstack\Appstack\freelance_project\customer_engine\decorators.py", line 28, in _wrapped_view
    return view_func(request, *args, **kwargs)
           ^^^^^^^^^^^^^^^^^^^^^^^^^^^^^^^^^^^
  File "C:\Users\Lenovo\Downloads\Appstack\Appstack\freelance_project\backoffice_engine\views.py", line 166, in index
    return render(request,"index.html",{
           ^^^^^^^^^^^^^^^^^^^^^^^^^^^^^
  File "C:\Users\Lenovo\Downloads\Appstack\Appstack\env\Lib\site-packages\django\shortcuts.py", line 24, in render
    content = loader.render_to_string(template_name, context, request, using=using)
              ^^^^^^^^^^^^^^^^^^^^^^^^^^^^^^^^^^^^^^^^^^^^^^^^^^^^^^^^^^^^^^^^^^^^^
  File "C:\Users\Lenovo\Downloads\Appstack\Appstack\env\Lib\site-packages\django\template\loader.py", line 62, in render_to_string
    return template.render(context, request)
           ^^^^^^^^^^^^^^^^^^^^^^^^^^^^^^^^^
  File "C:\Users\Lenovo\Downloads\Appstack\Appstack\env\Lib\site-packages\django\template\backends\django.py", line 61, in render
    return self.template.render(context)
           ^^^^^^^^^^^^^^^^^^^^^^^^^^^^^
  File "C:\Users\Lenovo\Downloads\Appstack\Appstack\env\Lib\site-packages\django\template\base.py", line 175, in render
    return self._render(context)
           ^^^^^^^^^^^^^^^^^^^^^
  File "C:\Users\Lenovo\Downloads\Appstack\Appstack\env\Lib\site-packages\django\template\base.py", line 167, in _render
    return self.nodelist.render(context)
           ^^^^^^^^^^^^^^^^^^^^^^^^^^^^^
  File "C:\Users\Lenovo\Downloads\Appstack\Appstack\env\Lib\site-packages\django\template\base.py", line 1005, in render
    return SafeString("".join([node.render_annotated(context) for node in self]))
                              ^^^^^^^^^^^^^^^^^^^^^^^^^^^^^^^^^^^^^^^^^^^^^^^^^
  File "C:\Users\Lenovo\Downloads\Appstack\Appstack\env\Lib\site-packages\django\template\base.py", line 1005, in <listcomp>
    return SafeString("".join([node.render_annotated(context) for node in self]))
                               ^^^^^^^^^^^^^^^^^^^^^^^^^^^^^^
  File "C:\Users\Lenovo\Downloads\Appstack\Appstack\env\Lib\site-packages\django\template\base.py", line 966, in render_annotated
    return self.render(context)
           ^^^^^^^^^^^^^^^^^^^^
  File "C:\Users\Lenovo\Downloads\Appstack\Appstack\env\Lib\site-packages\django\template\defaulttags.py", line 471, in render
    url = reverse(view_name, args=args, kwargs=kwargs, current_app=current_app)
          ^^^^^^^^^^^^^^^^^^^^^^^^^^^^^^^^^^^^^^^^^^^^^^^^^^^^^^^^^^^^^^^^^^^^^
  File "C:\Users\Lenovo\Downloads\Appstack\Appstack\env\Lib\site-packages\django\urls\base.py", line 88, in reverse
    return resolver._reverse_with_prefix(view, prefix, *args, **kwargs)
           ^^^^^^^^^^^^^^^^^^^^^^^^^^^^^^^^^^^^^^^^^^^^^^^^^^^^^^^^^^^^
  File "C:\Users\Lenovo\Downloads\Appstack\Appstack\env\Lib\site-packages\django\urls\resolvers.py", line 828, in _reverse_with_prefix
    raise NoReverseMatch(msg)
django.urls.exceptions.NoReverseMatch: Reverse for 'dish_calculator' not found. 'dish_calculator' is not a valid view function or pattern name.
ERROR 2023-10-06 13:20:44,628 log Internal Server Error: /dashboard/
Traceback (most recent call last):
  File "C:\Users\Lenovo\Downloads\Appstack\Appstack\env\Lib\site-packages\django\core\handlers\exception.py", line 55, in inner
    response = get_response(request)
               ^^^^^^^^^^^^^^^^^^^^^
  File "C:\Users\Lenovo\Downloads\Appstack\Appstack\env\Lib\site-packages\django\core\handlers\base.py", line 197, in _get_response
    response = wrapped_callback(request, *callback_args, **callback_kwargs)
               ^^^^^^^^^^^^^^^^^^^^^^^^^^^^^^^^^^^^^^^^^^^^^^^^^^^^^^^^^^^^
  File "C:\Users\Lenovo\Downloads\Appstack\Appstack\freelance_project\customer_engine\decorators.py", line 28, in _wrapped_view
    return view_func(request, *args, **kwargs)
           ^^^^^^^^^^^^^^^^^^^^^^^^^^^^^^^^^^^
  File "C:\Users\Lenovo\Downloads\Appstack\Appstack\freelance_project\backoffice_engine\views.py", line 166, in index
    return render(request,"index.html",{
           ^^^^^^^^^^^^^^^^^^^^^^^^^^^^^
  File "C:\Users\Lenovo\Downloads\Appstack\Appstack\env\Lib\site-packages\django\shortcuts.py", line 24, in render
    content = loader.render_to_string(template_name, context, request, using=using)
              ^^^^^^^^^^^^^^^^^^^^^^^^^^^^^^^^^^^^^^^^^^^^^^^^^^^^^^^^^^^^^^^^^^^^^
  File "C:\Users\Lenovo\Downloads\Appstack\Appstack\env\Lib\site-packages\django\template\loader.py", line 62, in render_to_string
    return template.render(context, request)
           ^^^^^^^^^^^^^^^^^^^^^^^^^^^^^^^^^
  File "C:\Users\Lenovo\Downloads\Appstack\Appstack\env\Lib\site-packages\django\template\backends\django.py", line 61, in render
    return self.template.render(context)
           ^^^^^^^^^^^^^^^^^^^^^^^^^^^^^
  File "C:\Users\Lenovo\Downloads\Appstack\Appstack\env\Lib\site-packages\django\template\base.py", line 175, in render
    return self._render(context)
           ^^^^^^^^^^^^^^^^^^^^^
  File "C:\Users\Lenovo\Downloads\Appstack\Appstack\env\Lib\site-packages\django\template\base.py", line 167, in _render
    return self.nodelist.render(context)
           ^^^^^^^^^^^^^^^^^^^^^^^^^^^^^
  File "C:\Users\Lenovo\Downloads\Appstack\Appstack\env\Lib\site-packages\django\template\base.py", line 1005, in render
    return SafeString("".join([node.render_annotated(context) for node in self]))
                              ^^^^^^^^^^^^^^^^^^^^^^^^^^^^^^^^^^^^^^^^^^^^^^^^^
  File "C:\Users\Lenovo\Downloads\Appstack\Appstack\env\Lib\site-packages\django\template\base.py", line 1005, in <listcomp>
    return SafeString("".join([node.render_annotated(context) for node in self]))
                               ^^^^^^^^^^^^^^^^^^^^^^^^^^^^^^
  File "C:\Users\Lenovo\Downloads\Appstack\Appstack\env\Lib\site-packages\django\template\base.py", line 966, in render_annotated
    return self.render(context)
           ^^^^^^^^^^^^^^^^^^^^
  File "C:\Users\Lenovo\Downloads\Appstack\Appstack\env\Lib\site-packages\django\template\defaulttags.py", line 471, in render
    url = reverse(view_name, args=args, kwargs=kwargs, current_app=current_app)
          ^^^^^^^^^^^^^^^^^^^^^^^^^^^^^^^^^^^^^^^^^^^^^^^^^^^^^^^^^^^^^^^^^^^^^
  File "C:\Users\Lenovo\Downloads\Appstack\Appstack\env\Lib\site-packages\django\urls\base.py", line 88, in reverse
    return resolver._reverse_with_prefix(view, prefix, *args, **kwargs)
           ^^^^^^^^^^^^^^^^^^^^^^^^^^^^^^^^^^^^^^^^^^^^^^^^^^^^^^^^^^^^
  File "C:\Users\Lenovo\Downloads\Appstack\Appstack\env\Lib\site-packages\django\urls\resolvers.py", line 828, in _reverse_with_prefix
    raise NoReverseMatch(msg)
django.urls.exceptions.NoReverseMatch: Reverse for 'dish_calculator' not found. 'dish_calculator' is not a valid view function or pattern name.
